<?xml version="1.0" ?>
<sdf version="1.6">
  <!--NUgus SDF Model-->
  <!--Last updated: 21 Aug 2019 14:17:05-->
  <model name="nubots_nugus_hull">
    <pose frame="">0.000000000 0.000000000 0.000000000 0.000000000 0.000000000 0.000000000</pose>
    <!--LINK: torso-->
    <link name="torso">
      <pose frame="">0.000000000 0.000000000 0.000000000 0.000000000 0.000000000 1.570796327</pose>
      <inertial>
        <pose frame="">0.005007970 0.008880922 0.102150315 0.000000000 0.000000000 0.000000000</pose>
        <mass>2.539</mass>
        <inertia>
          <ixx>0.0166572872071</ixx>
          <ixy>0.00154518589069</ixy>
          <ixz>0.00493865774288</ixz>
          <iyy>0.00422523541751</iyy>
          <iyz>0.00120275338963</iyz>
          <izz>0.0555077839106</izz>
        </inertia>
      </inertial>
      <collision name="torso_collision">
        <pose frame="">0.000000000 0.000000000 0.000000000 0.000000000 0.000000000 0.000000000</pose>
        <geometry>
          <mesh>
            <scale>1 1 1</scale>
            <uri>model://nubots_nugus_hull/mesh/torso.stl</uri>
          </mesh>
        </geometry>
        <surface>
          <contact>
            <ode/>
          </contact>
          <friction>
            <ode>
              <mu>0.98</mu>
              <mu2>0.98</mu2>
              <slip1>1e-05</slip1>
              <slip2>1e-05</slip2>
            </ode>
            <torsional>
              <coefficient>0.8</coefficient>
              <patch_radius>1.0</patch_radius>
            </torsional>
          </friction>
        </surface>
      </collision>
      <visual name="torso_visual">
        <pose frame="">0.000000000 0.000000000 0.000000000 0.000000000 0.000000000 0.000000000</pose>
        <geometry>
          <mesh>
            <scale>1 1 1</scale>
            <uri>model://nubots_nugus_hull/mesh/torso.stl</uri>
          </mesh>
        </geometry>
        <material>
          <script>
            <name>Gazebo/Grey</name>
            <uri>file://media/materials/scripts/gazebo.material</uri>
          </script>
        </material>
      </visual>
      <gravity>1</gravity>
      <self_collide/>
      <sensor name="imu_sensor" type="imu">
        <pose frame="">0.000000000 0.000000000 0.000000000 0.000000000 0.000000000 0.000000000</pose>
        <always_on>1</always_on>
        <visualize>1</visualize>
        <update_rate>100</update_rate>
        <imu>
          <orientation_reference_frame>
            <localization>GRAV_UP</localization>
            <grav_dir_x>1 0 0</grav_dir_x>
          </orientation_reference_frame>
          <angular_velocity>
            <x>
              <noise type="gaussian">
                <mean>0.0</mean>
              </noise>
            </x>
            <y>
              <noise type="gaussian">
                <mean>0.0</mean>
              </noise>
            </y>
            <z>
              <noise type="gaussian">
                <mean>0.0</mean>
              </noise>
            </z>
          </angular_velocity>
          <linear_acceleration>
            <x>
              <noise type="gaussian">
                <mean>0.0</mean>
              </noise>
            </x>
            <y>
              <noise type="gaussian">
                <mean>0.0</mean>
              </noise>
            </y>
            <z>
              <noise type="gaussian">
                <mean>0.0</mean>
              </noise>
            </z>
          </linear_acceleration>
        </imu>
      </sensor>
    </link>
    <!--LINK: right_shoulder-->
    <link name="right_shoulder">
      <pose frame="">0.005000000 -0.115000000 0.180000000 -1.570796327 0.000000000 1.570796327</pose>
      <inertial>
        <pose frame="">0.003491000 -0.001684000 0.003753000 0.000000000 0.000000000 0.000000000</pose>
        <mass>0.025434</mass>
        <inertia>
          <ixx>0.000636</ixx>
          <ixy>2e-06</ixy>
          <ixz>-3.5e-05</ixz>
          <iyy>0.000485</iyy>
          <iyz>6e-06</iyz>
          <izz>0.000628</izz>
        </inertia>
      </inertial>
      <collision name="right_shoulder_collision">
        <pose frame="">0.000000000 0.000000000 0.000000000 0.000000000 0.000000000 0.000000000</pose>
        <geometry>
          <mesh>
            <scale>1 1 1</scale>
            <uri>model://nubots_nugus_hull/mesh/right_shoulder.stl</uri>
          </mesh>
        </geometry>
        <surface>
          <contact>
            <ode/>
          </contact>
          <friction>
            <ode>
              <mu>0.98</mu>
              <mu2>0.98</mu2>
              <slip1>1e-05</slip1>
              <slip2>1e-05</slip2>
            </ode>
            <torsional>
              <coefficient>0.8</coefficient>
              <patch_radius>1.0</patch_radius>
            </torsional>
          </friction>
        </surface>
      </collision>
      <visual name="right_shoulder_visual">
        <pose frame="">0.000000000 0.000000000 0.000000000 0.000000000 0.000000000 0.000000000</pose>
        <geometry>
          <mesh>
            <scale>1 1 1</scale>
            <uri>model://nubots_nugus_hull/mesh/right_shoulder.stl</uri>
          </mesh>
        </geometry>
        <material>
          <script>
            <name>Gazebo/Grey</name>
            <uri>file://media/materials/scripts/gazebo.material</uri>
          </script>
        </material>
      </visual>
      <gravity>1</gravity>
      <self_collide/>
    </link>
    <!--LINK: left_shoulder-->
    <link name="left_shoulder">
      <pose frame="">0.005000000 0.115000000 0.180000000 -1.570796327 0.000000000 1.570796327</pose>
      <inertial>
        <pose frame="">0.003491000 -0.001684000 0.003753000 0.000000000 0.000000000 0.000000000</pose>
        <mass>0.025434</mass>
        <inertia>
          <ixx>0.000636</ixx>
          <ixy>-2e-06</ixy>
          <ixz>-3.5e-05</ixz>
          <iyy>0.000485</iyy>
          <iyz>-6e-06</iyz>
          <izz>0.000628</izz>
        </inertia>
      </inertial>
      <collision name="left_shoulder_collision">
        <pose frame="">0.000000000 0.000000000 0.000000000 0.000000000 0.000000000 0.000000000</pose>
        <geometry>
          <mesh>
            <scale>1 1 1</scale>
            <uri>model://nubots_nugus_hull/mesh/left_shoulder.stl</uri>
          </mesh>
        </geometry>
        <surface>
          <contact>
            <ode/>
          </contact>
          <friction>
            <ode>
              <mu>0.98</mu>
              <mu2>0.98</mu2>
              <slip1>1e-05</slip1>
              <slip2>1e-05</slip2>
            </ode>
            <torsional>
              <coefficient>0.8</coefficient>
              <patch_radius>1.0</patch_radius>
            </torsional>
          </friction>
        </surface>
      </collision>
      <visual name="left_shoulder_visual">
        <pose frame="">0.000000000 0.000000000 0.000000000 0.000000000 0.000000000 0.000000000</pose>
        <geometry>
          <mesh>
            <scale>1 1 1</scale>
            <uri>model://nubots_nugus_hull/mesh/left_shoulder.stl</uri>
          </mesh>
        </geometry>
        <material>
          <script>
            <name>Gazebo/Grey</name>
            <uri>file://media/materials/scripts/gazebo.material</uri>
          </script>
        </material>
      </visual>
      <gravity>1</gravity>
      <self_collide/>
    </link>
    <!--LINK: right_upper_arm-->
    <link name="right_upper_arm">
      <pose frame="">0.000000000 -0.130000000 0.180000000 3.141590000 3.141590000 -1.570796327</pose>
      <inertial>
        <pose frame="">-0.000475465 -0.000483063 -0.047851450 0.000000000 0.000000000 0.000000000</pose>
        <mass>0.297</mass>
        <inertia>
          <ixx>0.00244090259623</ixx>
          <ixy>-3.67136912481e-06</ixy>
          <ixz>-0.000138914522851</ixz>
          <iyy>0.0022838340537</iyy>
          <iyz>-1.97953337853e-05</iyz>
          <izz>0.000536693721409</izz>
        </inertia>
      </inertial>
      <collision name="right_upper_arm_collision">
        <pose frame="">0.000000000 0.000000000 0.000000000 0.000000000 0.000000000 0.000000000</pose>
        <geometry>
          <mesh>
            <scale>1 1 1</scale>
            <uri>model://nubots_nugus_hull/mesh/right_upper_arm.stl</uri>
          </mesh>
        </geometry>
        <surface>
          <contact>
            <ode/>
          </contact>
          <friction>
            <ode>
              <mu>0.98</mu>
              <mu2>0.98</mu2>
              <slip1>1e-05</slip1>
              <slip2>1e-05</slip2>
            </ode>
            <torsional>
              <coefficient>0.8</coefficient>
              <patch_radius>1.0</patch_radius>
            </torsional>
          </friction>
        </surface>
      </collision>
      <visual name="right_upper_arm_visual">
        <pose frame="">0.000000000 0.000000000 0.000000000 0.000000000 0.000000000 0.000000000</pose>
        <geometry>
          <mesh>
            <scale>1 1 1</scale>
            <uri>model://nubots_nugus_hull/mesh/right_upper_arm.stl</uri>
          </mesh>
        </geometry>
        <material>
          <script>
            <name>Gazebo/Grey</name>
            <uri>file://media/materials/scripts/gazebo.material</uri>
          </script>
        </material>
      </visual>
      <gravity>1</gravity>
      <self_collide/>
    </link>
    <!--LINK: left_upper_arm-->
    <link name="left_upper_arm">
      <pose frame="">0.000000000 0.130000000 0.180000000 3.141590000 3.141590000 -1.570796327</pose>
      <inertial>
        <pose frame="">-0.000475465 0.000483063 -0.047851450 0.000000000 0.000000000 0.000000000</pose>
        <mass>0.297</mass>
        <inertia>
          <ixx>0.00244090259623</ixx>
          <ixy>-3.67136912481e-06</ixy>
          <ixz>-0.000138914522851</ixz>
          <iyy>0.0022838340537</iyy>
          <iyz>-1.97953337853e-05</iyz>
          <izz>0.000536693721409</izz>
        </inertia>
      </inertial>
      <collision name="left_upper_arm_collision">
        <pose frame="">0.000000000 0.000000000 0.000000000 0.000000000 0.000000000 0.000000000</pose>
        <geometry>
          <mesh>
            <scale>1 1 1</scale>
            <uri>model://nubots_nugus_hull/mesh/left_upper_arm.stl</uri>
          </mesh>
        </geometry>
        <surface>
          <contact>
            <ode/>
          </contact>
          <friction>
            <ode>
              <mu>0.98</mu>
              <mu2>0.98</mu2>
              <slip1>1e-05</slip1>
              <slip2>1e-05</slip2>
            </ode>
            <torsional>
              <coefficient>0.8</coefficient>
              <patch_radius>1.0</patch_radius>
            </torsional>
          </friction>
        </surface>
      </collision>
      <visual name="left_upper_arm_visual">
        <pose frame="">0.000000000 0.000000000 0.000000000 0.000000000 0.000000000 0.000000000</pose>
        <geometry>
          <mesh>
            <scale>1 1 1</scale>
            <uri>model://nubots_nugus_hull/mesh/left_upper_arm.stl</uri>
          </mesh>
        </geometry>
        <material>
          <script>
            <name>Gazebo/Grey</name>
            <uri>file://media/materials/scripts/gazebo.material</uri>
          </script>
        </material>
      </visual>
      <gravity>1</gravity>
      <self_collide/>
    </link>
    <!--LINK: right_lower_arm-->
    <link name="right_lower_arm">
      <pose frame="">0.190000000 -0.120000000 0.220000000 0.000000000 0.000000000 1.570796327</pose>
      <inertial>
        <pose frame="">0.053365457 -0.000815620 0.000606326 0.000000000 0.000000000 0.000000000</pose>
        <mass>0.26</mass>
        <inertia>
          <ixx>0.0003407158556</ixx>
          <ixy>0.000118236734121</ixy>
          <ixz>-2.88307886182e-05</ixz>
          <iyy>0.00176921345035</iyy>
          <iyz>4.6856873015e-06</iyz>
          <izz>0.00161805925411</izz>
        </inertia>
      </inertial>
      <collision name="right_lower_arm_collision">
        <pose frame="">0.000000000 0.000000000 0.000000000 0.000000000 0.000000000 0.000000000</pose>
        <geometry>
          <mesh>
            <scale>1 1 1</scale>
            <uri>model://nubots_nugus_hull/mesh/right_lower_arm.stl</uri>
          </mesh>
        </geometry>
        <surface>
          <contact>
            <ode/>
          </contact>
          <friction>
            <ode>
              <mu>0.98</mu>
              <mu2>0.98</mu2>
              <slip1>1e-05</slip1>
              <slip2>1e-05</slip2>
            </ode>
            <torsional>
              <coefficient>0.8</coefficient>
              <patch_radius>1.0</patch_radius>
            </torsional>
          </friction>
        </surface>
      </collision>
      <visual name="right_lower_arm_visual">
        <pose frame="">0.000000000 0.000000000 0.000000000 0.000000000 0.000000000 0.000000000</pose>
        <geometry>
          <mesh>
            <scale>1 1 1</scale>
            <uri>model://nubots_nugus_hull/mesh/right_lower_arm.stl</uri>
          </mesh>
        </geometry>
        <material>
          <script>
            <name>Gazebo/Grey</name>
            <uri>file://media/materials/scripts/gazebo.material</uri>
          </script>
        </material>
      </visual>
      <gravity>1</gravity>
      <self_collide/>
    </link>
    <!--LINK: left_lower_arm-->
    <link name="left_lower_arm">
      <pose frame="">0.190000000 0.120000000 0.220000000 0.000000000 0.000000000 1.570796327</pose>
      <inertial>
        <pose frame="">0.053365457 -0.000815620 0.000606326 0.000000000 0.000000000 0.000000000</pose>
        <mass>0.26</mass>
        <inertia>
          <ixx>0.0003407158556</ixx>
          <ixy>0.000118236734121</ixy>
          <ixz>-2.88307886182e-05</ixz>
          <iyy>0.00176921345035</iyy>
          <iyz>4.6856873015e-06</iyz>
          <izz>0.00161805925411</izz>
        </inertia>
      </inertial>
      <collision name="left_lower_arm_collision">
        <pose frame="">0.000000000 0.000000000 0.000000000 0.000000000 0.000000000 0.000000000</pose>
        <geometry>
          <mesh>
            <scale>1 1 1</scale>
            <uri>model://nubots_nugus_hull/mesh/left_lower_arm.stl</uri>
          </mesh>
        </geometry>
        <surface>
          <contact>
            <ode/>
          </contact>
          <friction>
            <ode>
              <mu>0.98</mu>
              <mu2>0.98</mu2>
              <slip1>1e-05</slip1>
              <slip2>1e-05</slip2>
            </ode>
            <torsional>
              <coefficient>0.8</coefficient>
              <patch_radius>1.0</patch_radius>
            </torsional>
          </friction>
        </surface>
      </collision>
      <visual name="left_lower_arm_visual">
        <pose frame="">0.000000000 0.000000000 0.000000000 0.000000000 0.000000000 0.000000000</pose>
        <geometry>
          <mesh>
            <scale>1 1 1</scale>
            <uri>model://nubots_nugus_hull/mesh/left_lower_arm.stl</uri>
          </mesh>
        </geometry>
        <material>
          <script>
            <name>Gazebo/Grey</name>
            <uri>file://media/materials/scripts/gazebo.material</uri>
          </script>
        </material>
      </visual>
      <gravity>1</gravity>
      <self_collide/>
    </link>
    <!--LINK: right_hip_yaw-->
    <link name="right_hip_yaw">
      <pose frame="">0.000000000 -0.055000000 0.000000000 0.000000000 0.000000000 1.570796327</pose>
      <inertial>
        <pose frame="">-0.002182239 -0.046051953 -0.024755435 0.000000000 0.000000000 0.000000000</pose>
        <mass>0.067</mass>
        <inertia>
          <ixx>0.000882290820872</ixx>
          <ixy>1.67744972811e-06</ixy>
          <ixz>-7.82340516059e-06</ixz>
          <iyy>0.0017446691852</iyy>
          <iyz>-2.5331607648e-05</iyz>
          <izz>0.00199696722705</izz>
        </inertia>
      </inertial>
      <collision name="right_hip_yaw_collision">
        <pose frame="">0.000000000 0.000000000 0.000000000 0.000000000 0.000000000 0.000000000</pose>
        <geometry>
          <mesh>
            <scale>1 1 1</scale>
            <uri>model://nubots_nugus_hull/mesh/right_hip_yaw.stl</uri>
          </mesh>
        </geometry>
        <surface>
          <contact>
            <ode/>
          </contact>
          <friction>
            <ode>
              <mu>0.98</mu>
              <mu2>0.98</mu2>
              <slip1>1e-05</slip1>
              <slip2>1e-05</slip2>
            </ode>
            <torsional>
              <coefficient>0.8</coefficient>
              <patch_radius>1.0</patch_radius>
            </torsional>
          </friction>
        </surface>
      </collision>
      <visual name="right_hip_yaw_visual">
        <pose frame="">0.000000000 0.000000000 0.000000000 0.000000000 0.000000000 0.000000000</pose>
        <geometry>
          <mesh>
            <scale>1 1 1</scale>
            <uri>model://nubots_nugus_hull/mesh/right_hip_yaw.stl</uri>
          </mesh>
        </geometry>
        <material>
          <script>
            <name>Gazebo/Grey</name>
            <uri>file://media/materials/scripts/gazebo.material</uri>
          </script>
        </material>
      </visual>
      <gravity>1</gravity>
      <self_collide/>
    </link>
    <!--LINK: left_hip_yaw-->
    <link name="left_hip_yaw">
      <pose frame="">0.000000000 0.055000000 0.000000000 0.000000000 0.000000000 1.570796327</pose>
      <inertial>
        <pose frame="">-0.002182239 0.046051953 -0.024755435 0.000000000 0.000000000 0.000000000</pose>
        <mass>0.067</mass>
        <inertia>
          <ixx>0.000882226060809</ixx>
          <ixy>-1.70552313911e-06</ixy>
          <ixz>-7.85442766165e-06</ixz>
          <iyy>0.00174462757152</iyy>
          <iyz>2.53317940902e-05</iyz>
          <izz>0.00199699030659</izz>
        </inertia>
      </inertial>
      <collision name="left_hip_yaw_collision">
        <pose frame="">0.000000000 0.000000000 0.000000000 0.000000000 0.000000000 0.000000000</pose>
        <geometry>
          <mesh>
            <scale>1 1 1</scale>
            <uri>model://nubots_nugus_hull/mesh/left_hip_yaw.stl</uri>
          </mesh>
        </geometry>
        <surface>
          <contact>
            <ode/>
          </contact>
          <friction>
            <ode>
              <mu>0.98</mu>
              <mu2>0.98</mu2>
              <slip1>1e-05</slip1>
              <slip2>1e-05</slip2>
            </ode>
            <torsional>
              <coefficient>0.8</coefficient>
              <patch_radius>1.0</patch_radius>
            </torsional>
          </friction>
        </surface>
      </collision>
      <visual name="left_hip_yaw_visual">
        <pose frame="">0.000000000 0.000000000 0.000000000 0.000000000 0.000000000 0.000000000</pose>
        <geometry>
          <mesh>
            <scale>1 1 1</scale>
            <uri>model://nubots_nugus_hull/mesh/left_hip_yaw.stl</uri>
          </mesh>
        </geometry>
        <material>
          <script>
            <name>Gazebo/Grey</name>
            <uri>file://media/materials/scripts/gazebo.material</uri>
          </script>
        </material>
      </visual>
      <gravity>1</gravity>
      <self_collide/>
    </link>
    <!--LINK: right_hip_roll-->
    <link name="right_hip_roll">
      <pose frame="">0.000000000 -0.055000000 -0.060000000 0.000000000 0.000000000 1.570796327</pose>
      <inertial>
        <pose frame="">0.015732947 -0.000033191 -0.020710853 0.000000000 0.000000000 0.000000000</pose>
        <mass>0.306</mass>
        <inertia>
          <ixx>0.00011792969792</ixx>
          <ixy>3.75077766164e-06</ixy>
          <ixz>-3.76239396173e-06</ixz>
          <iyy>0.000216752921659</iyy>
          <iyz>-1.04719102357e-06</iyz>
          <izz>0.00026193571108</izz>
        </inertia>
      </inertial>
      <collision name="right_hip_roll_collision">
        <pose frame="">0.000000000 0.000000000 0.000000000 0.000000000 0.000000000 0.000000000</pose>
        <geometry>
          <mesh>
            <scale>1 1 1</scale>
            <uri>model://nubots_nugus_hull/mesh/right_hip_roll.stl</uri>
          </mesh>
        </geometry>
        <surface>
          <contact>
            <ode/>
          </contact>
          <friction>
            <ode>
              <mu>0.98</mu>
              <mu2>0.98</mu2>
              <slip1>1e-05</slip1>
              <slip2>1e-05</slip2>
            </ode>
            <torsional>
              <coefficient>0.8</coefficient>
              <patch_radius>1.0</patch_radius>
            </torsional>
          </friction>
        </surface>
      </collision>
      <visual name="right_hip_roll_visual">
        <pose frame="">0.000000000 0.000000000 0.000000000 0.000000000 0.000000000 0.000000000</pose>
        <geometry>
          <mesh>
            <scale>1 1 1</scale>
            <uri>model://nubots_nugus_hull/mesh/right_hip_roll.stl</uri>
          </mesh>
        </geometry>
        <material>
          <script>
            <name>Gazebo/Grey</name>
            <uri>file://media/materials/scripts/gazebo.material</uri>
          </script>
        </material>
      </visual>
      <gravity>1</gravity>
      <self_collide/>
    </link>
    <!--LINK: left_hip_roll-->
    <link name="left_hip_roll">
      <pose frame="">0.000000000 0.055000000 -0.060000000 0.000000000 0.000000000 1.570796327</pose>
      <inertial>
        <pose frame="">0.015732947 0.000033191 -0.020710853 0.000000000 0.000000000 0.000000000</pose>
        <mass>0.306</mass>
        <inertia>
          <ixx>0.00011792969792</ixx>
          <ixy>3.75077766164e-06</ixy>
          <ixz>-3.76239396173e-06</ixz>
          <iyy>0.000216752921659</iyy>
          <iyz>-1.04719102357e-06</iyz>
          <izz>0.00026193571108</izz>
        </inertia>
      </inertial>
      <collision name="left_hip_roll_collision">
        <pose frame="">0.000000000 0.000000000 0.000000000 0.000000000 0.000000000 0.000000000</pose>
        <geometry>
          <mesh>
            <scale>1 1 1</scale>
            <uri>model://nubots_nugus_hull/mesh/left_hip_roll.stl</uri>
          </mesh>
        </geometry>
        <surface>
          <contact>
            <ode/>
          </contact>
          <friction>
            <ode>
              <mu>0.98</mu>
              <mu2>0.98</mu2>
              <slip1>1e-05</slip1>
              <slip2>1e-05</slip2>
            </ode>
            <torsional>
              <coefficient>0.8</coefficient>
              <patch_radius>1.0</patch_radius>
            </torsional>
          </friction>
        </surface>
      </collision>
      <visual name="left_hip_roll_visual">
        <pose frame="">0.000000000 0.000000000 0.000000000 0.000000000 0.000000000 0.000000000</pose>
        <geometry>
          <mesh>
            <scale>1 1 1</scale>
            <uri>model://nubots_nugus_hull/mesh/left_hip_roll.stl</uri>
          </mesh>
        </geometry>
        <material>
          <script>
            <name>Gazebo/Grey</name>
            <uri>file://media/materials/scripts/gazebo.material</uri>
          </script>
        </material>
      </visual>
      <gravity>1</gravity>
      <self_collide/>
    </link>
    <!--LINK: right_upper_leg-->
    <link name="right_upper_leg">
      <pose frame="">0.010000000 -0.055000000 -0.050000000 -0.050000000 0.000000000 1.570796327</pose>
      <inertial>
        <pose frame="">-0.086823947 -0.000990468 -0.003223657 0.000000000 0.000000000 0.000000000</pose>
        <mass>0.387</mass>
        <inertia>
          <ixx>0.000696700519632</ixx>
          <ixy>-9.53476806421e-06</ixy>
          <ixz>-0.000470624649862</ixz>
          <iyy>0.00239278787906</iyy>
          <iyz>1.16876636437e-07</iyz>
          <izz>0.00205692152569</izz>
        </inertia>
      </inertial>
      <collision name="right_upper_leg_collision">
        <pose frame="">0.000000000 0.000000000 0.000000000 0.000000000 0.000000000 0.000000000</pose>
        <geometry>
          <mesh>
            <scale>1 1 1</scale>
            <uri>model://nubots_nugus_hull/mesh/right_upper_leg.stl</uri>
          </mesh>
        </geometry>
        <surface>
          <contact>
            <ode/>
          </contact>
          <friction>
            <ode>
              <mu>0.98</mu>
              <mu2>0.98</mu2>
              <slip1>1e-05</slip1>
              <slip2>1e-05</slip2>
            </ode>
            <torsional>
              <coefficient>0.8</coefficient>
              <patch_radius>1.0</patch_radius>
            </torsional>
          </friction>
        </surface>
      </collision>
      <visual name="right_upper_leg_visual">
        <pose frame="">0.000000000 0.000000000 0.000000000 0.000000000 0.000000000 0.000000000</pose>
        <geometry>
          <mesh>
            <scale>1 1 1</scale>
            <uri>model://nubots_nugus_hull/mesh/right_upper_leg.stl</uri>
          </mesh>
        </geometry>
        <material>
          <script>
            <name>Gazebo/Grey</name>
            <uri>file://media/materials/scripts/gazebo.material</uri>
          </script>
        </material>
      </visual>
      <gravity>1</gravity>
      <self_collide/>
    </link>
    <!--LINK: left_upper_leg-->
    <link name="left_upper_leg">
      <pose frame="">0.010000000 0.055000000 -0.060000000 -0.050000000 0.000000000 1.570796327</pose>
      <inertial>
        <pose frame="">-0.086823947 -0.000990468 -0.003223657 0.000000000 0.000000000 0.000000000</pose>
        <mass>0.387</mass>
        <inertia>
          <ixx>0.000696700519632</ixx>
          <ixy>9.53476806421e-06</ixy>
          <ixz>-0.000470624649862</ixz>
          <iyy>0.00239278787906</iyy>
          <iyz>-1.16876636437e-07</iyz>
          <izz>0.00205692152569</izz>
        </inertia>
      </inertial>
      <collision name="left_upper_leg_collision">
        <pose frame="">0.000000000 0.000000000 0.000000000 0.000000000 0.000000000 0.000000000</pose>
        <geometry>
          <mesh>
            <scale>1 1 1</scale>
            <uri>model://nubots_nugus_hull/mesh/left_upper_leg.stl</uri>
          </mesh>
        </geometry>
        <surface>
          <contact>
            <ode/>
          </contact>
          <friction>
            <ode>
              <mu>0.98</mu>
              <mu2>0.98</mu2>
              <slip1>1e-05</slip1>
              <slip2>1e-05</slip2>
            </ode>
            <torsional>
              <coefficient>0.8</coefficient>
              <patch_radius>1.0</patch_radius>
            </torsional>
          </friction>
        </surface>
      </collision>
      <visual name="left_upper_leg_visual">
        <pose frame="">0.000000000 0.000000000 0.000000000 0.000000000 0.000000000 0.000000000</pose>
        <geometry>
          <mesh>
            <scale>1 1 1</scale>
            <uri>model://nubots_nugus_hull/mesh/left_upper_leg.stl</uri>
          </mesh>
        </geometry>
        <material>
          <script>
            <name>Gazebo/Grey</name>
            <uri>file://media/materials/scripts/gazebo.material</uri>
          </script>
        </material>
      </visual>
      <gravity>1</gravity>
      <self_collide/>
    </link>
    <!--LINK: right_lower_leg-->
    <link name="right_lower_leg">
      <pose frame="">0.010000000 -0.055000000 -0.250000000 0.000000000 0.000000000 1.570796327</pose>
      <inertial>
        <pose frame="">-0.100008473 0.001284944 -0.007072907 0.000000000 0.000000000 0.000000000</pose>
        <mass>0.177</mass>
        <inertia>
          <ixx>0.000262985314881</ixx>
          <ixy>-8.38322526059e-06</ixy>
          <ixz>0.000263433998983</ixz>
          <iyy>0.00158709194955</iyy>
          <iyz>-6.90920077416e-07</iyz>
          <izz>0.00141772095062</izz>
        </inertia>
      </inertial>
      <collision name="right_lower_leg_collision">
        <pose frame="">0.000000000 0.000000000 0.000000000 0.000000000 0.000000000 0.000000000</pose>
        <geometry>
          <mesh>
            <scale>1 1 1</scale>
            <uri>model://nubots_nugus_hull/mesh/right_lower_leg.stl</uri>
          </mesh>
        </geometry>
        <surface>
          <contact>
            <ode/>
          </contact>
          <friction>
            <ode>
              <mu>0.98</mu>
              <mu2>0.98</mu2>
              <slip1>1e-05</slip1>
              <slip2>1e-05</slip2>
            </ode>
            <torsional>
              <coefficient>0.8</coefficient>
              <patch_radius>1.0</patch_radius>
            </torsional>
          </friction>
        </surface>
      </collision>
      <visual name="right_lower_leg_visual">
        <pose frame="">0.000000000 0.000000000 0.000000000 0.000000000 0.000000000 0.000000000</pose>
        <geometry>
          <mesh>
            <scale>1 1 1</scale>
            <uri>model://nubots_nugus_hull/mesh/right_lower_leg.stl</uri>
          </mesh>
        </geometry>
        <material>
          <script>
            <name>Gazebo/Grey</name>
            <uri>file://media/materials/scripts/gazebo.material</uri>
          </script>
        </material>
      </visual>
      <gravity>1</gravity>
      <self_collide/>
    </link>
    <!--LINK: left_lower_leg-->
    <link name="left_lower_leg">
      <pose frame="">0.010000000 0.055000000 -0.250000000 0.000000000 0.000000000 1.570796327</pose>
      <inertial>
        <pose frame="">-0.100008473 0.001284944 -0.007072907 0.000000000 0.000000000 0.000000000</pose>
        <mass>0.177</mass>
        <inertia>
          <ixx>0.000262985314881</ixx>
          <ixy>8.38322526059e-06</ixy>
          <ixz>0.000263433998983</ixz>
          <iyy>0.00158709194955</iyy>
          <iyz>6.90920077416e-07</iyz>
          <izz>0.00141772095062</izz>
        </inertia>
      </inertial>
      <collision name="left_lower_leg_collision">
        <pose frame="">0.000000000 0.000000000 0.000000000 0.000000000 0.000000000 0.000000000</pose>
        <geometry>
          <mesh>
            <scale>1 1 1</scale>
            <uri>model://nubots_nugus_hull/mesh/left_lower_leg.stl</uri>
          </mesh>
        </geometry>
        <surface>
          <contact>
            <ode/>
          </contact>
          <friction>
            <ode>
              <mu>0.98</mu>
              <mu2>0.98</mu2>
              <slip1>1e-05</slip1>
              <slip2>1e-05</slip2>
            </ode>
            <torsional>
              <coefficient>0.8</coefficient>
              <patch_radius>1.0</patch_radius>
            </torsional>
          </friction>
        </surface>
      </collision>
      <visual name="left_lower_leg_visual">
        <pose frame="">0.000000000 0.000000000 0.000000000 0.000000000 0.000000000 0.000000000</pose>
        <geometry>
          <mesh>
            <scale>1 1 1</scale>
            <uri>model://nubots_nugus_hull/mesh/left_lower_leg.stl</uri>
          </mesh>
        </geometry>
        <material>
          <script>
            <name>Gazebo/Grey</name>
            <uri>file://media/materials/scripts/gazebo.material</uri>
          </script>
        </material>
      </visual>
      <gravity>1</gravity>
      <self_collide/>
    </link>
    <!--LINK: right_ankle-->
    <link name="right_ankle">
      <pose frame="">0.000000000 -0.055000000 -0.450000000 0.000000000 3.141590000 1.570796327</pose>
      <inertial>
        <pose frame="">-0.015732947 0.000512608 -0.021976237 0.000000000 0.000000000 0.000000000</pose>
        <mass>0.306</mass>
        <inertia>
          <ixx>0.00011792969792</ixx>
          <ixy>3.75077766164e-06</ixy>
          <ixz>3.76239396173e-06</ixz>
          <iyy>0.000216752921659</iyy>
          <iyz>1.04719102357e-06</iyz>
          <izz>0.00026193571108</izz>
        </inertia>
      </inertial>
      <collision name="right_ankle_collision">
        <pose frame="">0.000000000 0.000000000 0.000000000 0.000000000 0.000000000 0.000000000</pose>
        <geometry>
          <mesh>
            <scale>1 1 1</scale>
            <uri>model://nubots_nugus_hull/mesh/right_ankle.stl</uri>
          </mesh>
        </geometry>
        <surface>
          <contact>
            <ode/>
          </contact>
          <friction>
            <ode>
              <mu>0.98</mu>
              <mu2>0.98</mu2>
              <slip1>1e-05</slip1>
              <slip2>1e-05</slip2>
            </ode>
            <torsional>
              <coefficient>0.8</coefficient>
              <patch_radius>1.0</patch_radius>
            </torsional>
          </friction>
        </surface>
      </collision>
      <visual name="right_ankle_visual">
        <pose frame="">0.000000000 0.000000000 0.000000000 0.000000000 0.000000000 0.000000000</pose>
        <geometry>
          <mesh>
            <scale>1 1 1</scale>
            <uri>model://nubots_nugus_hull/mesh/right_ankle.stl</uri>
          </mesh>
        </geometry>
        <material>
          <script>
            <name>Gazebo/Grey</name>
            <uri>file://media/materials/scripts/gazebo.material</uri>
          </script>
        </material>
      </visual>
      <gravity>1</gravity>
      <self_collide/>
    </link>
    <!--LINK: left_ankle-->
    <link name="left_ankle">
      <pose frame="">0.000000000 0.055000000 -0.450000000 0.000000000 3.141590000 1.570796327</pose>
      <inertial>
        <pose frame="">-0.015732947 0.000512608 -0.021976237 0.000000000 0.000000000 0.000000000</pose>
        <mass>0.306</mass>
        <inertia>
          <ixx>0.00011792969792</ixx>
          <ixy>-3.75077766164e-06</ixy>
          <ixz>3.76239396173e-06</ixz>
          <iyy>0.000216752921659</iyy>
          <iyz>-1.04719102357e-06</iyz>
          <izz>0.00026193571108</izz>
        </inertia>
      </inertial>
      <collision name="left_ankle_collision">
        <pose frame="">0.000000000 0.000000000 0.000000000 0.000000000 0.000000000 0.000000000</pose>
        <geometry>
          <mesh>
            <scale>1 1 1</scale>
            <uri>model://nubots_nugus_hull/mesh/left_ankle.stl</uri>
          </mesh>
        </geometry>
        <surface>
          <contact>
            <ode/>
          </contact>
          <friction>
            <ode>
              <mu>0.98</mu>
              <mu2>0.98</mu2>
              <slip1>1e-05</slip1>
              <slip2>1e-05</slip2>
            </ode>
            <torsional>
              <coefficient>0.8</coefficient>
              <patch_radius>1.0</patch_radius>
            </torsional>
          </friction>
        </surface>
      </collision>
      <visual name="left_ankle_visual">
        <pose frame="">0.000000000 0.000000000 0.000000000 0.000000000 0.000000000 0.000000000</pose>
        <geometry>
          <mesh>
            <scale>1 1 1</scale>
            <uri>model://nubots_nugus_hull/mesh/left_ankle.stl</uri>
          </mesh>
        </geometry>
        <material>
          <script>
            <name>Gazebo/Grey</name>
            <uri>file://media/materials/scripts/gazebo.material</uri>
          </script>
        </material>
      </visual>
      <gravity>1</gravity>
      <self_collide/>
    </link>
    <!--LINK: right_foot-->
    <link name="right_foot">
      <pose frame="">-0.040000000 -0.055000000 -0.450000000 0.000000000 0.000000000 1.570796327</pose>
      <inertial>
        <pose frame="">0.030807480 0.008771711 0.011298452 0.000000000 0.000000000 0.000000000</pose>
        <mass>0.205</mass>
        <inertia>
          <ixx>0.000469227615567</ixx>
          <ixy>1.23728985389e-05</ixy>
          <ixz>5.16561744473e-06</ixz>
          <iyy>0.0010836186025</iyy>
          <iyz>-1.75941501866e-06</iyz>
          <izz>0.00139011775571</izz>
        </inertia>
      </inertial>
      <collision name="right_foot_collision">
        <pose frame="">0.000000000 0.000000000 0.000000000 0.000000000 0.000000000 0.000000000</pose>
        <geometry>
          <mesh>
            <scale>1 1 1</scale>
            <uri>model://nubots_nugus_hull/mesh/right_foot.stl</uri>
          </mesh>
        </geometry>
        <surface>
          <contact>
            <ode/>
          </contact>
          <friction>
            <ode>
              <mu>0.98</mu>
              <mu2>0.98</mu2>
              <slip1>1e-05</slip1>
              <slip2>1e-05</slip2>
            </ode>
            <torsional>
              <coefficient>0.8</coefficient>
              <patch_radius>1.0</patch_radius>
            </torsional>
          </friction>
        </surface>
      </collision>
      <visual name="right_foot_visual">
        <pose frame="">0.000000000 0.000000000 0.000000000 0.000000000 0.000000000 0.000000000</pose>
        <geometry>
          <mesh>
            <scale>1 1 1</scale>
            <uri>model://nubots_nugus_hull/mesh/right_foot.stl</uri>
          </mesh>
        </geometry>
        <material>
          <script>
            <name>Gazebo/Grey</name>
            <uri>file://media/materials/scripts/gazebo.material</uri>
          </script>
        </material>
      </visual>
      <gravity>1</gravity>
      <self_collide/>
    </link>
    <!--LINK: left_foot-->
    <link name="left_foot">
      <pose frame="">-0.040000000 0.055000000 -0.450000000 0.000000000 0.000000000 1.570796327</pose>
      <inertial>
        <pose frame="">0.030807480 0.008771711 0.011298452 0.000000000 0.000000000 0.000000000</pose>
        <mass>0.205</mass>
        <inertia>
          <ixx>0.000469227615567</ixx>
          <ixy>-1.23728985389e-05</ixy>
          <ixz>5.16561744473e-06</ixz>
          <iyy>0.0010836186025</iyy>
          <iyz>1.75941501866e-06</iyz>
          <izz>0.00139011775571</izz>
        </inertia>
      </inertial>
      <collision name="left_foot_collision">
        <pose frame="">0.000000000 0.000000000 0.000000000 0.000000000 0.000000000 0.000000000</pose>
        <geometry>
          <mesh>
            <scale>1 1 1</scale>
            <uri>model://nubots_nugus_hull/mesh/left_foot.stl</uri>
          </mesh>
        </geometry>
        <surface>
          <contact>
            <ode/>
          </contact>
          <friction>
            <ode>
              <mu>0.98</mu>
              <mu2>0.98</mu2>
              <slip1>1e-05</slip1>
              <slip2>1e-05</slip2>
            </ode>
            <torsional>
              <coefficient>0.8</coefficient>
              <patch_radius>1.0</patch_radius>
            </torsional>
          </friction>
        </surface>
      </collision>
      <visual name="left_foot_visual">
        <pose frame="">0.000000000 0.000000000 0.000000000 0.000000000 0.000000000 0.000000000</pose>
        <geometry>
          <mesh>
            <scale>1 1 1</scale>
            <uri>model://nubots_nugus_hull/mesh/left_foot.stl</uri>
          </mesh>
        </geometry>
        <material>
          <script>
            <name>Gazebo/Grey</name>
            <uri>file://media/materials/scripts/gazebo.material</uri>
          </script>
        </material>
      </visual>
      <gravity>1</gravity>
      <self_collide/>
    </link>
    <!--LINK: neck-->
    <link name="neck">
      <pose frame="">0.000000000 0.000000000 0.260000000 0.000000000 0.000000000 1.570796327</pose>
      <inertial>
        <pose frame="">-0.006037340 -0.001599843 0.241159162 0.000000000 0.000000000 0.000000000</pose>
        <mass>0.135</mass>
        <inertia>
          <ixx>0.000411112411154</ixx>
          <ixy>1.34448293546e-10</ixy>
          <ixz>-3.64693458364e-10</ixz>
          <iyy>0.000343174942176</iyy>
          <iyz>-1.24602176867e-05</iyz>
          <izz>0.000233389890355</izz>
        </inertia>
      </inertial>
      <collision name="neck_collision">
        <pose frame="">0.000000000 0.000000000 0.000000000 0.000000000 0.000000000 0.000000000</pose>
        <geometry>
          <mesh>
            <scale>1 1 1</scale>
            <uri>model://nubots_nugus_hull/mesh/neck.stl</uri>
          </mesh>
        </geometry>
        <surface>
          <contact>
            <ode/>
          </contact>
          <friction>
            <ode>
              <mu>0.98</mu>
              <mu2>0.98</mu2>
              <slip1>1e-05</slip1>
              <slip2>1e-05</slip2>
            </ode>
            <torsional>
              <coefficient>0.8</coefficient>
              <patch_radius>1.0</patch_radius>
            </torsional>
          </friction>
        </surface>
      </collision>
      <visual name="neck_visual">
        <pose frame="">0.000000000 0.000000000 0.000000000 0.000000000 0.000000000 0.000000000</pose>
        <geometry>
          <mesh>
            <scale>1 1 1</scale>
            <uri>model://nubots_nugus_hull/mesh/neck.stl</uri>
          </mesh>
        </geometry>
        <material>
          <script>
            <name>Gazebo/Grey</name>
            <uri>file://media/materials/scripts/gazebo.material</uri>
          </script>
        </material>
      </visual>
      <gravity>1</gravity>
      <self_collide/>
    </link>
    <!--LINK: head-->
    <link name="head">
      <pose frame="">0.000000000 0.000000000 0.260000000 0.000000000 0.000000000 1.570796327</pose>
      <inertial>
        <pose frame="">-0.054822290 -0.000108882 0.001171290 0.000000000 0.000000000 0.000000000</pose>
        <mass>0.419</mass>
        <inertia>
          <ixx>0.00522954263224</ixx>
          <ixy>8.06868913029e-07</ixy>
          <ixz>-7.85419377514e-05</ixz>
          <iyy>0.00427382206022</iyy>
          <iyz>2.26332170851e-07</iyz>
          <izz>0.00333363205267</izz>
        </inertia>
      </inertial>
      <collision name="head_collision">
        <pose frame="">0.000000000 0.000000000 0.000000000 0.000000000 0.000000000 0.000000000</pose>
        <geometry>
          <mesh>
            <scale>1 1 1</scale>
            <uri>model://nubots_nugus_hull/mesh/head.stl</uri>
          </mesh>
        </geometry>
        <surface>
          <contact>
            <ode/>
          </contact>
          <friction>
            <ode>
              <mu>0.98</mu>
              <mu2>0.98</mu2>
              <slip1>1e-05</slip1>
              <slip2>1e-05</slip2>
            </ode>
            <torsional>
              <coefficient>0.8</coefficient>
              <patch_radius>1.0</patch_radius>
            </torsional>
          </friction>
        </surface>
      </collision>
      <visual name="head_visual">
        <pose frame="">0.000000000 0.000000000 0.000000000 0.000000000 0.000000000 0.000000000</pose>
        <geometry>
          <mesh>
            <scale>1 1 1</scale>
            <uri>model://nubots_nugus_hull/mesh/head.stl</uri>
          </mesh>
        </geometry>
        <material>
          <script>
            <name>Gazebo/Grey</name>
            <uri>file://media/materials/scripts/gazebo.material</uri>
          </script>
        </material>
      </visual>
      <gravity>1</gravity>
      <self_collide/>
    </link>
    <!--JOINT: right_shoulder_pitch-->
    <joint name="right_shoulder_pitch" type="revolute">
      <child>right_shoulder</child>
      <parent>torso</parent>
      <axis>
        <xyz>0 1 0</xyz>
        <limit>
          <lower>-3.14159265359</lower>
          <upper>3.14159265359</upper>
          <velocity>8.16814</velocity>
          <effort>7.3</effort>
        </limit>
        <dynamics>
          <friction>0.5</friction>
          <damping>0.6</damping>
          <spring_reference>0</spring_reference>
          <spring_stiffness>3.25</spring_stiffness>
        </dynamics>
        <use_parent_model_frame>1</use_parent_model_frame>
      </axis>
    </joint>
    <!--JOINT: left_shoulder_pitch-->
    <joint name="left_shoulder_pitch" type="revolute">
      <child>left_shoulder</child>
      <parent>torso</parent>
      <axis>
        <xyz>0 1 0</xyz>
        <limit>
          <lower>-3.14159265359</lower>
          <upper>3.14159265359</upper>
          <velocity>8.16814</velocity>
          <effort>7.3</effort>
        </limit>
        <dynamics>
          <friction>0.5</friction>
          <damping>0.6</damping>
          <spring_reference>0</spring_reference>
          <spring_stiffness>3.25</spring_stiffness>
        </dynamics>
        <use_parent_model_frame>1</use_parent_model_frame>
      </axis>
    </joint>
    <!--JOINT: right_shoulder_roll-->
    <joint name="right_shoulder_roll" type="revolute">
      <child>right_upper_arm</child>
      <parent>right_shoulder</parent>
      <axis>
        <xyz>0 0 1</xyz>
        <limit>
          <lower>-3.14159265359</lower>
          <upper>3.14159265359</upper>
          <velocity>8.16814</velocity>
          <effort>7.3</effort>
        </limit>
        <dynamics>
          <friction>0.5</friction>
          <damping>0.6</damping>
          <spring_reference>0</spring_reference>
          <spring_stiffness>3.25</spring_stiffness>
        </dynamics>
        <use_parent_model_frame>1</use_parent_model_frame>
      </axis>
    </joint>
    <!--JOINT: left_shoulder_roll-->
    <joint name="left_shoulder_roll" type="revolute">
      <child>left_upper_arm</child>
      <parent>left_shoulder</parent>
      <axis>
        <xyz>0 0 1</xyz>
        <limit>
          <lower>-3.14159265359</lower>
          <upper>3.14159265359</upper>
          <velocity>8.16814</velocity>
          <effort>7.3</effort>
        </limit>
        <dynamics>
          <friction>0.5</friction>
          <damping>0.6</damping>
          <spring_reference>0</spring_reference>
          <spring_stiffness>3.25</spring_stiffness>
        </dynamics>
        <use_parent_model_frame>1</use_parent_model_frame>
      </axis>
    </joint>
    <!--JOINT: right_elbow_pitch-->
    <joint name="right_elbow_pitch" type="revolute">
      <child>right_lower_arm</child>
      <parent>right_upper_arm</parent>
      <axis>
        <xyz>0 1 0</xyz>
        <limit>
          <lower>-3.14159265359</lower>
          <upper>3.14159265359</upper>
          <velocity>8.16814</velocity>
          <effort>7.3</effort>
        </limit>
        <dynamics>
          <friction>0.5</friction>
          <damping>0.6</damping>
          <spring_reference>0</spring_reference>
          <spring_stiffness>3.25</spring_stiffness>
        </dynamics>
        <use_parent_model_frame>1</use_parent_model_frame>
      </axis>
    </joint>
    <!--JOINT: left_elbow_pitch-->
    <joint name="left_elbow_pitch" type="revolute">
      <child>left_lower_arm</child>
      <parent>left_upper_arm</parent>
      <axis>
        <xyz>0 1 0</xyz>
        <limit>
          <lower>-3.14159265359</lower>
          <upper>3.14159265359</upper>
          <velocity>8.16814</velocity>
          <effort>7.3</effort>
        </limit>
        <dynamics>
          <friction>0.5</friction>
          <damping>0.6</damping>
          <spring_reference>0</spring_reference>
          <spring_stiffness>3.25</spring_stiffness>
        </dynamics>
        <use_parent_model_frame>1</use_parent_model_frame>
      </axis>
    </joint>
    <!--JOINT: right_hip_yaw-->
    <joint name="right_hip_yaw" type="revolute">
      <child>right_hip_yaw</child>
      <parent>torso</parent>
      <axis>
        <xyz>0 0 1</xyz>
        <limit>
          <lower>-3.14159265359</lower>
          <upper>3.14159265359</upper>
          <velocity>5.75959</velocity>
          <effort>10.0</effort>
        </limit>
        <dynamics>
          <friction>0.5</friction>
          <damping>0.6</damping>
          <spring_reference>0</spring_reference>
          <spring_stiffness>3.25</spring_stiffness>
        </dynamics>
        <use_parent_model_frame>1</use_parent_model_frame>
      </axis>
    </joint>
    <!--JOINT: left_hip_yaw-->
    <joint name="left_hip_yaw" type="revolute">
      <child>left_hip_yaw</child>
      <parent>torso</parent>
      <axis>
        <xyz>0 0 1</xyz>
        <limit>
          <lower>-3.14159265359</lower>
          <upper>3.14159265359</upper>
          <velocity>5.75959</velocity>
          <effort>10.0</effort>
        </limit>
        <dynamics>
          <friction>0.5</friction>
          <damping>0.6</damping>
          <spring_reference>0</spring_reference>
          <spring_stiffness>3.25</spring_stiffness>
        </dynamics>
        <use_parent_model_frame>1</use_parent_model_frame>
      </axis>
    </joint>
    <!--JOINT: right_hip_roll-->
    <joint name="right_hip_roll" type="revolute">
      <child>right_hip_roll</child>
      <parent>right_hip_yaw</parent>
      <axis>
        <xyz>1 0 0</xyz>
        <limit>
          <lower>-3.14159265359</lower>
          <upper>3.14159265359</upper>
          <velocity>5.75959</velocity>
          <effort>10.0</effort>
        </limit>
        <dynamics>
          <friction>0.5</friction>
          <damping>0.6</damping>
          <spring_reference>0</spring_reference>
          <spring_stiffness>3.25</spring_stiffness>
        </dynamics>
        <use_parent_model_frame>1</use_parent_model_frame>
      </axis>
    </joint>
    <!--JOINT: left_hip_roll-->
    <joint name="left_hip_roll" type="revolute">
      <child>left_hip_roll</child>
      <parent>left_hip_yaw</parent>
      <axis>
        <xyz>1 0 0</xyz>
        <limit>
          <lower>-3.14159265359</lower>
          <upper>3.14159265359</upper>
          <velocity>5.75959</velocity>
          <effort>10.0</effort>
        </limit>
        <dynamics>
          <friction>0.5</friction>
          <damping>0.6</damping>
          <spring_reference>0</spring_reference>
          <spring_stiffness>3.25</spring_stiffness>
        </dynamics>
        <use_parent_model_frame>1</use_parent_model_frame>
      </axis>
    </joint>
    <!--JOINT: right_hip_pitch-->
    <joint name="right_hip_pitch" type="revolute">
      <child>right_upper_leg</child>
      <parent>right_hip_roll</parent>
      <axis>
        <xyz>0 1 0</xyz>
        <limit>
          <lower>-3.14159265359</lower>
          <upper>3.14159265359</upper>
          <velocity>5.75959</velocity>
          <effort>10.0</effort>
        </limit>
        <dynamics>
          <friction>0.5</friction>
          <damping>0.6</damping>
          <spring_reference>0</spring_reference>
          <spring_stiffness>3.25</spring_stiffness>
        </dynamics>
        <use_parent_model_frame>1</use_parent_model_frame>
      </axis>
    </joint>
    <!--JOINT: left_hip_pitch-->
    <joint name="left_hip_pitch" type="revolute">
      <child>left_upper_leg</child>
      <parent>left_hip_roll</parent>
      <axis>
        <xyz>0 1 0</xyz>
        <limit>
          <lower>-3.14159265359</lower>
          <upper>3.14159265359</upper>
          <velocity>5.75959</velocity>
          <effort>10.0</effort>
        </limit>
        <dynamics>
          <friction>0.5</friction>
          <damping>0.6</damping>
          <spring_reference>0</spring_reference>
          <spring_stiffness>3.25</spring_stiffness>
        </dynamics>
        <use_parent_model_frame>1</use_parent_model_frame>
      </axis>
    </joint>
    <!--JOINT: right_knee_pitch-->
    <joint name="right_knee_pitch" type="revolute">
      <child>right_lower_leg</child>
      <parent>right_upper_leg</parent>
      <axis>
        <xyz>0 1 0</xyz>
        <limit>
          <lower>-3.14159265359</lower>
          <upper>3.14159265359</upper>
          <velocity>5.75959</velocity>
          <effort>10.0</effort>
        </limit>
        <dynamics>
          <friction>0.5</friction>
          <damping>0.6</damping>
          <spring_reference>0</spring_reference>
          <spring_stiffness>3.25</spring_stiffness>
        </dynamics>
        <use_parent_model_frame>1</use_parent_model_frame>
      </axis>
    </joint>
    <!--JOINT: left_knee_pitch-->
    <joint name="left_knee_pitch" type="revolute">
      <child>left_lower_leg</child>
      <parent>left_upper_leg</parent>
      <axis>
        <xyz>0 1 0</xyz>
        <limit>
          <lower>-3.14159265359</lower>
          <upper>3.14159265359</upper>
          <velocity>5.75959</velocity>
          <effort>10.0</effort>
        </limit>
        <dynamics>
          <friction>0.5</friction>
          <damping>0.6</damping>
          <spring_reference>0</spring_reference>
          <spring_stiffness>3.25</spring_stiffness>
        </dynamics>
        <use_parent_model_frame>1</use_parent_model_frame>
      </axis>
    </joint>
    <!--JOINT: right_ankle_pitch-->
    <joint name="right_ankle_pitch" type="revolute">
      <child>right_ankle</child>
      <parent>right_lower_leg</parent>
      <axis>
        <xyz>0 1 0</xyz>
        <limit>
          <lower>-3.14159265359</lower>
          <upper>3.14159265359</upper>
          <velocity>5.75959</velocity>
          <effort>10.0</effort>
        </limit>
        <dynamics>
          <friction>0.5</friction>
          <damping>0.6</damping>
          <spring_reference>0</spring_reference>
          <spring_stiffness>3.25</spring_stiffness>
        </dynamics>
        <use_parent_model_frame>1</use_parent_model_frame>
      </axis>
    </joint>
    <!--JOINT: left_ankle_pitch-->
    <joint name="left_ankle_pitch" type="revolute">
      <child>left_ankle</child>
      <parent>left_lower_leg</parent>
      <axis>
        <xyz>0 1 0</xyz>
        <limit>
          <lower>-3.14159265359</lower>
          <upper>3.14159265359</upper>
          <velocity>5.75959</velocity>
          <effort>10.0</effort>
        </limit>
        <dynamics>
          <friction>0.5</friction>
          <damping>0.6</damping>
          <spring_reference>0</spring_reference>
          <spring_stiffness>3.25</spring_stiffness>
        </dynamics>
        <use_parent_model_frame>1</use_parent_model_frame>
      </axis>
    </joint>
    <!--JOINT: right_ankle_roll-->
    <joint name="right_ankle_roll" type="revolute">
      <child>right_foot</child>
      <parent>right_ankle</parent>
      <axis>
        <xyz>1 0 0</xyz>
        <limit>
          <lower>-3.14159265359</lower>
          <upper>3.14159265359</upper>
          <velocity>5.75959</velocity>
          <effort>10.0</effort>
        </limit>
        <dynamics>
          <friction>0.5</friction>
          <damping>0.6</damping>
          <spring_reference>0</spring_reference>
          <spring_stiffness>3.25</spring_stiffness>
        </dynamics>
        <use_parent_model_frame>1</use_parent_model_frame>
      </axis>
    </joint>
    <!--JOINT: left_ankle_roll-->
    <joint name="left_ankle_roll" type="revolute">
      <child>left_foot</child>
      <parent>left_ankle</parent>
      <axis>
        <xyz>1 0 0</xyz>
        <limit>
          <lower>-3.14159265359</lower>
          <upper>3.14159265359</upper>
          <velocity>5.75959</velocity>
          <effort>10.0</effort>
        </limit>
        <dynamics>
          <friction>0.5</friction>
          <damping>0.6</damping>
          <spring_reference>0</spring_reference>
          <spring_stiffness>3.25</spring_stiffness>
        </dynamics>
        <use_parent_model_frame>1</use_parent_model_frame>
      </axis>
    </joint>
    <!--JOINT: neck_yaw-->
    <joint name="neck_yaw" type="revolute">
      <child>neck</child>
      <parent>torso</parent>
      <axis>
        <xyz>0 0 1</xyz>
        <limit>
          <lower>-3.14159265359</lower>
          <upper>3.14159265359</upper>
          <velocity>8.16814</velocity>
          <effort>7.3</effort>
        </limit>
        <dynamics>
          <friction>0.5</friction>
          <damping>0.6</damping>
          <spring_reference>0</spring_reference>
          <spring_stiffness>3.25</spring_stiffness>
        </dynamics>
        <use_parent_model_frame>1</use_parent_model_frame>
      </axis>
    </joint>
    <!--JOINT: head_pitch-->
    <joint name="head_pitch" type="revolute">
      <child>head</child>
      <parent>neck</parent>
      <axis>
        <xyz>0 1 0</xyz>
        <limit>
          <lower>-3.14159265359</lower>
          <upper>3.14159265359</upper>
          <velocity>8.16814</velocity>
          <effort>7.3</effort>
        </limit>
        <dynamics>
          <friction>0.5</friction>
          <damping>0.6</damping>
          <spring_reference>0</spring_reference>
          <spring_stiffness>3.25</spring_stiffness>
        </dynamics>
        <use_parent_model_frame>1</use_parent_model_frame>
      </axis>
    </joint>
  </model>
</sdf>
