<?xml version="1.0"?>
<sdf version="1.6">
  <model name='nubots_nugus_hull'>
    <link name='trunk_link'>
      <pose frame=''>0 0 0 0 -0 0</pose>
      <inertial>
        <pose frame=''>-0.016856 -0.000198 0.019225 0 -0 0</pose>
        <mass>1.8051</mass>
        <inertia>
          <ixx>0.016444</ixx>
          <ixy>1.4574e-05</ixy>
          <ixz>0.00048254</ixz>
          <iyy>0.013972</iyy>
          <iyz>5.0355e-06</iyz>
          <izz>0.0064508</izz>
        </inertia>
      </inertial>
      <collision name='trunk_link_collision'>
        <pose frame=''>-0.0665 0 -0.0779 1.5708 -0 1.5708</pose>
        <geometry>
          <mesh>
            <scale>1 1 1</scale>
            <uri>model://nubots_nugus_hull/mesh/trunk_link.stl</uri>
          </mesh>
        </geometry>
        <surface>
          <contact>
            <ode/>
          </contact>
          <friction>
            <ode>
              <mu>0.98</mu>
              <mu2>0.98</mu2>
            </ode>
          </friction>
        </surface>
      </collision>
      <visual name='trunk_link_visual'>
        <pose frame=''>-0.0665 0 -0.0779 1.5708 -0 1.5708</pose>
        <geometry>
          <mesh>
            <scale>1 1 1</scale>
            <uri>model://nubots_nugus_hull/mesh/trunk_link.stl</uri>
          </mesh>
        </geometry>
        <material>
          <script>
            <name>Gazebo/Orange</name>
            <uri>file://media/materials/scripts/gazebo.material</uri>
          </script>
        </material>
      </visual>
      <gravity>1</gravity>
      <velocity_decay/>
      <self_collide>0</self_collide>
      <sensor name='imu_sensor' type='imu'>
        <pose>0 0 0 0 -0 0</pose>
        <always_on>1</always_on>
        <visualize>1</visualize>
        <update_rate>1000.0</update_rate>
        <imu>
          <orientation_reference_frame>
            <localization>GRAV_UP</localization>
            <grav_dir_x>1 0 0</grav_dir_x>
          </orientation_reference_frame>
          <angular_velocity>
            <x>
              <noise type='gaussian'>
                <mean>0.0</mean>
                <stddev>0.0</stddev>
              </noise>
            </x>
            <y>
              <noise type='gaussian'>
                <mean>0.0</mean>
                <stddev>0.0</stddev>
              </noise>
            </y>
            <z>
              <noise type='gaussian'>
                <mean>0.0</mean>
                <stddev>0.0</stddev>
              </noise>
            </z>
          </angular_velocity>
          <linear_acceleration>
            <x>
              <noise type='gaussian'>
                <mean>0.0</mean>
                <stddev>0.0</stddev>
              </noise>
            </x>
            <y>
              <noise type='gaussian'>
                <mean>0.0</mean>
                <stddev>0.0</stddev>
              </noise>
            </y>
            <z>
              <noise type='gaussian'>
                <mean>0.0</mean>
                <stddev>0.0</stddev>
              </noise>
            </z>
          </linear_acceleration>
        </imu>
      </sensor>
    </link>
    <link name='left_hip_yaw_link'>
      <pose frame=''>-0.02025 0.055 -0.08 0 -0 0</pose>
      <inertial>
        <pose frame=''>0 0 -0.013803 0 -0 0</pose>
        <mass>0.073374</mass>
        <inertia>
          <ixx>2.6774e-05</ixx>
          <ixy>1.9727e-19</ixy>
          <ixz>-8.7961e-19</ixz>
          <iyy>0.00011478</iyy>
          <iyz>-2.3128e-19</iyz>
          <izz>0.00010743</izz>
        </inertia>
      </inertial>
      <collision name='left_hip_yaw_link_collision'>
        <pose frame=''>0.01625 -0.08 -0.335 1.5708 0 -1.5708</pose>
        <geometry>
          <mesh>
            <scale>1 1 1</scale>
            <uri>model://nubots_nugus_hull/mesh/left_hip_yaw_link.stl</uri>
          </mesh>
        </geometry>
        <surface>
          <contact>
            <ode/>
          </contact>
          <friction>
            <ode>
              <mu>0.98</mu>
              <mu2>0.98</mu2>
            </ode>
          </friction>
        </surface>
      </collision>
      <visual name='left_hip_yaw_link_visual'>
        <pose frame=''>0.01625 -0.08 -0.335 1.5708 0 -1.5708</pose>
        <geometry>
          <mesh>
            <scale>1 1 1</scale>
            <uri>model://nubots_nugus_hull/mesh/left_hip_yaw_link.stl</uri>
          </mesh>
        </geometry>
        <material>
          <script>
            <name>Gazebo/Orange</name>
            <uri>file://media/materials/scripts/gazebo.material</uri>
          </script>
        </material>
      </visual>
      <gravity>1</gravity>
      <velocity_decay/>
      <self_collide>0</self_collide>
    </link>
    <joint name='left_hip_yaw' type='revolute'>
      <child>left_hip_yaw_link</child>
      <parent>trunk_link</parent>
      <axis>
        <xyz>0 0 1</xyz>
        <limit>
          <velocity>5.236</velocity>
        </limit>
        <dynamics>
          <friction>0.5</friction>
          <damping>1</damping>
          <spring_reference>0</spring_reference>
          <spring_stiffness>1.5</spring_stiffness>
        </dynamics>
        <use_parent_model_frame>1</use_parent_model_frame>
      </axis>
    </joint>
    <link name='left_hip_roll_link'>
      <pose frame=''>0.00285 0.055 -0.1238 0 -0 0</pose>
      <inertial>
        <pose frame=''>-0.019434 -0.00025 -0.014536 0 -0 0</pose>
        <mass>0.35844</mass>
        <inertia>
          <ixx>0.00015501</ixx>
          <ixy>-1.7299e-06</ixy>
          <ixz>8.5156e-06</ixz>
          <iyy>0.00032958</iyy>
          <iyz>-2.4435e-07</iyz>
          <izz>0.00027786</izz>
        </inertia>
      </inertial>
      <collision name='left_hip_roll_link_collision'>
        <pose frame=''>0 0 0 0 -0 0</pose>
        <geometry>
          <mesh>
            <scale>1 1 1</scale>
            <uri>model://nubots_nugus_hull/mesh/left_hip_roll_link.stl</uri>
          </mesh>
        </geometry>
        <surface>
          <contact>
            <ode/>
          </contact>
          <friction>
            <ode>
              <mu>0.98</mu>
              <mu2>0.98</mu2>
            </ode>
          </friction>
        </surface>
      </collision>
      <visual name='left_hip_roll_link_visual'>
        <pose frame=''>0 0 0 0 -0 0</pose>
        <geometry>
          <mesh>
            <scale>1 1 1</scale>
            <uri>model://nubots_nugus_hull/mesh/left_hip_roll_link.stl</uri>
          </mesh>
        </geometry>
        <material>
          <script>
            <name>Gazebo/White</name>
            <uri>file://media/materials/scripts/gazebo.material</uri>
          </script>
        </material>
      </visual>
      <gravity>1</gravity>
      <velocity_decay/>
      <self_collide>0</self_collide>
    </link>
    <joint name='left_hip_roll' type='revolute'>
      <child>left_hip_roll_link</child>
      <parent>left_hip_yaw_link</parent>
      <axis>
        <xyz>1 0 0</xyz>
        <limit>
          <velocity>5.236</velocity>
        </limit>
        <dynamics>
          <friction>0.5</friction>
          <damping>1</damping>
          <spring_reference>0</spring_reference>
          <spring_stiffness>1.5</spring_stiffness>
        </dynamics>
        <use_parent_model_frame>1</use_parent_model_frame>
      </axis>
    </joint>
    <link name='left_thigh_link'>
      <pose frame=''>0.00285 0.055 -0.1238 0 -0 0</pose>
      <inertial>
        <pose frame=''>0.003858 -0.000238 -0.1495 0 -0 0</pose>
        <mass>0.38276</mass>
        <inertia>
          <ixx>0.0020952</ixx>
          <ixy>-1.9541e-07</ixy>
          <ixz>-0.00017822</ixz>
          <iyy>0.0020044</iyy>
          <iyz>5.4912e-06</iyz>
          <izz>0.00027919</izz>
        </inertia>
      </inertial>
      <collision name='left_thigh_link_collision'>
        <pose frame=''>-0.0065 -0.08 -0.291 1.5708 0 -1.5708</pose>
        <geometry>
          <mesh>
            <scale>1 1 1</scale>
            <uri>model://nubots_nugus_hull/mesh/left_thigh_link.stl</uri>
          </mesh>
        </geometry>
        <surface>
          <contact>
            <ode/>
          </contact>
          <friction>
            <ode>
              <mu>0.98</mu>
              <mu2>0.98</mu2>
            </ode>
          </friction>
        </surface>
      </collision>
      <visual name='left_thigh_link_visual'>
        <pose frame=''>-0.0065 -0.08 -0.291 1.5708 0 -1.5708</pose>
        <geometry>
          <mesh>
            <scale>1 1 1</scale>
            <uri>model://nubots_nugus_hull/mesh/left_thigh_link.stl</uri>
          </mesh>
        </geometry>
        <material>
          <script>
            <name>Gazebo/Orange</name>
            <uri>file://media/materials/scripts/gazebo.material</uri>
          </script>
        </material>
      </visual>
      <gravity>1</gravity>
      <velocity_decay/>
      <self_collide>0</self_collide>
    </link>
    <joint name='left_hip_pitch' type='revolute'>
      <child>left_thigh_link</child>
      <parent>left_hip_roll_link</parent>
      <axis>
        <xyz>0 1 0</xyz>
        <limit>
          <velocity>5.236</velocity>
        </limit>
        <dynamics>
          <friction>0.5</friction>
          <damping>1</damping>
          <spring_reference>0</spring_reference>
          <spring_stiffness>1.5</spring_stiffness>
        </dynamics>
        <use_parent_model_frame>1</use_parent_model_frame>
      </axis>
    </joint>
    <link name='left_shank_link'>
      <pose frame=''>0.00285 0.055 -0.3238 0 -0 0</pose>
      <inertial>
        <pose frame=''>-0.003378 -0.0012 -0.10469 0 -0 0</pose>
        <mass>0.20549</mass>
        <inertia>
          <ixx>0.0011378</ixx>
          <ixy>-2.8771e-12</ixy>
          <ixz>9.7123e-05</ixz>
          <iyy>0.0010393</iyy>
          <iyz>-1.4479e-11</iyz>
          <izz>0.00019656</izz>
        </inertia>
      </inertial>
      <collision name='left_shank_link_collision'>
        <pose frame=''>-0.0065 -0.08 -0.092 1.5708 0 -1.5708</pose>
        <geometry>
          <mesh>
            <scale>1 1 1</scale>
            <uri>model://nubots_nugus_hull/mesh/left_shank_link.stl</uri>
          </mesh>
        </geometry>
        <surface>
          <contact>
            <ode/>
          </contact>
          <friction>
            <ode>
              <mu>0.98</mu>
              <mu2>0.98</mu2>
            </ode>
          </friction>
        </surface>
      </collision>
      <visual name='left_shank_link_visual'>
        <pose frame=''>-0.0065 -0.08 -0.092 1.5708 0 -1.5708</pose>
        <geometry>
          <mesh>
            <scale>1 1 1</scale>
            <uri>model://nubots_nugus_hull/mesh/left_shank_link.stl</uri>
          </mesh>
        </geometry>
        <material>
          <script>
            <name>Gazebo/Orange</name>
            <uri>file://media/materials/scripts/gazebo.material</uri>
          </script>
        </material>
      </visual>
      <gravity>1</gravity>
      <velocity_decay/>
      <self_collide>0</self_collide>
    </link>
    <joint name='left_knee_pitch' type='revolute'>
      <child>left_shank_link</child>
      <parent>left_thigh_link</parent>
      <axis>
        <xyz>0 1 0</xyz>
        <limit>
          <velocity>5.236</velocity>
        </limit>
        <dynamics>
          <friction>0.5</friction>
          <damping>1</damping>
          <spring_reference>0</spring_reference>
          <spring_stiffness>1.5</spring_stiffness>
        </dynamics>
        <use_parent_model_frame>1</use_parent_model_frame>
      </axis>
    </joint>
    <link name='left_ankle_link'>
      <pose frame=''>0.00835 0.055 -0.5238 0 -0 0</pose>
      <inertial>
        <pose frame=''>-0.019418 -0.001438 0.014538 0 -0 0</pose>
        <mass>0.35903</mass>
        <inertia>
          <ixx>0.00015503</ixx>
          <ixy>-1.738e-06</ixy>
          <ixz>-8.5148e-06</ixz>
          <iyy>0.0003299</iyy>
          <iyz>2.4403e-07</iyz>
          <izz>0.0002782</izz>
        </inertia>
      </inertial>
      <collision name='left_ankle_link_collision'>
        <pose frame=''>0 0 0 0 -0 0</pose>
        <geometry>
          <mesh>
            <scale>1 1 1</scale>
            <uri>model://nubots_nugus_hull/mesh/left_ankle_link.stl</uri>
          </mesh>
        </geometry>
        <surface>
          <contact>
            <ode/>
          </contact>
          <friction>
            <ode>
              <mu>0.98</mu>
              <mu2>0.98</mu2>
            </ode>
          </friction>
        </surface>
      </collision>
      <visual name='left_ankle_link_visual'>
        <pose frame=''>0 0 0 0 -0 0</pose>
        <geometry>
          <mesh>
            <scale>1 1 1</scale>
            <uri>model://nubots_nugus_hull/mesh/left_ankle_link.stl</uri>
          </mesh>
        </geometry>
        <material>
          <script>
            <name>Gazebo/White</name>
            <uri>file://media/materials/scripts/gazebo.material</uri>
          </script>
        </material>
      </visual>
      <gravity>1</gravity>
      <velocity_decay/>
      <self_collide>0</self_collide>
    </link>
    <joint name='left_ankle_pitch' type='revolute'>
      <child>left_ankle_link</child>
      <parent>left_shank_link</parent>
      <axis>
        <xyz>0 1 0</xyz>
        <limit>
          <velocity>5.236</velocity>
        </limit>
        <dynamics>
          <friction>0.5</friction>
          <damping>1</damping>
          <spring_reference>0</spring_reference>
          <spring_stiffness>1.5</spring_stiffness>
        </dynamics>
        <use_parent_model_frame>1</use_parent_model_frame>
      </axis>
    </joint>
    <link name='left_foot_link'>
      <pose frame=''>0.00835 0.055 -0.5238 0 -0 0</pose>
      <inertial>
        <pose frame=''>0.003608 0.008119 -0.03091 0 -0 0</pose>
        <mass>0.1488</mass>
        <inertia>
          <ixx>0.0001853</ixx>
          <ixy>1.1466e-05</ixy>
          <ixz>-8.3793e-06</ixz>
          <iyy>0.00060485</iyy>
          <iyz>-5.9046e-06</iyz>
          <izz>0.00075213</izz>
        </inertia>
      </inertial>
      <collision name='left_foot_link_collision'>
        <pose frame=''>-0.01 -0.08 0.1075 1.5708 0 -1.5708</pose>
        <geometry>
          <mesh>
            <scale>1 1 1</scale>
            <uri>model://nubots_nugus_hull/mesh/left_foot_link_studded.stl</uri>
          </mesh>
        </geometry>
        <surface>
          <friction>
            <ode>
              <mu>INF</mu>
              <mu2>INF</mu2>
              <fdir1>1 0 0</fdir1>
            </ode>
          </friction>
        </surface>
      </collision>
      <visual name='left_foot_link_visual'>
        <pose frame=''>-0.01 -0.08 0.1075 1.5708 0 -1.5708</pose>
        <geometry>
          <mesh>
            <scale>1 1 1</scale>
            <uri>model://nubots_nugus_hull/mesh/left_foot_link_studded.stl</uri>
          </mesh>
        </geometry>
        <material>
          <script>
            <name>Gazebo/Orange</name>
            <uri>file://media/materials/scripts/gazebo.material</uri>
          </script>
        </material>
      </visual>
      <gravity>1</gravity>
      <velocity_decay/>
      <self_collide>0</self_collide>
    </link>
    <joint name='left_ankle_roll' type='revolute'>
      <child>left_foot_link</child>
      <parent>left_ankle_link</parent>
      <axis>
        <xyz>1 0 0</xyz>
        <limit>
          <velocity>5.236</velocity>
        </limit>
        <dynamics>
          <friction>0.5</friction>
          <damping>1</damping>
          <spring_reference>0</spring_reference>
          <spring_stiffness>1.5</spring_stiffness>
        </dynamics>
        <use_parent_model_frame>1</use_parent_model_frame>
      </axis>
    </joint>
    <link name='left_shoulder_pitch_link'>
      <pose frame=''>-0.0205 0.0745 0.1075 -0 0 0</pose>
      <inertial>
        <pose frame=''>-0 0.014621 -0 0 -0 0</pose>
        <mass>0.025434</mass>
        <inertia>
          <ixx>6.7511e-06</ixx>
          <ixy>6.4644e-21</ixy>
          <ixz>-3.365e-21</ixz>
          <iyy>1.2425e-05</iyy>
          <iyz>-4.6109e-22</iyz>
          <izz>1.4317e-05</izz>
        </inertia>
      </inertial>
      <collision name='left_shoulder_pitch_link_collision'>
        <pose frame=''>0 -0.15 0 1.5708 0 -1.5708</pose>
        <geometry>
          <mesh>
            <scale>1 1 1</scale>
            <uri>model://nubots_nugus_hull/mesh/left_shoulder_pitch_link.stl</uri>
          </mesh>
        </geometry>
        <surface>
          <contact>
            <ode/>
          </contact>
          <friction>
            <ode>
              <mu>0.98</mu>
              <mu2>0.98</mu2>
            </ode>
          </friction>
        </surface>
      </collision>
      <visual name='left_shoulder_pitch_link_visual'>
        <pose frame=''>0 -0.15 0 1.5708 0 -1.5708</pose>
        <geometry>
          <mesh>
            <scale>1 1 1</scale>
            <uri>model://nubots_nugus_hull/mesh/left_shoulder_pitch_link.stl</uri>
          </mesh>
        </geometry>
        <material>
          <script>
            <name>Gazebo/White</name>
            <uri>file://media/materials/scripts/gazebo.material</uri>
          </script>
        </material>
      </visual>
      <gravity>1</gravity>
      <velocity_decay/>
      <self_collide>0</self_collide>
    </link>
    <joint name='left_shoulder_pitch' type='revolute'>
      <child>left_shoulder_pitch_link</child>
      <parent>trunk_link</parent>
      <axis>
        <xyz>-0 1 -0</xyz>
        <limit>
          <velocity>5.236</velocity>
        </limit>
        <dynamics>
          <friction>0.5</friction>
          <damping>1</damping>
          <spring_reference>0</spring_reference>
          <spring_stiffness>1.5</spring_stiffness>
        </dynamics>
        <use_parent_model_frame>1</use_parent_model_frame>
      </axis>
    </joint>
    <link name='left_upper_arm_link'>
      <pose frame=''>-0.0205 0.1225 0.0975 -0 0 0</pose>
      <inertial>
        <pose frame=''>0.001367 0.000227 -0.049517 0 -0 0</pose>
        <mass>0.2575</mass>
        <inertia>
          <ixx>0.00081539</ixx>
          <ixy>1.1134e-07</ixy>
          <ixz>-5.114e-05</ixz>
          <iyy>0.0007994</iyy>
          <iyz>-2.4756e-06</iyz>
          <izz>0.00012883</izz>
        </inertia>
      </inertial>
      <collision name='left_upper_arm_link_collision'>
        <pose frame=''>0 -0.245 0 3.14159 -0 1.5708</pose>
        <geometry>
          <mesh>
            <scale>1 1 1</scale>
            <uri>model://nubots_nugus_hull/mesh/left_upper_arm_link.stl</uri>
          </mesh>
        </geometry>
        <surface>
          <contact>
            <ode/>
          </contact>
          <friction>
            <ode>
              <mu>0.98</mu>
              <mu2>0.98</mu2>
            </ode>
          </friction>
        </surface>
      </collision>
      <visual name='left_upper_arm_link_visual'>
        <pose frame=''>0 -0.245 0 3.14159 -0 1.5708</pose>
        <geometry>
          <mesh>
            <scale>1 1 1</scale>
            <uri>model://nubots_nugus_hull/mesh/left_upper_arm_link.stl</uri>
          </mesh>
        </geometry>
        <material>
          <script>
            <name>Gazebo/Orange</name>
            <uri>file://media/materials/scripts/gazebo.material</uri>
          </script>
        </material>
      </visual>
      <gravity>1</gravity>
      <velocity_decay/>
      <self_collide>0</self_collide>
    </link>
    <joint name='left_shoulder_roll' type='revolute'>
      <child>left_upper_arm_link</child>
      <parent>left_shoulder_pitch_link</parent>
      <axis>
        <xyz>1 0 0</xyz>
        <limit>
          <velocity>5.236</velocity>
        </limit>
        <dynamics>
          <friction>0.5</friction>
          <damping>1</damping>
          <spring_reference>0</spring_reference>
          <spring_stiffness>1.5</spring_stiffness>
        </dynamics>
        <use_parent_model_frame>1</use_parent_model_frame>
      </axis>
    </joint>
    <link name='left_lower_arm_link'>
      <pose frame=''>0.0065 0.1225 -0.0615 -0 -0 0</pose>
      <inertial>
        <pose frame=''>0.001742 -6.5e-05 -0.059095 0 -0 0</pose>
        <mass>0.23502</mass>
        <inertia>
          <ixx>0.0011616</ixx>
          <ixy>-2.6303e-07</ixy>
          <ixz>-7.2367e-05</ixz>
          <iyy>0.0011751</iyy>
          <iyz>9.5624e-06</iyz>
          <izz>0.00010214</izz>
        </inertia>
      </inertial>
      <collision name='left_lower_arm_link_collision'>
        <pose frame=''>-0.0275 -0.245 0.158 3.14159 -0 1.5708</pose>
        <geometry>
          <mesh>
            <scale>1 1 1</scale>
            <uri>model://nubots_nugus_hull/mesh/left_lower_arm_link.stl</uri>
          </mesh>
        </geometry>
        <surface>
          <contact>
            <ode/>
          </contact>
          <friction>
            <ode>
              <mu>0.98</mu>
              <mu2>0.98</mu2>
            </ode>
          </friction>
        </surface>
      </collision>
      <visual name='left_lower_arm_link_visual'>
        <pose frame=''>-0.0275 -0.245 0.158 3.14159 -0 1.5708</pose>
        <geometry>
          <mesh>
            <scale>1 1 1</scale>
            <uri>model://nubots_nugus_hull/mesh/left_lower_arm_link.stl</uri>
          </mesh>
        </geometry>
        <material>
          <script>
            <name>Gazebo/Orange</name>
            <uri>file://media/materials/scripts/gazebo.material</uri>
          </script>
        </material>
      </visual>
      <gravity>1</gravity>
      <velocity_decay/>
      <self_collide>0</self_collide>
    </link>
    <joint name='left_elbow_pitch' type='revolute'>
      <child>left_lower_arm_link</child>
      <parent>left_upper_arm_link</parent>
      <axis>
        <xyz>-0 1 -0</xyz>
        <limit>
          <velocity>5.236</velocity>
        </limit>
        <dynamics>
          <friction>0.5</friction>
          <damping>1</damping>
          <spring_reference>0</spring_reference>
          <spring_stiffness>1.5</spring_stiffness>
        </dynamics>
        <use_parent_model_frame>1</use_parent_model_frame>
      </axis>
    </joint>
    <link name='neck_link'>
      <pose frame=''>-0.0285 0 0.1365 -0 0 -0.145633</pose>
      <inertial>
        <pose frame=''>2.2e-05 0.000648 0.033208 0 -0 0</pose>
        <mass>0.15587</mass>
        <inertia>
          <ixx>7.5209e-05</ixx>
          <ixy>-1.8422e-06</ixy>
          <ixz>-4.9817e-07</ixz>
          <iyy>6.2999e-05</iyy>
          <iyz>-9.9088e-08</iyz>
          <izz>3.826e-05</izz>
        </inertia>
      </inertial>
      <collision name='neck_link_collision'>
        <pose frame=''>0 0 0 0 -0 0</pose>
        <geometry>
          <mesh>
            <scale>1 1 1</scale>
            <uri>model://nubots_nugus_hull/mesh/neck_link.stl</uri>
          </mesh>
        </geometry>
        <surface>
          <contact>
            <ode/>
          </contact>
          <friction>
            <ode>
              <mu>0.98</mu>
              <mu2>0.98</mu2>
            </ode>
          </friction>
        </surface>
      </collision>
      <visual name='neck_link_visual'>
        <pose frame=''>0 0 0 0 -0 0</pose>
        <geometry>
          <mesh>
            <scale>1 1 1</scale>
            <uri>model://nubots_nugus_hull/mesh/neck_link.stl</uri>
          </mesh>
        </geometry>
        <material>
          <script>
            <name>Gazebo/White</name>
            <uri>file://media/materials/scripts/gazebo.material</uri>
          </script>
        </material>
      </visual>
      <gravity>1</gravity>
      <velocity_decay/>
      <self_collide>0</self_collide>
    </link>
    <joint name='neck_yaw' type='revolute'>
      <child>neck_link</child>
      <parent>trunk_link</parent>
      <axis>
        <xyz>0 0 1</xyz>
        <limit>
          <velocity>5.236</velocity>
        </limit>
        <dynamics>
          <friction>0.5</friction>
          <damping>1</damping>
          <spring_reference>0</spring_reference>
          <spring_stiffness>1.5</spring_stiffness>
        </dynamics>
        <use_parent_model_frame>1</use_parent_model_frame>
      </axis>
    </joint>
    <link name='head_link'>
      <pose frame=''>-0.0285 0 0.187 -0 -0 0</pose>
      <inertial>
        <pose frame=''>0.014358 0.000552 0.069919 0 -0 0</pose>
        <mass>0.40746</mass>
        <inertia>
          <ixx>0.0014813</ixx>
          <ixy>3.1631e-07</ixy>
          <ixz>-4.1003e-05</ixz>
          <iyy>0.0016361</iyy>
          <iyz>6.7483e-07</iyz>
          <izz>0.0017353</izz>
        </inertia>
      </inertial>
      <collision name='head_link_collision'>
        <pose frame=''>0.005 0 0.0685 1.5708 -0 1.5708</pose>
        <geometry>
          <mesh>
            <scale>1 1 1</scale>
            <uri>model://nubots_nugus_hull/mesh/head_link.stl</uri>
          </mesh>
        </geometry>
      </collision>
      <visual name='head_link_visual'>
        <pose frame=''>0.005 0 0.0685 1.5708 -0 1.5708</pose>
        <geometry>
          <mesh>
            <scale>1 1 1</scale>
            <uri>model://nubots_nugus_hull/mesh/head_link.stl</uri>
          </mesh>
        </geometry>
      </visual>
    </link>
    <joint name='head_pitch' type='revolute'>
      <child>head_link</child>
      <parent>neck_link</parent>
      <axis>
        <xyz>0 1 -0</xyz>
        <limit>
          <velocity>5.236</velocity>
        </limit>
        <dynamics>
          <friction>0.5</friction>
          <damping>1</damping>
          <spring_reference>0</spring_reference>
          <spring_stiffness>1.5</spring_stiffness>
        </dynamics>
        <use_parent_model_frame>1</use_parent_model_frame>
      </axis>
    </joint>
    <link name='right_hip_yaw_link'>
      <pose frame=''>-0.02025 -0.055 -0.08 0 -0 0</pose>
      <inertial>
        <pose frame=''>0 0 -0.013803 0 -0 0</pose>
        <mass>0.073374</mass>
        <inertia>
          <ixx>2.6774e-05</ixx>
          <ixy>1.5536e-19</ixy>
          <ixz>-9.0622e-19</ixz>
          <iyy>0.00011478</iyy>
          <iyz>-2.2736e-19</iyz>
          <izz>0.00010743</izz>
        </inertia>
      </inertial>
      <collision name='right_hip_yaw_link_collision'>
        <pose frame=''>0.01625 0.03 -0.335 1.5708 0 -1.5708</pose>
        <geometry>
          <mesh>
            <scale>1 1 1</scale>
            <uri>model://nubots_nugus_hull/mesh/right_hip_yaw_link.stl</uri>
          </mesh>
        </geometry>
        <surface>
          <contact>
            <ode/>
          </contact>
          <friction>
            <ode>
              <mu>0.98</mu>
              <mu2>0.98</mu2>
            </ode>
          </friction>
        </surface>
      </collision>
      <visual name='right_hip_yaw_link_visual'>
        <pose frame=''>0.01625 0.03 -0.335 1.5708 0 -1.5708</pose>
        <geometry>
          <mesh>
            <scale>1 1 1</scale>
            <uri>model://nubots_nugus_hull/mesh/right_hip_yaw_link.stl</uri>
          </mesh>
        </geometry>
        <material>
          <script>
            <name>Gazebo/Orange</name>
            <uri>file://media/materials/scripts/gazebo.material</uri>
          </script>
        </material>
      </visual>
      <gravity>1</gravity>
      <velocity_decay/>
      <self_collide>0</self_collide>
    </link>
    <joint name='right_hip_yaw' type='revolute'>
      <child>right_hip_yaw_link</child>
      <parent>trunk_link</parent>
      <axis>
        <xyz>0 0 1</xyz>
        <limit>
          <velocity>5.236</velocity>
        </limit>
        <dynamics>
          <friction>0.5</friction>
          <damping>1</damping>
          <spring_reference>0</spring_reference>
          <spring_stiffness>1.5</spring_stiffness>
        </dynamics>
        <use_parent_model_frame>1</use_parent_model_frame>
      </axis>
    </joint>
    <link name='right_hip_roll_link'>
      <pose frame=''>-0.027464 -0.055 -0.1238 0 -0 0</pose>
      <inertial>
        <pose frame=''>0.010896 0.000238 -0.014538 0 -0 0</pose>
        <mass>0.35903</mass>
        <inertia>
          <ixx>0.00015503</ixx>
          <ixy>1.738e-06</ixy>
          <ixz>8.5148e-06</ixz>
          <iyy>0.0003299</iyy>
          <iyz>2.4403e-07</iyz>
          <izz>0.0002782</izz>
        </inertia>
      </inertial>
      <collision name='right_hip_roll_link_collision'>
        <pose frame=''>0 0 0 0 -0 0</pose>
        <geometry>
          <mesh>
            <scale>1 1 1</scale>
            <uri>model://nubots_nugus_hull/mesh/right_hip_roll_link.stl</uri>
          </mesh>
        </geometry>
        <surface>
          <contact>
            <ode/>
          </contact>
          <friction>
            <ode>
              <mu>0.98</mu>
              <mu2>0.98</mu2>
            </ode>
          </friction>
        </surface>
      </collision>
      <visual name='right_hip_roll_link_visual'>
        <pose frame=''>0 0 0 0 -0 0</pose>
        <geometry>
          <mesh>
            <scale>1 1 1</scale>
            <uri>model://nubots_nugus_hull/mesh/right_hip_roll_link.stl</uri>
          </mesh>
        </geometry>
        <material>
          <script>
            <name>Gazebo/White</name>
            <uri>file://media/materials/scripts/gazebo.material</uri>
            <name>Gazebo/TurquoiseGlowOutline</name>
            <uri>file://media/materials/scripts/gazebo.material</uri>
          </script>
        </material>
      </visual>
      <gravity>1</gravity>
      <velocity_decay/>
      <self_collide>0</self_collide>
    </link>
    <joint name='right_hip_roll' type='revolute'>
      <child>right_hip_roll_link</child>
      <parent>right_hip_yaw_link</parent>
      <axis>
        <xyz>1 0 0</xyz>
        <limit>
          <velocity>5.236</velocity>
        </limit>
        <dynamics>
          <friction>0.5</friction>
          <damping>1</damping>
          <spring_reference>0</spring_reference>
          <spring_stiffness>1.5</spring_stiffness>
        </dynamics>
        <use_parent_model_frame>1</use_parent_model_frame>
      </axis>
    </joint>
    <link name='right_thigh_link'>
      <pose frame=''>0.00285 -0.055 -0.1238 0 -0 0</pose>
      <inertial>
        <pose frame=''>0.003855 0.000238 -0.1495 0 -0 0</pose>
        <mass>0.38276</mass>
        <inertia>
          <ixx>0.0020951</ixx>
          <ixy>1.8755e-07</ixy>
          <ixz>-0.00017816</ixz>
          <iyy>0.0020043</iyy>
          <iyz>-5.4867e-06</iyz>
          <izz>0.00027919</izz>
        </inertia>
      </inertial>
      <collision name='right_thigh_link_collision'>
        <pose frame=''>-0.0065 0.03 -0.291 1.5708 0 -1.5708</pose>
        <geometry>
          <mesh>
            <scale>1 1 1</scale>
            <uri>model://nubots_nugus_hull/mesh/right_thigh_link.stl</uri>
          </mesh>
        </geometry>
        <surface>
          <contact>
            <ode/>
          </contact>
          <friction>
            <ode>
              <mu>0.98</mu>
              <mu2>0.98</mu2>
            </ode>
          </friction>
        </surface>
      </collision>
      <visual name='right_thigh_link_visual'>
        <pose frame=''>-0.0065 0.03 -0.291 1.5708 0 -1.5708</pose>
        <geometry>
          <mesh>
            <scale>1 1 1</scale>
            <uri>model://nubots_nugus_hull/mesh/right_thigh_link.stl</uri>
          </mesh>
        </geometry>
        <material>
          <script>
            <name>Gazebo/Orange</name>
            <uri>file://media/materials/scripts/gazebo.material</uri>
          </script>
        </material>
      </visual>
      <gravity>1</gravity>
      <velocity_decay/>
      <self_collide>0</self_collide>
    </link>
    <joint name='right_hip_pitch' type='revolute'>
      <child>right_thigh_link</child>
      <parent>right_hip_roll_link</parent>
      <axis>
        <xyz>0 1 0</xyz>
        <limit>
          <velocity>5.236</velocity>
        </limit>
        <dynamics>
          <friction>0.5</friction>
          <damping>1</damping>
          <spring_reference>0</spring_reference>
          <spring_stiffness>1.5</spring_stiffness>
        </dynamics>
        <use_parent_model_frame>1</use_parent_model_frame>
      </axis>
    </joint>
    <link name='right_shank_link'>
      <pose frame=''>0.00285 -0.055 -0.3238 0 -0 0</pose>
      <inertial>
        <pose frame=''>-0.003378 0 -0.10469 0 -0 0</pose>
        <mass>0.20549</mass>
        <inertia>
          <ixx>0.0011378</ixx>
          <ixy>-2.8771e-12</ixy>
          <ixz>9.7123e-05</ixz>
          <iyy>0.0010393</iyy>
          <iyz>-1.4479e-11</iyz>
          <izz>0.00019656</izz>
        </inertia>
      </inertial>
      <collision name='right_shank_link_collision'>
        <pose frame=''>-0.0065 0.03 -0.092 1.5708 0 -1.5708</pose>
        <geometry>
          <mesh>
            <scale>1 1 1</scale>
            <uri>model://nubots_nugus_hull/mesh/right_shank_link.stl</uri>
          </mesh>
        </geometry>
        <surface>
          <contact>
            <ode/>
          </contact>
          <friction>
            <ode>
              <mu>0.98</mu>
              <mu2>0.98</mu2>
            </ode>
          </friction>
        </surface>
      </collision>
      <visual name='right_shank_link_visual'>
        <pose frame=''>-0.0065 0.03 -0.092 1.5708 0 -1.5708</pose>
        <geometry>
          <mesh>
            <scale>1 1 1</scale>
            <uri>model://nubots_nugus_hull/mesh/right_shank_link.stl</uri>
          </mesh>
        </geometry>
        <material>
          <script>
            <name>Gazebo/Orange</name>
            <uri>file://media/materials/scripts/gazebo.material</uri>
          </script>
        </material>
      </visual>
      <gravity>1</gravity>
      <velocity_decay/>
      <self_collide>0</self_collide>
    </link>
    <joint name='right_knee_pitch' type='revolute'>
      <child>right_shank_link</child>
      <parent>right_thigh_link</parent>
      <axis>
        <xyz>0 1 0</xyz>
        <limit>
          <velocity>5.236</velocity>
        </limit>
        <dynamics>
          <friction>0.5</friction>
          <damping>1</damping>
          <spring_reference>0</spring_reference>
          <spring_stiffness>1.5</spring_stiffness>
        </dynamics>
        <use_parent_model_frame>1</use_parent_model_frame>
      </axis>
    </joint>
    <link name='right_ankle_link'>
      <pose frame=''>0.00835 -0.055 -0.5238 0 -0 0</pose>
      <inertial>
        <pose frame=''>-0.019434 0.00025 0.014536 0 -0 0</pose>
        <mass>0.35844</mass>
        <inertia>
          <ixx>0.00015501</ixx>
          <ixy>1.7299e-06</ixy>
          <ixz>-8.5156e-06</ixz>
          <iyy>0.00032958</iyy>
          <iyz>-2.4435e-07</iyz>
          <izz>0.00027786</izz>
        </inertia>
      </inertial>
      <collision name='right_ankle_link_collision'>
        <pose frame=''>0 0 0 0 -0 0</pose>
        <geometry>
          <mesh>
            <scale>1 1 1</scale>
            <uri>model://nubots_nugus_hull/mesh/right_ankle_link.stl</uri>
          </mesh>
        </geometry>
        <surface>
          <contact>
            <ode/>
          </contact>
          <friction>
            <ode>
              <mu>0.98</mu>
              <mu2>0.98</mu2>
            </ode>
          </friction>
        </surface>
      </collision>
      <visual name='right_ankle_link_visual'>
        <pose frame=''>0 0 0 0 -0 0</pose>
        <geometry>
          <mesh>
            <scale>1 1 1</scale>
            <uri>model://nubots_nugus_hull/mesh/right_ankle_link.stl</uri>
          </mesh>
        </geometry>
        <material>
          <script>
            <name>Gazebo/White</name>
            <uri>file://media/materials/scripts/gazebo.material</uri>
          </script>
        </material>
      </visual>
      <gravity>1</gravity>
      <velocity_decay/>
      <self_collide>0</self_collide>
    </link>
    <joint name='right_ankle_pitch' type='revolute'>
      <child>right_ankle_link</child>
      <parent>right_shank_link</parent>
      <axis>
        <xyz>0 1 0</xyz>
        <limit>
          <velocity>5.236</velocity>
        </limit>
        <dynamics>
          <friction>0.5</friction>
          <damping>1</damping>
          <spring_reference>0</spring_reference>
          <spring_stiffness>1.5</spring_stiffness>
        </dynamics>
        <use_parent_model_frame>1</use_parent_model_frame>
      </axis>
    </joint>
    <link name='right_foot_link'>
      <pose frame=''>0.00835 -0.055 -0.5238 0 -0 0</pose>
      <inertial>
        <pose frame=''>0.003669 -0.008117 -0.030903 0 -0 0</pose>
        <mass>0.1488</mass>
        <inertia>
          <ixx>0.00018527</ixx>
          <ixy>-1.1504e-05</ixy>
          <ixz>-7.2667e-06</ixz>
          <iyy>0.00060485</iyy>
          <iyz>5.8883e-06</iyz>
          <izz>0.00075217</izz>
        </inertia>
      </inertial>
      <collision name='right_foot_link_collision'>
        <pose frame=''>-0.01 0.03 0.1075 1.5708 0 -1.5708</pose>
        <geometry>
          <mesh>
            <scale>1 1 1</scale>
            <uri>model://nubots_nugus_hull/mesh/right_foot_link_studded.stl</uri>
          </mesh>
        </geometry>
        <surface>
          <friction>
            <ode>
              <mu>INF</mu>
              <mu2>INF</mu2>
              <fdir1>1 0 0</fdir1>
            </ode>
          </friction>
        </surface>
      </collision>
      <visual name='right_foot_link_visual'>
        <pose frame=''>-0.01 0.03 0.1075 1.5708 0 -1.5708</pose>
        <geometry>
          <mesh>
            <scale>1 1 1</scale>
            <uri>model://nubots_nugus_hull/mesh/right_foot_link_studded.stl</uri>
          </mesh>
        </geometry>
        <material>
          <script>
            <name>Gazebo/Orange</name>
            <uri>file://media/materials/scripts/gazebo.material</uri>
          </script>
        </material>
      </visual>
      <gravity>1</gravity>
      <velocity_decay/>
      <self_collide>0</self_collide>
    </link>
    <joint name='right_ankle_roll' type='revolute'>
      <child>right_foot_link</child>
      <parent>right_ankle_link</parent>
      <axis>
        <xyz>1 0 0</xyz>
        <limit>
          <velocity>5.236</velocity>
        </limit>
        <dynamics>
          <friction>0.5</friction>
          <damping>1</damping>
          <spring_reference>0</spring_reference>
          <spring_stiffness>1.5</spring_stiffness>
        </dynamics>
        <use_parent_model_frame>1</use_parent_model_frame>
      </axis>
    </joint>
    <link name='right_shoulder_pitch_link'>
      <pose frame=''>-0.0205 -0.0745 0.1075 0 0 0</pose>
      <inertial>
        <pose frame=''>0 -0.014621 0 0 -0 0</pose>
        <mass>0.025434</mass>
        <inertia>
          <ixx>6.7511e-06</ixx>
          <ixy>1.5595e-20</ixy>
          <ixz>-5.4198e-21</ixz>
          <iyy>1.2425e-05</iyy>
          <iyz>-2.4006e-20</iyz>
          <izz>1.4317e-05</izz>
        </inertia>
      </inertial>
      <collision name='right_shoulder_pitch_link_collision'>
        <pose frame=''>0 -0.0025 0 1.5708 0 -1.5708</pose>
        <geometry>
          <mesh>
            <scale>1 1 1</scale>
            <uri>model://nubots_nugus_hull/mesh/right_shoulder_pitch_link.stl</uri>
          </mesh>
        </geometry>
        <surface>
          <contact>
            <ode/>
          </contact>
          <friction>
            <ode>
              <mu>0.98</mu>
              <mu2>0.98</mu2>
            </ode>
          </friction>
        </surface>
      </collision>
      <visual name='right_shoulder_pitch_link_visual'>
        <pose frame=''>0 -0.0025 0 1.5708 0 -1.5708</pose>
        <geometry>
          <mesh>
            <scale>1 1 1</scale>
            <uri>model://nubots_nugus_hull/mesh/right_shoulder_pitch_link.stl</uri>
          </mesh>
        </geometry>
        <material>
          <script>
            <name>Gazebo/White</name>
            <uri>file://media/materials/scripts/gazebo.material</uri>
          </script>
        </material>
      </visual>
      <gravity>1</gravity>
      <velocity_decay/>
      <self_collide>0</self_collide>
    </link>
    <joint name='right_shoulder_pitch' type='revolute'>
      <child>right_shoulder_pitch_link</child>
      <parent>trunk_link</parent>
      <axis>
        <xyz>0 1 0</xyz>
        <limit>
          <velocity>5.236</velocity>
        </limit>
        <dynamics>
          <friction>0.5</friction>
          <damping>1</damping>
          <spring_reference>0</spring_reference>
          <spring_stiffness>1.5</spring_stiffness>
        </dynamics>
        <use_parent_model_frame>1</use_parent_model_frame>
      </axis>
    </joint>
    <link name='right_upper_arm_link'>
      <pose frame=''>-0.0205 -0.1225 0.0975 -0 0 0</pose>
      <inertial>
        <pose frame=''>0.001367 0.000227 -0.049517 0 -0 0</pose>
        <mass>0.2575</mass>
        <inertia>
          <ixx>0.00081539</ixx>
          <ixy>1.1134e-07</ixy>
          <ixz>-5.114e-05</ixz>
          <iyy>0.0007994</iyy>
          <iyz>-2.4756e-06</iyz>
          <izz>0.00012883</izz>
        </inertia>
      </inertial>
      <collision name='right_upper_arm_link_collision'>
        <pose frame=''>0 0 0 3.14159 -0 1.5708</pose>
        <geometry>
          <mesh>
            <scale>1 1 1</scale>
            <uri>model://nubots_nugus_hull/mesh/right_shoulder_arm_link.stl</uri>
          </mesh>
        </geometry>
        <surface>
          <contact>
            <ode/>
          </contact>
          <friction>
            <ode>
              <mu>0.98</mu>
              <mu2>0.98</mu2>
            </ode>
          </friction>
        </surface>
      </collision>
      <visual name='right_upper_arm_link_visual'>
        <pose frame=''>0 0 0 3.14159 -0 1.5708</pose>
        <geometry>
          <mesh>
            <scale>1 1 1</scale>
            <uri>model://nubots_nugus_hull/mesh/right_shoulder_arm_link.stl</uri>
          </mesh>
        </geometry>
        <material>
          <script>
            <name>Gazebo/Orange</name>
            <uri>file://media/materials/scripts/gazebo.material</uri>
          </script>
        </material>
      </visual>
      <gravity>1</gravity>
      <velocity_decay/>
      <self_collide>0</self_collide>
    </link>
    <joint name='right_shoulder_roll' type='revolute'>
      <child>right_upper_arm_link</child>
      <parent>right_shoulder_pitch_link</parent>
      <axis>
        <xyz>1 0 -0</xyz>
        <limit>
          <velocity>5.236</velocity>
        </limit>
        <dynamics>
          <friction>0.5</friction>
          <damping>1</damping>
          <spring_reference>0</spring_reference>
          <spring_stiffness>1.5</spring_stiffness>
        </dynamics>
        <use_parent_model_frame>1</use_parent_model_frame>
      </axis>
    </joint>
    <link name='right_lower_arm_link'>
      <pose frame=''>0.0065 -0.1225 -0.0615 0.040206 0.001607 0.010034</pose>
      <inertial>
        <pose frame=''>0.00185 -0.000917 -0.059095 0 -0 0</pose>
        <mass>0.23502</mass>
        <inertia>
          <ixx>0.0011613</ixx>
          <ixy>-5.8221e-07</ixy>
          <ixz>-7.4224e-05</ixz>
          <iyy>0.0011747</iyy>
          <iyz>2.0082e-05</iyz>
          <izz>0.00010273</izz>
        </inertia>
      </inertial>
      <collision name='right_lower_arm_link_collision'>
        <pose frame=''>-0.0275 0 0.158 3.14159 -0 1.5708</pose>
        <geometry>
          <mesh>
            <scale>1 1 1</scale>
            <uri>model://nubots_nugus_hull/mesh/right_lower_arm_link.stl</uri>
          </mesh>
        </geometry>
        <surface>
          <contact>
            <ode/>
          </contact>
          <friction>
            <ode>
              <mu>0.98</mu>
              <mu2>0.98</mu2>
            </ode>
          </friction>
        </surface>
      </collision>
      <visual name='right_lower_arm_link_visual'>
        <pose frame=''>-0.0275 0 0.158 3.14159 -0 1.5708</pose>
        <geometry>
          <mesh>
            <scale>1 1 1</scale>
            <uri>model://nubots_nugus_hull/mesh/right_lower_arm_link.stl</uri>
          </mesh>
        </geometry>
        <material>
          <script>
            <name>Gazebo/Orange</name>
            <uri>file://media/materials/scripts/gazebo.material</uri>
          </script>
        </material>
      </visual>
      <gravity>1</gravity>
      <velocity_decay/>
      <self_collide>0</self_collide>
    </link>
    <joint name='right_elbow_pitch' type='revolute'>
      <child>right_lower_arm_link</child>
      <parent>right_upper_arm_link</parent>
      <axis>
        <xyz>-0 1 -0</xyz>
        <limit>
          <velocity>5.236</velocity>
        </limit>
        <dynamics>
          <friction>0.5</friction>
          <damping>1</damping>
          <spring_reference>0</spring_reference>
          <spring_stiffness>1.5</spring_stiffness>
        </dynamics>
        <use_parent_model_frame>1</use_parent_model_frame>
      </axis>
    </joint>
    <static>0</static>
  </model>
</sdf>
