<?xml version="1.0" ?>
<sdf version="1.6">
  <!--NUgus SDF Model-->
  <!--Last updated: 28 Aug 2019 15:08:22-->
  <model name="nubots_nugus_hull">
    <pose frame="">0.000000000 0.000000000 0.000000000 0.000000000 0.000000000 0.000000000</pose>
    <!--LINK: torso-->
    <link name="torso">
      <pose frame="">0.000000000 0.000000000 0.000000000 0.000000000 0.000000000 1.570796327</pose>
      <inertial>
        <pose frame="">0.000000000 0.000339000 0.112557000 0.000000000 0.000000000 0.000000000</pose>
        <mass>1.9581</mass>
        <inertia>
          <ixx>0.0316879323</ixx>
          <ixy>0</ixy>
          <ixz>0</ixz>
          <iyy>0.0366712968</iyy>
          <iyz>-0.00022557312</iyz>
          <izz>0.01878092034</izz>
        </inertia>
      </inertial>
      <collision name="torso_collision">
        <pose frame="">0.000000000 0.000000000 0.000000000 0.000000000 0.000000000 0.000000000</pose>
        <geometry>
          <mesh>
            <scale>1 1 1</scale>
            <uri>model://nubots_nugus_hull/mesh/torso.stl</uri>
          </mesh>
        </geometry>
        <surface>
          <contact>
            <ode/>
          </contact>
          <friction>
            <ode>
              <mu>0.98</mu>
              <mu2>0.98</mu2>
              <slip1>0.001</slip1>
              <slip2>0.001</slip2>
            </ode>
            <torsional>
              <coefficient>0.8</coefficient>
              <patch_radius>1.0</patch_radius>
            </torsional>
          </friction>
        </surface>
      </collision>
      <visual name="torso_visual">
        <pose frame="">0.000000000 0.000000000 0.000000000 0.000000000 0.000000000 0.000000000</pose>
        <geometry>
          <mesh>
            <scale>1 1 1</scale>
            <uri>model://nubots_nugus_hull/mesh/torso.stl</uri>
          </mesh>
        </geometry>
        <material>
          <script>
            <name>Gazebo/Grey</name>
            <uri>file://media/materials/scripts/gazebo.material</uri>
          </script>
        </material>
      </visual>
      <gravity>1</gravity>
      <self_collide/>
      <sensor name="imu_sensor" type="imu">
        <pose frame="">0.000000000 0.000000000 0.000000000 0.000000000 0.000000000 0.000000000</pose>
        <always_on>1</always_on>
        <visualize>1</visualize>
        <update_rate>100</update_rate>
        <imu>
          <orientation_reference_frame>
            <localization>GRAV_UP</localization>
            <grav_dir_x>1 0 0</grav_dir_x>
          </orientation_reference_frame>
          <angular_velocity>
            <x>
              <noise type="gaussian">
                <mean>0.0</mean>
              </noise>
            </x>
            <y>
              <noise type="gaussian">
                <mean>0.0</mean>
              </noise>
            </y>
            <z>
              <noise type="gaussian">
                <mean>0.0</mean>
              </noise>
            </z>
          </angular_velocity>
          <linear_acceleration>
            <x>
              <noise type="gaussian">
                <mean>0.0</mean>
              </noise>
            </x>
            <y>
              <noise type="gaussian">
                <mean>0.0</mean>
              </noise>
            </y>
            <z>
              <noise type="gaussian">
                <mean>0.0</mean>
              </noise>
            </z>
          </linear_acceleration>
        </imu>
      </sensor>
    </link>
    <!--LINK: right_shoulder-->
    <link name="right_shoulder">
      <pose frame="">0.005000000 -0.115000000 0.180000000 -1.570796327 0.000000000 1.570796327</pose>
      <inertial>
        <pose frame="">0.003491000 -0.001684000 0.003753000 0.000000000 0.000000000 0.000000000</pose>
        <mass>0.06</mass>
        <inertia>
          <ixx>7.632e-06</ixx>
          <ixy>2.4e-08</ixy>
          <ixz>-4.2e-07</ixz>
          <iyy>5.82e-06</iyy>
          <iyz>7.2e-08</iyz>
          <izz>7.536e-06</izz>
        </inertia>
      </inertial>
      <collision name="right_shoulder_collision">
        <pose frame="">0.000000000 0.000000000 0.000000000 0.000000000 0.000000000 0.000000000</pose>
        <geometry>
          <mesh>
            <scale>1 1 1</scale>
            <uri>model://nubots_nugus_hull/mesh/right_shoulder.stl</uri>
          </mesh>
        </geometry>
        <surface>
          <contact>
            <ode/>
          </contact>
          <friction>
            <ode>
              <mu>0.98</mu>
              <mu2>0.98</mu2>
              <slip1>0.001</slip1>
              <slip2>0.001</slip2>
            </ode>
            <torsional>
              <coefficient>0.8</coefficient>
              <patch_radius>1.0</patch_radius>
            </torsional>
          </friction>
        </surface>
      </collision>
      <visual name="right_shoulder_visual">
        <pose frame="">0.000000000 0.000000000 0.000000000 0.000000000 0.000000000 0.000000000</pose>
        <geometry>
          <mesh>
            <scale>1 1 1</scale>
            <uri>model://nubots_nugus_hull/mesh/right_shoulder.stl</uri>
          </mesh>
        </geometry>
        <material>
          <script>
            <name>Gazebo/Grey</name>
            <uri>file://media/materials/scripts/gazebo.material</uri>
          </script>
        </material>
      </visual>
      <gravity>1</gravity>
      <self_collide/>
    </link>
    <!--LINK: left_shoulder-->
    <link name="left_shoulder">
      <pose frame="">0.005000000 0.115000000 0.180000000 -1.570796327 0.000000000 1.570796327</pose>
      <inertial>
        <pose frame="">-0.003491000 -0.001684000 0.003753000 0.000000000 0.000000000 0.000000000</pose>
        <mass>0.06</mass>
        <inertia>
          <ixx>7.632e-06</ixx>
          <ixy>-2.4e-08</ixy>
          <ixz>4.2e-07</ixz>
          <iyy>5.82e-06</iyy>
          <iyz>7.2e-08</iyz>
          <izz>7.536e-06</izz>
        </inertia>
      </inertial>
      <collision name="left_shoulder_collision">
        <pose frame="">0.000000000 0.000000000 0.000000000 0.000000000 0.000000000 0.000000000</pose>
        <geometry>
          <mesh>
            <scale>1 1 1</scale>
            <uri>model://nubots_nugus_hull/mesh/left_shoulder.stl</uri>
          </mesh>
        </geometry>
        <surface>
          <contact>
            <ode/>
          </contact>
          <friction>
            <ode>
              <mu>0.98</mu>
              <mu2>0.98</mu2>
              <slip1>0.001</slip1>
              <slip2>0.001</slip2>
            </ode>
            <torsional>
              <coefficient>0.8</coefficient>
              <patch_radius>1.0</patch_radius>
            </torsional>
          </friction>
        </surface>
      </collision>
      <visual name="left_shoulder_visual">
        <pose frame="">0.000000000 0.000000000 0.000000000 0.000000000 0.000000000 0.000000000</pose>
        <geometry>
          <mesh>
            <scale>1 1 1</scale>
            <uri>model://nubots_nugus_hull/mesh/left_shoulder.stl</uri>
          </mesh>
        </geometry>
        <material>
          <script>
            <name>Gazebo/Grey</name>
            <uri>file://media/materials/scripts/gazebo.material</uri>
          </script>
        </material>
      </visual>
      <gravity>1</gravity>
      <self_collide/>
    </link>
    <!--LINK: right_upper_arm-->
    <link name="right_upper_arm">
      <pose frame="">0.000000000 -0.130000000 0.180000000 3.141590000 3.141590000 -1.570796327</pose>
      <inertial>
        <pose frame="">0.006723000 -0.090631000 0.000549000 0.000000000 0.000000000 0.000000000</pose>
        <mass>0.297</mass>
        <inertia>
          <ixx>8.835156e-05</ixx>
          <ixy>3.99762e-06</ixy>
          <ixz>-9.504e-08</ixz>
          <iyy>1.483812e-05</iyy>
          <iyz>2.08494e-06</iyz>
          <izz>9.10305e-05</izz>
        </inertia>
      </inertial>
      <collision name="right_upper_arm_collision">
        <pose frame="">0.000000000 0.000000000 0.000000000 0.000000000 0.000000000 0.000000000</pose>
        <geometry>
          <mesh>
            <scale>1 1 1</scale>
            <uri>model://nubots_nugus_hull/mesh/right_upper_arm.stl</uri>
          </mesh>
        </geometry>
        <surface>
          <contact>
            <ode/>
          </contact>
          <friction>
            <ode>
              <mu>0.98</mu>
              <mu2>0.98</mu2>
              <slip1>0.001</slip1>
              <slip2>0.001</slip2>
            </ode>
            <torsional>
              <coefficient>0.8</coefficient>
              <patch_radius>1.0</patch_radius>
            </torsional>
          </friction>
        </surface>
      </collision>
      <visual name="right_upper_arm_visual">
        <pose frame="">0.000000000 0.000000000 0.000000000 0.000000000 0.000000000 0.000000000</pose>
        <geometry>
          <mesh>
            <scale>1 1 1</scale>
            <uri>model://nubots_nugus_hull/mesh/right_upper_arm.stl</uri>
          </mesh>
        </geometry>
        <material>
          <script>
            <name>Gazebo/Grey</name>
            <uri>file://media/materials/scripts/gazebo.material</uri>
          </script>
        </material>
      </visual>
      <gravity>1</gravity>
      <self_collide/>
    </link>
    <!--LINK: left_upper_arm-->
    <link name="left_upper_arm">
      <pose frame="">0.000000000 0.130000000 0.180000000 3.141590000 3.141590000 -1.570796327</pose>
      <inertial>
        <pose frame="">-0.006723000 -0.090631000 0.000549000 0.000000000 0.000000000 0.000000000</pose>
        <mass>0.297</mass>
        <inertia>
          <ixx>8.835156e-05</ixx>
          <ixy>-3.99762e-06</ixy>
          <ixz>9.504e-08</ixz>
          <iyy>1.483812e-05</iyy>
          <iyz>2.08494e-06</iyz>
          <izz>9.10305e-05</izz>
        </inertia>
      </inertial>
      <collision name="left_upper_arm_collision">
        <pose frame="">0.000000000 0.000000000 0.000000000 0.000000000 0.000000000 0.000000000</pose>
        <geometry>
          <mesh>
            <scale>1 1 1</scale>
            <uri>model://nubots_nugus_hull/mesh/left_upper_arm.stl</uri>
          </mesh>
        </geometry>
        <surface>
          <contact>
            <ode/>
          </contact>
          <friction>
            <ode>
              <mu>0.98</mu>
              <mu2>0.98</mu2>
              <slip1>0.001</slip1>
              <slip2>0.001</slip2>
            </ode>
            <torsional>
              <coefficient>0.8</coefficient>
              <patch_radius>1.0</patch_radius>
            </torsional>
          </friction>
        </surface>
      </collision>
      <visual name="left_upper_arm_visual">
        <pose frame="">0.000000000 0.000000000 0.000000000 0.000000000 0.000000000 0.000000000</pose>
        <geometry>
          <mesh>
            <scale>1 1 1</scale>
            <uri>model://nubots_nugus_hull/mesh/left_upper_arm.stl</uri>
          </mesh>
        </geometry>
        <material>
          <script>
            <name>Gazebo/Grey</name>
            <uri>file://media/materials/scripts/gazebo.material</uri>
          </script>
        </material>
      </visual>
      <gravity>1</gravity>
      <self_collide/>
    </link>
    <!--LINK: right_lower_arm-->
    <link name="right_lower_arm">
      <pose frame="">0.190000000 -0.120000000 0.220000000 0.000000000 0.000000000 1.570796327</pose>
      <inertial>
        <pose frame="">0.004014000 -0.060888000 -0.000161000 0.000000000 0.000000000 0.000000000</pose>
        <mass>0.26</mass>
        <inertia>
          <ixx>0.0011613</ixx>
          <ixy>-5.8221e-07</ixy>
          <ixz>-7.4224e-05</ixz>
          <iyy>0.0011747</iyy>
          <iyz>2.0082e-05</iyz>
          <izz>0.00010273</izz>
        </inertia>
      </inertial>
      <collision name="right_lower_arm_collision">
        <pose frame="">0.000000000 0.000000000 0.000000000 0.000000000 0.000000000 0.000000000</pose>
        <geometry>
          <mesh>
            <scale>1 1 1</scale>
            <uri>model://nubots_nugus_hull/mesh/right_lower_arm.stl</uri>
          </mesh>
        </geometry>
        <surface>
          <contact>
            <ode/>
          </contact>
          <friction>
            <ode>
              <mu>0.98</mu>
              <mu2>0.98</mu2>
              <slip1>0.001</slip1>
              <slip2>0.001</slip2>
            </ode>
            <torsional>
              <coefficient>0.8</coefficient>
              <patch_radius>1.0</patch_radius>
            </torsional>
          </friction>
        </surface>
      </collision>
      <visual name="right_lower_arm_visual">
        <pose frame="">0.000000000 0.000000000 0.000000000 0.000000000 0.000000000 0.000000000</pose>
        <geometry>
          <mesh>
            <scale>1 1 1</scale>
            <uri>model://nubots_nugus_hull/mesh/right_lower_arm.stl</uri>
          </mesh>
        </geometry>
        <material>
          <script>
            <name>Gazebo/Grey</name>
            <uri>file://media/materials/scripts/gazebo.material</uri>
          </script>
        </material>
      </visual>
      <gravity>1</gravity>
      <self_collide/>
    </link>
    <!--LINK: left_lower_arm-->
    <link name="left_lower_arm">
      <pose frame="">0.190000000 0.120000000 0.220000000 0.000000000 0.000000000 1.570796327</pose>
      <inertial>
        <pose frame="">-0.004014000 -0.060888000 -0.000161000 0.000000000 0.000000000 0.000000000</pose>
        <mass>0.26</mass>
        <inertia>
          <ixx>0.00081539</ixx>
          <ixy>1.1134e-07</ixy>
          <ixz>-5.114e-05</ixz>
          <iyy>0.0007994</iyy>
          <iyz>-2.4756e-06</iyz>
          <izz>0.00012883</izz>
        </inertia>
      </inertial>
      <collision name="left_lower_arm_collision">
        <pose frame="">0.000000000 0.000000000 0.000000000 0.000000000 0.000000000 0.000000000</pose>
        <geometry>
          <mesh>
            <scale>1 1 1</scale>
            <uri>model://nubots_nugus_hull/mesh/left_lower_arm.stl</uri>
          </mesh>
        </geometry>
        <surface>
          <contact>
            <ode/>
          </contact>
          <friction>
            <ode>
              <mu>0.98</mu>
              <mu2>0.98</mu2>
              <slip1>0.001</slip1>
              <slip2>0.001</slip2>
            </ode>
            <torsional>
              <coefficient>0.8</coefficient>
              <patch_radius>1.0</patch_radius>
            </torsional>
          </friction>
        </surface>
      </collision>
      <visual name="left_lower_arm_visual">
        <pose frame="">0.000000000 0.000000000 0.000000000 0.000000000 0.000000000 0.000000000</pose>
        <geometry>
          <mesh>
            <scale>1 1 1</scale>
            <uri>model://nubots_nugus_hull/mesh/left_lower_arm.stl</uri>
          </mesh>
        </geometry>
        <material>
          <script>
            <name>Gazebo/Grey</name>
            <uri>file://media/materials/scripts/gazebo.material</uri>
          </script>
        </material>
      </visual>
      <gravity>1</gravity>
      <self_collide/>
    </link>
    <!--LINK: right_hip_yaw-->
    <link name="right_hip_yaw">
      <pose frame="">0.000000000 -0.055000000 0.000000000 0.000000000 0.000000000 1.570796327</pose>
      <inertial>
        <pose frame="">0.001672000 0.008885000 -0.026767000 0.000000000 0.000000000 0.000000000</pose>
        <mass>0.22</mass>
        <inertia>
          <ixx>2.6774e-05</ixx>
          <ixy>1.5536e-19</ixy>
          <ixz>-9.0622e-19</ixz>
          <iyy>0.00011478</iyy>
          <iyz>-2.2736e-19</iyz>
          <izz>0.00010743</izz>
        </inertia>
      </inertial>
      <collision name="right_hip_yaw_collision">
        <pose frame="">0.000000000 0.000000000 0.000000000 0.000000000 0.000000000 0.000000000</pose>
        <geometry>
          <mesh>
            <scale>1 1 1</scale>
            <uri>model://nubots_nugus_hull/mesh/right_hip_yaw.stl</uri>
          </mesh>
        </geometry>
        <surface>
          <contact>
            <ode/>
          </contact>
          <friction>
            <ode>
              <mu>0.98</mu>
              <mu2>0.98</mu2>
              <slip1>0.001</slip1>
              <slip2>0.001</slip2>
            </ode>
            <torsional>
              <coefficient>0.8</coefficient>
              <patch_radius>1.0</patch_radius>
            </torsional>
          </friction>
        </surface>
      </collision>
      <visual name="right_hip_yaw_visual">
        <pose frame="">0.000000000 0.000000000 0.000000000 0.000000000 0.000000000 0.000000000</pose>
        <geometry>
          <mesh>
            <scale>1 1 1</scale>
            <uri>model://nubots_nugus_hull/mesh/right_hip_yaw.stl</uri>
          </mesh>
        </geometry>
        <material>
          <script>
            <name>Gazebo/Grey</name>
            <uri>file://media/materials/scripts/gazebo.material</uri>
          </script>
        </material>
      </visual>
      <gravity>1</gravity>
      <self_collide/>
    </link>
    <!--LINK: left_hip_yaw-->
    <link name="left_hip_yaw">
      <pose frame="">0.000000000 0.055000000 0.000000000 0.000000000 0.000000000 1.570796327</pose>
      <inertial>
        <pose frame="">-0.001672000 0.008885000 -0.026767000 0.000000000 0.000000000 0.000000000</pose>
        <mass>0.22</mass>
        <inertia>
          <ixx>2.6774e-05</ixx>
          <ixy>1.9727e-19</ixy>
          <ixz>-8.7961e-19</ixz>
          <iyy>0.00011478</iyy>
          <iyz>-2.3128e-19</iyz>
          <izz>0.00010743</izz>
        </inertia>
      </inertial>
      <collision name="left_hip_yaw_collision">
        <pose frame="">0.000000000 0.000000000 0.000000000 0.000000000 0.000000000 0.000000000</pose>
        <geometry>
          <mesh>
            <scale>1 1 1</scale>
            <uri>model://nubots_nugus_hull/mesh/left_hip_yaw.stl</uri>
          </mesh>
        </geometry>
        <surface>
          <contact>
            <ode/>
          </contact>
          <friction>
            <ode>
              <mu>0.98</mu>
              <mu2>0.98</mu2>
              <slip1>0.001</slip1>
              <slip2>0.001</slip2>
            </ode>
            <torsional>
              <coefficient>0.8</coefficient>
              <patch_radius>1.0</patch_radius>
            </torsional>
          </friction>
        </surface>
      </collision>
      <visual name="left_hip_yaw_visual">
        <pose frame="">0.000000000 0.000000000 0.000000000 0.000000000 0.000000000 0.000000000</pose>
        <geometry>
          <mesh>
            <scale>1 1 1</scale>
            <uri>model://nubots_nugus_hull/mesh/left_hip_yaw.stl</uri>
          </mesh>
        </geometry>
        <material>
          <script>
            <name>Gazebo/Grey</name>
            <uri>file://media/materials/scripts/gazebo.material</uri>
          </script>
        </material>
      </visual>
      <gravity>1</gravity>
      <self_collide/>
    </link>
    <!--LINK: right_hip_roll-->
    <link name="right_hip_roll">
      <pose frame="">0.000000000 -0.055000000 -0.060000000 0.000000000 0.000000000 1.570796327</pose>
      <inertial>
        <pose frame="">-0.000017000 -0.000295000 -0.004740000 0.000000000 0.000000000 0.000000000</pose>
        <mass>0.306</mass>
        <inertia>
          <ixx>0.00015503</ixx>
          <ixy>1.738e-06</ixy>
          <ixz>8.5148e-06</ixz>
          <iyy>0.0003299</iyy>
          <iyz>2.4403e-07</iyz>
          <izz>0.0002782</izz>
        </inertia>
      </inertial>
      <collision name="right_hip_roll_collision">
        <pose frame="">0.000000000 0.000000000 0.000000000 0.000000000 0.000000000 0.000000000</pose>
        <geometry>
          <mesh>
            <scale>1 1 1</scale>
            <uri>model://nubots_nugus_hull/mesh/right_hip_roll.stl</uri>
          </mesh>
        </geometry>
        <surface>
          <contact>
            <ode/>
          </contact>
          <friction>
            <ode>
              <mu>0.98</mu>
              <mu2>0.98</mu2>
              <slip1>0.001</slip1>
              <slip2>0.001</slip2>
            </ode>
            <torsional>
              <coefficient>0.8</coefficient>
              <patch_radius>1.0</patch_radius>
            </torsional>
          </friction>
        </surface>
      </collision>
      <visual name="right_hip_roll_visual">
        <pose frame="">0.000000000 0.000000000 0.000000000 0.000000000 0.000000000 0.000000000</pose>
        <geometry>
          <mesh>
            <scale>1 1 1</scale>
            <uri>model://nubots_nugus_hull/mesh/right_hip_roll.stl</uri>
          </mesh>
        </geometry>
        <material>
          <script>
            <name>Gazebo/Grey</name>
            <uri>file://media/materials/scripts/gazebo.material</uri>
          </script>
        </material>
      </visual>
      <gravity>1</gravity>
      <self_collide/>
    </link>
    <!--LINK: left_hip_roll-->
    <link name="left_hip_roll">
      <pose frame="">0.000000000 0.055000000 -0.060000000 0.000000000 0.000000000 1.570796327</pose>
      <inertial>
        <pose frame="">0.000017000 -0.000295000 -0.004740000 0.000000000 0.000000000 0.000000000</pose>
        <mass>0.306</mass>
        <inertia>
          <ixx>0.00015501</ixx>
          <ixy>-1.7299e-06</ixy>
          <ixz>8.5156e-06</ixz>
          <iyy>0.00032958</iyy>
          <iyz>-2.4435e-07</iyz>
          <izz>0.00027786</izz>
        </inertia>
      </inertial>
      <collision name="left_hip_roll_collision">
        <pose frame="">0.000000000 0.000000000 0.000000000 0.000000000 0.000000000 0.000000000</pose>
        <geometry>
          <mesh>
            <scale>1 1 1</scale>
            <uri>model://nubots_nugus_hull/mesh/left_hip_roll.stl</uri>
          </mesh>
        </geometry>
        <surface>
          <contact>
            <ode/>
          </contact>
          <friction>
            <ode>
              <mu>0.98</mu>
              <mu2>0.98</mu2>
              <slip1>0.001</slip1>
              <slip2>0.001</slip2>
            </ode>
            <torsional>
              <coefficient>0.8</coefficient>
              <patch_radius>1.0</patch_radius>
            </torsional>
          </friction>
        </surface>
      </collision>
      <visual name="left_hip_roll_visual">
        <pose frame="">0.000000000 0.000000000 0.000000000 0.000000000 0.000000000 0.000000000</pose>
        <geometry>
          <mesh>
            <scale>1 1 1</scale>
            <uri>model://nubots_nugus_hull/mesh/left_hip_roll.stl</uri>
          </mesh>
        </geometry>
        <material>
          <script>
            <name>Gazebo/Grey</name>
            <uri>file://media/materials/scripts/gazebo.material</uri>
          </script>
        </material>
      </visual>
      <gravity>1</gravity>
      <self_collide/>
    </link>
    <!--LINK: right_upper_leg-->
    <link name="right_upper_leg">
      <pose frame="">0.010000000 -0.055000000 -0.050000000 -0.050000000 0.000000000 1.570796327</pose>
      <inertial>
        <pose frame="">0.000592000 -0.005444000 -0.102193000 0.000000000 0.000000000 0.000000000</pose>
        <mass>0.387</mass>
        <inertia>
          <ixx>0.0020951</ixx>
          <ixy>1.8755e-07</ixy>
          <ixz>-0.00017816</ixz>
          <iyy>0.0020043</iyy>
          <iyz>-5.4867e-06</iyz>
          <izz>0.00027919</izz>
        </inertia>
      </inertial>
      <collision name="right_upper_leg_collision">
        <pose frame="">0.000000000 0.000000000 0.000000000 0.000000000 0.000000000 0.000000000</pose>
        <geometry>
          <mesh>
            <scale>1 1 1</scale>
            <uri>model://nubots_nugus_hull/mesh/right_upper_leg.stl</uri>
          </mesh>
        </geometry>
        <surface>
          <contact>
            <ode/>
          </contact>
          <friction>
            <ode>
              <mu>0.98</mu>
              <mu2>0.98</mu2>
              <slip1>0.001</slip1>
              <slip2>0.001</slip2>
            </ode>
            <torsional>
              <coefficient>0.8</coefficient>
              <patch_radius>1.0</patch_radius>
            </torsional>
          </friction>
        </surface>
      </collision>
      <visual name="right_upper_leg_visual">
        <pose frame="">0.000000000 0.000000000 0.000000000 0.000000000 0.000000000 0.000000000</pose>
        <geometry>
          <mesh>
            <scale>1 1 1</scale>
            <uri>model://nubots_nugus_hull/mesh/right_upper_leg.stl</uri>
          </mesh>
        </geometry>
        <material>
          <script>
            <name>Gazebo/Grey</name>
            <uri>file://media/materials/scripts/gazebo.material</uri>
          </script>
        </material>
      </visual>
      <gravity>1</gravity>
      <self_collide/>
    </link>
    <!--LINK: left_upper_leg-->
    <link name="left_upper_leg">
      <pose frame="">0.010000000 0.055000000 -0.050000000 -0.050000000 0.000000000 1.570796327</pose>
      <inertial>
        <pose frame="">-0.000592000 -0.005444000 -0.102193000 0.000000000 0.000000000 0.000000000</pose>
        <mass>0.387</mass>
        <inertia>
          <ixx>0.0020952</ixx>
          <ixy>-1.9541e-07</ixy>
          <ixz>-0.00017822</ixz>
          <iyy>0.0020044</iyy>
          <iyz>5.4912e-06</iyz>
          <izz>0.00027919</izz>
        </inertia>
      </inertial>
      <collision name="left_upper_leg_collision">
        <pose frame="">0.000000000 0.000000000 0.000000000 0.000000000 0.000000000 0.000000000</pose>
        <geometry>
          <mesh>
            <scale>1 1 1</scale>
            <uri>model://nubots_nugus_hull/mesh/left_upper_leg.stl</uri>
          </mesh>
        </geometry>
        <surface>
          <contact>
            <ode/>
          </contact>
          <friction>
            <ode>
              <mu>0.98</mu>
              <mu2>0.98</mu2>
              <slip1>0.001</slip1>
              <slip2>0.001</slip2>
            </ode>
            <torsional>
              <coefficient>0.8</coefficient>
              <patch_radius>1.0</patch_radius>
            </torsional>
          </friction>
        </surface>
      </collision>
      <visual name="left_upper_leg_visual">
        <pose frame="">0.000000000 0.000000000 0.000000000 0.000000000 0.000000000 0.000000000</pose>
        <geometry>
          <mesh>
            <scale>1 1 1</scale>
            <uri>model://nubots_nugus_hull/mesh/left_upper_leg.stl</uri>
          </mesh>
        </geometry>
        <material>
          <script>
            <name>Gazebo/Grey</name>
            <uri>file://media/materials/scripts/gazebo.material</uri>
          </script>
        </material>
      </visual>
      <gravity>1</gravity>
      <self_collide/>
    </link>
    <!--LINK: right_lower_leg-->
    <link name="right_lower_leg">
      <pose frame="">0.010000000 -0.055000000 -0.250000000 0.000000000 0.000000000 1.570796327</pose>
      <inertial>
        <pose frame="">-0.002452000 0.006376000 -0.088280000 0.000000000 0.000000000 0.000000000</pose>
        <mass>0.177</mass>
        <inertia>
          <ixx>0.0011378</ixx>
          <ixy>-2.8771e-12</ixy>
          <ixz>9.7123e-05</ixz>
          <iyy>0.0010393</iyy>
          <iyz>-1.4479e-11</iyz>
          <izz>0.00019656</izz>
        </inertia>
      </inertial>
      <collision name="right_lower_leg_collision">
        <pose frame="">0.000000000 0.000000000 0.000000000 0.000000000 0.000000000 0.000000000</pose>
        <geometry>
          <mesh>
            <scale>1 1 1</scale>
            <uri>model://nubots_nugus_hull/mesh/right_lower_leg.stl</uri>
          </mesh>
        </geometry>
        <surface>
          <contact>
            <ode/>
          </contact>
          <friction>
            <ode>
              <mu>0.98</mu>
              <mu2>0.98</mu2>
              <slip1>0.001</slip1>
              <slip2>0.001</slip2>
            </ode>
            <torsional>
              <coefficient>0.8</coefficient>
              <patch_radius>1.0</patch_radius>
            </torsional>
          </friction>
        </surface>
      </collision>
      <visual name="right_lower_leg_visual">
        <pose frame="">0.000000000 0.000000000 0.000000000 0.000000000 0.000000000 0.000000000</pose>
        <geometry>
          <mesh>
            <scale>1 1 1</scale>
            <uri>model://nubots_nugus_hull/mesh/right_lower_leg.stl</uri>
          </mesh>
        </geometry>
        <material>
          <script>
            <name>Gazebo/Grey</name>
            <uri>file://media/materials/scripts/gazebo.material</uri>
          </script>
        </material>
      </visual>
      <gravity>1</gravity>
      <self_collide/>
    </link>
    <!--LINK: left_lower_leg-->
    <link name="left_lower_leg">
      <pose frame="">0.010000000 0.055000000 -0.250000000 0.000000000 0.000000000 1.570796327</pose>
      <inertial>
        <pose frame="">0.002452000 0.006376000 -0.088280000 0.000000000 0.000000000 0.000000000</pose>
        <mass>0.177</mass>
        <inertia>
          <ixx>0.0011378</ixx>
          <ixy>-2.8771e-12</ixy>
          <ixz>9.7123e-05</ixz>
          <iyy>0.0010393</iyy>
          <iyz>-1.4479e-11</iyz>
          <izz>0.00019656</izz>
        </inertia>
      </inertial>
      <collision name="left_lower_leg_collision">
        <pose frame="">0.000000000 0.000000000 0.000000000 0.000000000 0.000000000 0.000000000</pose>
        <geometry>
          <mesh>
            <scale>1 1 1</scale>
            <uri>model://nubots_nugus_hull/mesh/left_lower_leg.stl</uri>
          </mesh>
        </geometry>
        <surface>
          <contact>
            <ode/>
          </contact>
          <friction>
            <ode>
              <mu>0.98</mu>
              <mu2>0.98</mu2>
              <slip1>0.001</slip1>
              <slip2>0.001</slip2>
            </ode>
            <torsional>
              <coefficient>0.8</coefficient>
              <patch_radius>1.0</patch_radius>
            </torsional>
          </friction>
        </surface>
      </collision>
      <visual name="left_lower_leg_visual">
        <pose frame="">0.000000000 0.000000000 0.000000000 0.000000000 0.000000000 0.000000000</pose>
        <geometry>
          <mesh>
            <scale>1 1 1</scale>
            <uri>model://nubots_nugus_hull/mesh/left_lower_leg.stl</uri>
          </mesh>
        </geometry>
        <material>
          <script>
            <name>Gazebo/Grey</name>
            <uri>file://media/materials/scripts/gazebo.material</uri>
          </script>
        </material>
      </visual>
      <gravity>1</gravity>
      <self_collide/>
    </link>
    <!--LINK: right_ankle-->
    <link name="right_ankle">
      <pose frame="">0.000000000 -0.055000000 -0.450000000 0.000000000 3.141590000 1.570796327</pose>
      <inertial>
        <pose frame="">0.000043000 0.021903000 -0.010508000 0.000000000 0.000000000 0.000000000</pose>
        <mass>0.306</mass>
        <inertia>
          <ixx>0.00015501</ixx>
          <ixy>1.7299e-06</ixy>
          <ixz>-8.5156e-06</ixz>
          <iyy>0.00032958</iyy>
          <iyz>-2.4435e-07</iyz>
          <izz>0.00027786</izz>
        </inertia>
      </inertial>
      <collision name="right_ankle_collision">
        <pose frame="">0.000000000 0.000000000 0.000000000 0.000000000 0.000000000 0.000000000</pose>
        <geometry>
          <mesh>
            <scale>1 1 1</scale>
            <uri>model://nubots_nugus_hull/mesh/right_ankle.stl</uri>
          </mesh>
        </geometry>
        <surface>
          <contact>
            <ode/>
          </contact>
          <friction>
            <ode>
              <mu>0.98</mu>
              <mu2>0.98</mu2>
              <slip1>0.001</slip1>
              <slip2>0.001</slip2>
            </ode>
            <torsional>
              <coefficient>0.8</coefficient>
              <patch_radius>1.0</patch_radius>
            </torsional>
          </friction>
        </surface>
      </collision>
      <visual name="right_ankle_visual">
        <pose frame="">0.000000000 0.000000000 0.000000000 0.000000000 0.000000000 0.000000000</pose>
        <geometry>
          <mesh>
            <scale>1 1 1</scale>
            <uri>model://nubots_nugus_hull/mesh/right_ankle.stl</uri>
          </mesh>
        </geometry>
        <material>
          <script>
            <name>Gazebo/Grey</name>
            <uri>file://media/materials/scripts/gazebo.material</uri>
          </script>
        </material>
      </visual>
      <gravity>1</gravity>
      <self_collide/>
    </link>
    <!--LINK: left_ankle-->
    <link name="left_ankle">
      <pose frame="">0.000000000 0.055000000 -0.450000000 0.000000000 3.141590000 1.570796327</pose>
      <inertial>
        <pose frame="">-0.000043000 0.021903000 -0.010508000 0.000000000 0.000000000 0.000000000</pose>
        <mass>0.306</mass>
        <inertia>
          <ixx>0.00015503</ixx>
          <ixy>-1.738e-06</ixy>
          <ixz>-8.5148e-06</ixz>
          <iyy>0.0003299</iyy>
          <iyz>2.4403e-07</iyz>
          <izz>0.0002782</izz>
        </inertia>
      </inertial>
      <collision name="left_ankle_collision">
        <pose frame="">0.000000000 0.000000000 0.000000000 0.000000000 0.000000000 0.000000000</pose>
        <geometry>
          <mesh>
            <scale>1 1 1</scale>
            <uri>model://nubots_nugus_hull/mesh/left_ankle.stl</uri>
          </mesh>
        </geometry>
        <surface>
          <contact>
            <ode/>
          </contact>
          <friction>
            <ode>
              <mu>0.98</mu>
              <mu2>0.98</mu2>
              <slip1>0.001</slip1>
              <slip2>0.001</slip2>
            </ode>
            <torsional>
              <coefficient>0.8</coefficient>
              <patch_radius>1.0</patch_radius>
            </torsional>
          </friction>
        </surface>
      </collision>
      <visual name="left_ankle_visual">
        <pose frame="">0.000000000 0.000000000 0.000000000 0.000000000 0.000000000 0.000000000</pose>
        <geometry>
          <mesh>
            <scale>1 1 1</scale>
            <uri>model://nubots_nugus_hull/mesh/left_ankle.stl</uri>
          </mesh>
        </geometry>
        <material>
          <script>
            <name>Gazebo/Grey</name>
            <uri>file://media/materials/scripts/gazebo.material</uri>
          </script>
        </material>
      </visual>
      <gravity>1</gravity>
      <self_collide/>
    </link>
    <!--LINK: right_foot-->
    <link name="right_foot">
      <pose frame="">-0.040000000 -0.055000000 -0.450000000 0.000000000 0.000000000 1.570796327</pose>
      <inertial>
        <pose frame="">-0.007551000 -0.077046000 -0.031619000 0.000000000 0.000000000 0.000000000</pose>
        <mass>0.205</mass>
        <inertia>
          <ixx>0.00018527</ixx>
          <ixy>-1.1504e-05</ixy>
          <ixz>-7.2667e-06</ixz>
          <iyy>0.00060485</iyy>
          <iyz>5.8883e-06</iyz>
          <izz>0.00075217</izz>
        </inertia>
      </inertial>
      <collision name="right_foot_collision">
        <pose frame="">0.000000000 0.000000000 0.000000000 0.000000000 0.000000000 0.000000000</pose>
        <geometry>
          <mesh>
            <scale>1 1 1</scale>
            <uri>model://nubots_nugus_hull/mesh/right_foot.stl</uri>
          </mesh>
        </geometry>
        <surface>
          <contact>
            <ode/>
          </contact>
          <friction>
            <ode>
              <mu>0.98</mu>
              <mu2>0.98</mu2>
              <slip1>0.001</slip1>
              <slip2>0.001</slip2>
            </ode>
            <torsional>
              <coefficient>0.8</coefficient>
              <patch_radius>1.0</patch_radius>
            </torsional>
          </friction>
        </surface>
      </collision>
      <visual name="right_foot_visual">
        <pose frame="">0.000000000 0.000000000 0.000000000 0.000000000 0.000000000 0.000000000</pose>
        <geometry>
          <mesh>
            <scale>1 1 1</scale>
            <uri>model://nubots_nugus_hull/mesh/right_foot.stl</uri>
          </mesh>
        </geometry>
        <material>
          <script>
            <name>Gazebo/Grey</name>
            <uri>file://media/materials/scripts/gazebo.material</uri>
          </script>
        </material>
      </visual>
      <gravity>1</gravity>
      <self_collide/>
    </link>
    <!--LINK: left_foot-->
    <link name="left_foot">
      <pose frame="">-0.040000000 0.055000000 -0.450000000 0.000000000 0.000000000 1.570796327</pose>
      <inertial>
        <pose frame="">0.007551000 -0.077046000 -0.031619000 0.000000000 0.000000000 0.000000000</pose>
        <mass>0.205</mass>
        <inertia>
          <ixx>0.0001853</ixx>
          <ixy>1.1466e-05</ixy>
          <ixz>-8.3793e-06</ixz>
          <iyy>0.00060485</iyy>
          <iyz>-5.9046e-06</iyz>
          <izz>0.00075213</izz>
        </inertia>
      </inertial>
      <collision name="left_foot_collision">
        <pose frame="">0.000000000 0.000000000 0.000000000 0.000000000 0.000000000 0.000000000</pose>
        <geometry>
          <mesh>
            <scale>1 1 1</scale>
            <uri>model://nubots_nugus_hull/mesh/left_foot.stl</uri>
          </mesh>
        </geometry>
        <surface>
          <contact>
            <ode/>
          </contact>
          <friction>
            <ode>
              <mu>0.98</mu>
              <mu2>0.98</mu2>
              <slip1>0.001</slip1>
              <slip2>0.001</slip2>
            </ode>
            <torsional>
              <coefficient>0.8</coefficient>
              <patch_radius>1.0</patch_radius>
            </torsional>
          </friction>
        </surface>
      </collision>
      <visual name="left_foot_visual">
        <pose frame="">0.000000000 0.000000000 0.000000000 0.000000000 0.000000000 0.000000000</pose>
        <geometry>
          <mesh>
            <scale>1 1 1</scale>
            <uri>model://nubots_nugus_hull/mesh/left_foot.stl</uri>
          </mesh>
        </geometry>
        <material>
          <script>
            <name>Gazebo/Grey</name>
            <uri>file://media/materials/scripts/gazebo.material</uri>
          </script>
        </material>
      </visual>
      <gravity>1</gravity>
      <self_collide/>
    </link>
    <!--LINK: neck-->
    <link name="neck">
      <pose frame="">0.000000000 0.000000000 0.260000000 0.000000000 0.000000000 1.570796327</pose>
      <inertial>
        <pose frame="">-0.000608000 -0.000007000 -0.015358000 0.000000000 0.000000000 0.000000000</pose>
        <mass>0.153</mass>
        <inertia>
          <ixx>4.2534e-06</ixx>
          <ixy>0.0</ixy>
          <ixz>1.224e-07</ixz>
          <iyy>4.437e-06</iyy>
          <iyz>0.0</iyz>
          <izz>2.907e-06</izz>
        </inertia>
      </inertial>
      <collision name="neck_collision">
        <pose frame="">0.000000000 0.000000000 0.000000000 0.000000000 0.000000000 0.000000000</pose>
        <geometry>
          <mesh>
            <scale>1 1 1</scale>
            <uri>model://nubots_nugus_hull/mesh/neck.stl</uri>
          </mesh>
        </geometry>
        <surface>
          <contact>
            <ode/>
          </contact>
          <friction>
            <ode>
              <mu>0.98</mu>
              <mu2>0.98</mu2>
              <slip1>0.001</slip1>
              <slip2>0.001</slip2>
            </ode>
            <torsional>
              <coefficient>0.8</coefficient>
              <patch_radius>1.0</patch_radius>
            </torsional>
          </friction>
        </surface>
      </collision>
      <visual name="neck_visual">
        <pose frame="">0.000000000 0.000000000 0.000000000 0.000000000 0.000000000 0.000000000</pose>
        <geometry>
          <mesh>
            <scale>1 1 1</scale>
            <uri>model://nubots_nugus_hull/mesh/neck.stl</uri>
          </mesh>
        </geometry>
        <material>
          <script>
            <name>Gazebo/Grey</name>
            <uri>file://media/materials/scripts/gazebo.material</uri>
          </script>
        </material>
      </visual>
      <gravity>1</gravity>
      <self_collide/>
    </link>
    <!--LINK: head-->
    <link name="head">
      <pose frame="">0.000000000 0.000000000 0.260000000 0.000000000 0.000000000 1.570796327</pose>
      <inertial>
        <pose frame="">-0.002841000 -0.003496000 0.064412000 0.000000000 0.000000000 0.000000000</pose>
        <mass>0.419</mass>
        <inertia>
          <ixx>0.0012</ixx>
          <ixy>0.0</ixy>
          <ixz>0.0</ixz>
          <iyy>0.0013</iyy>
          <iyz>0.0</iyz>
          <izz>0.0012</izz>
        </inertia>
      </inertial>
      <collision name="head_collision">
        <pose frame="">0.000000000 0.000000000 0.000000000 0.000000000 0.000000000 0.000000000</pose>
        <geometry>
          <mesh>
            <scale>1 1 1</scale>
            <uri>model://nubots_nugus_hull/mesh/head.stl</uri>
          </mesh>
        </geometry>
        <surface>
          <contact>
            <ode/>
          </contact>
          <friction>
            <ode>
              <mu>0.98</mu>
              <mu2>0.98</mu2>
              <slip1>0.001</slip1>
              <slip2>0.001</slip2>
            </ode>
            <torsional>
              <coefficient>0.8</coefficient>
              <patch_radius>1.0</patch_radius>
            </torsional>
          </friction>
        </surface>
      </collision>
      <visual name="head_visual">
        <pose frame="">0.000000000 0.000000000 0.000000000 0.000000000 0.000000000 0.000000000</pose>
        <geometry>
          <mesh>
            <scale>1 1 1</scale>
            <uri>model://nubots_nugus_hull/mesh/head.stl</uri>
          </mesh>
        </geometry>
        <material>
          <script>
            <name>Gazebo/Grey</name>
            <uri>file://media/materials/scripts/gazebo.material</uri>
          </script>
        </material>
      </visual>
      <gravity>1</gravity>
      <self_collide/>
    </link>
    <!--JOINT: right_shoulder_pitch-->
    <joint name="right_shoulder_pitch" type="revolute">
      <child>right_shoulder</child>
      <parent>torso</parent>
      <axis>
        <xyz>0 1 0</xyz>
        <limit>
          <lower>-3.14159265359</lower>
          <upper>3.14159265359</upper>
          <velocity>8.16814</velocity>
          <effort>7.3</effort>
        </limit>
        <dynamics>
          <friction>0.5</friction>
          <damping>0.6</damping>
          <spring_reference>0</spring_reference>
          <spring_stiffness>3.25</spring_stiffness>
        </dynamics>
        <use_parent_model_frame>1</use_parent_model_frame>
      </axis>
    </joint>
    <!--JOINT: left_shoulder_pitch-->
    <joint name="left_shoulder_pitch" type="revolute">
      <child>left_shoulder</child>
      <parent>torso</parent>
      <axis>
        <xyz>0 1 0</xyz>
        <limit>
          <lower>-3.14159265359</lower>
          <upper>3.14159265359</upper>
          <velocity>8.16814</velocity>
          <effort>7.3</effort>
        </limit>
        <dynamics>
          <friction>0.5</friction>
          <damping>0.6</damping>
          <spring_reference>0</spring_reference>
          <spring_stiffness>3.25</spring_stiffness>
        </dynamics>
        <use_parent_model_frame>1</use_parent_model_frame>
      </axis>
    </joint>
    <!--JOINT: right_shoulder_roll-->
    <joint name="right_shoulder_roll" type="revolute">
      <child>right_upper_arm</child>
      <parent>right_shoulder</parent>
      <axis>
        <xyz>0 0 1</xyz>
        <limit>
          <lower>-3.14159265359</lower>
          <upper>3.14159265359</upper>
          <velocity>8.16814</velocity>
          <effort>7.3</effort>
        </limit>
        <dynamics>
          <friction>0.5</friction>
          <damping>0.6</damping>
          <spring_reference>0</spring_reference>
          <spring_stiffness>3.25</spring_stiffness>
        </dynamics>
        <use_parent_model_frame>1</use_parent_model_frame>
      </axis>
    </joint>
    <!--JOINT: left_shoulder_roll-->
    <joint name="left_shoulder_roll" type="revolute">
      <child>left_upper_arm</child>
      <parent>left_shoulder</parent>
      <axis>
        <xyz>0 0 1</xyz>
        <limit>
          <lower>-3.14159265359</lower>
          <upper>3.14159265359</upper>
          <velocity>8.16814</velocity>
          <effort>7.3</effort>
        </limit>
        <dynamics>
          <friction>0.5</friction>
          <damping>0.6</damping>
          <spring_reference>0</spring_reference>
          <spring_stiffness>3.25</spring_stiffness>
        </dynamics>
        <use_parent_model_frame>1</use_parent_model_frame>
      </axis>
    </joint>
    <!--JOINT: right_elbow_pitch-->
    <joint name="right_elbow_pitch" type="revolute">
      <child>right_lower_arm</child>
      <parent>right_upper_arm</parent>
      <axis>
        <xyz>0 1 0</xyz>
        <limit>
          <lower>-3.14159265359</lower>
          <upper>3.14159265359</upper>
          <velocity>8.16814</velocity>
          <effort>7.3</effort>
        </limit>
        <dynamics>
          <friction>0.5</friction>
          <damping>0.6</damping>
          <spring_reference>0</spring_reference>
          <spring_stiffness>3.25</spring_stiffness>
        </dynamics>
        <use_parent_model_frame>1</use_parent_model_frame>
      </axis>
    </joint>
    <!--JOINT: left_elbow_pitch-->
    <joint name="left_elbow_pitch" type="revolute">
      <child>left_lower_arm</child>
      <parent>left_upper_arm</parent>
      <axis>
        <xyz>0 1 0</xyz>
        <limit>
          <lower>-3.14159265359</lower>
          <upper>3.14159265359</upper>
          <velocity>8.16814</velocity>
          <effort>7.3</effort>
        </limit>
        <dynamics>
          <friction>0.5</friction>
          <damping>0.6</damping>
          <spring_reference>0</spring_reference>
          <spring_stiffness>3.25</spring_stiffness>
        </dynamics>
        <use_parent_model_frame>1</use_parent_model_frame>
      </axis>
    </joint>
    <!--JOINT: right_hip_yaw-->
    <joint name="right_hip_yaw" type="revolute">
      <child>right_hip_yaw</child>
      <parent>torso</parent>
      <axis>
        <xyz>0 0 1</xyz>
        <limit>
          <lower>-3.14159265359</lower>
          <upper>3.14159265359</upper>
          <velocity>5.75959</velocity>
          <effort>10.0</effort>
        </limit>
        <dynamics>
          <friction>0.5</friction>
          <damping>0.6</damping>
          <spring_reference>0</spring_reference>
          <spring_stiffness>3.25</spring_stiffness>
        </dynamics>
        <use_parent_model_frame>1</use_parent_model_frame>
      </axis>
    </joint>
    <!--JOINT: left_hip_yaw-->
    <joint name="left_hip_yaw" type="revolute">
      <child>left_hip_yaw</child>
      <parent>torso</parent>
      <axis>
        <xyz>0 0 1</xyz>
        <limit>
          <lower>-3.14159265359</lower>
          <upper>3.14159265359</upper>
          <velocity>5.75959</velocity>
          <effort>10.0</effort>
        </limit>
        <dynamics>
          <friction>0.5</friction>
          <damping>0.6</damping>
          <spring_reference>0</spring_reference>
          <spring_stiffness>3.25</spring_stiffness>
        </dynamics>
        <use_parent_model_frame>1</use_parent_model_frame>
      </axis>
    </joint>
    <!--JOINT: right_hip_roll-->
    <joint name="right_hip_roll" type="revolute">
      <child>right_hip_roll</child>
      <parent>right_hip_yaw</parent>
      <axis>
        <xyz>1 0 0</xyz>
        <limit>
          <lower>-3.14159265359</lower>
          <upper>3.14159265359</upper>
          <velocity>5.75959</velocity>
          <effort>10.0</effort>
        </limit>
        <dynamics>
          <friction>0.5</friction>
          <damping>0.6</damping>
          <spring_reference>0</spring_reference>
          <spring_stiffness>3.25</spring_stiffness>
        </dynamics>
        <use_parent_model_frame>1</use_parent_model_frame>
      </axis>
    </joint>
    <!--JOINT: left_hip_roll-->
    <joint name="left_hip_roll" type="revolute">
      <child>left_hip_roll</child>
      <parent>left_hip_yaw</parent>
      <axis>
        <xyz>1 0 0</xyz>
        <limit>
          <lower>-3.14159265359</lower>
          <upper>3.14159265359</upper>
          <velocity>5.75959</velocity>
          <effort>10.0</effort>
        </limit>
        <dynamics>
          <friction>0.5</friction>
          <damping>0.6</damping>
          <spring_reference>0</spring_reference>
          <spring_stiffness>3.25</spring_stiffness>
        </dynamics>
        <use_parent_model_frame>1</use_parent_model_frame>
      </axis>
    </joint>
    <!--JOINT: right_hip_pitch-->
    <joint name="right_hip_pitch" type="revolute">
      <child>right_upper_leg</child>
      <parent>right_hip_roll</parent>
      <axis>
        <xyz>0 1 0</xyz>
        <limit>
          <lower>-3.14159265359</lower>
          <upper>3.14159265359</upper>
          <velocity>5.75959</velocity>
          <effort>10.0</effort>
        </limit>
        <dynamics>
          <friction>0.5</friction>
          <damping>0.6</damping>
          <spring_reference>0</spring_reference>
          <spring_stiffness>3.25</spring_stiffness>
        </dynamics>
        <use_parent_model_frame>1</use_parent_model_frame>
      </axis>
    </joint>
    <!--JOINT: left_hip_pitch-->
    <joint name="left_hip_pitch" type="revolute">
      <child>left_upper_leg</child>
      <parent>left_hip_roll</parent>
      <axis>
        <xyz>0 1 0</xyz>
        <limit>
          <lower>-3.14159265359</lower>
          <upper>3.14159265359</upper>
          <velocity>5.75959</velocity>
          <effort>10.0</effort>
        </limit>
        <dynamics>
          <friction>0.5</friction>
          <damping>0.6</damping>
          <spring_reference>0</spring_reference>
          <spring_stiffness>3.25</spring_stiffness>
        </dynamics>
        <use_parent_model_frame>1</use_parent_model_frame>
      </axis>
    </joint>
    <!--JOINT: right_knee_pitch-->
    <joint name="right_knee_pitch" type="revolute">
      <child>right_lower_leg</child>
      <parent>right_upper_leg</parent>
      <axis>
        <xyz>0 1 0</xyz>
        <limit>
          <lower>-3.14159265359</lower>
          <upper>3.14159265359</upper>
          <velocity>5.75959</velocity>
          <effort>10.0</effort>
        </limit>
        <dynamics>
          <friction>0.5</friction>
          <damping>0.6</damping>
          <spring_reference>0</spring_reference>
          <spring_stiffness>3.25</spring_stiffness>
        </dynamics>
        <use_parent_model_frame>1</use_parent_model_frame>
      </axis>
    </joint>
    <!--JOINT: left_knee_pitch-->
    <joint name="left_knee_pitch" type="revolute">
      <child>left_lower_leg</child>
      <parent>left_upper_leg</parent>
      <axis>
        <xyz>0 1 0</xyz>
        <limit>
          <lower>-3.14159265359</lower>
          <upper>3.14159265359</upper>
          <velocity>5.75959</velocity>
          <effort>10.0</effort>
        </limit>
        <dynamics>
          <friction>0.5</friction>
          <damping>0.6</damping>
          <spring_reference>0</spring_reference>
          <spring_stiffness>3.25</spring_stiffness>
        </dynamics>
        <use_parent_model_frame>1</use_parent_model_frame>
      </axis>
    </joint>
    <!--JOINT: right_ankle_pitch-->
    <joint name="right_ankle_pitch" type="revolute">
      <child>right_ankle</child>
      <parent>right_lower_leg</parent>
      <axis>
        <xyz>0 1 0</xyz>
        <limit>
          <lower>-3.14159265359</lower>
          <upper>3.14159265359</upper>
          <velocity>5.75959</velocity>
          <effort>10.0</effort>
        </limit>
        <dynamics>
          <friction>0.5</friction>
          <damping>0.6</damping>
          <spring_reference>0</spring_reference>
          <spring_stiffness>3.25</spring_stiffness>
        </dynamics>
        <use_parent_model_frame>1</use_parent_model_frame>
      </axis>
    </joint>
    <!--JOINT: left_ankle_pitch-->
    <joint name="left_ankle_pitch" type="revolute">
      <child>left_ankle</child>
      <parent>left_lower_leg</parent>
      <axis>
        <xyz>0 1 0</xyz>
        <limit>
          <lower>-3.14159265359</lower>
          <upper>3.14159265359</upper>
          <velocity>5.75959</velocity>
          <effort>10.0</effort>
        </limit>
        <dynamics>
          <friction>0.5</friction>
          <damping>0.6</damping>
          <spring_reference>0</spring_reference>
          <spring_stiffness>3.25</spring_stiffness>
        </dynamics>
        <use_parent_model_frame>1</use_parent_model_frame>
      </axis>
    </joint>
    <!--JOINT: right_ankle_roll-->
    <joint name="right_ankle_roll" type="revolute">
      <child>right_foot</child>
      <parent>right_ankle</parent>
      <axis>
        <xyz>1 0 0</xyz>
        <limit>
          <lower>-3.14159265359</lower>
          <upper>3.14159265359</upper>
          <velocity>5.75959</velocity>
          <effort>10.0</effort>
        </limit>
        <dynamics>
          <friction>0.5</friction>
          <damping>0.6</damping>
          <spring_reference>0</spring_reference>
          <spring_stiffness>3.25</spring_stiffness>
        </dynamics>
        <use_parent_model_frame>1</use_parent_model_frame>
      </axis>
    </joint>
    <!--JOINT: left_ankle_roll-->
    <joint name="left_ankle_roll" type="revolute">
      <child>left_foot</child>
      <parent>left_ankle</parent>
      <axis>
        <xyz>1 0 0</xyz>
        <limit>
          <lower>-3.14159265359</lower>
          <upper>3.14159265359</upper>
          <velocity>5.75959</velocity>
          <effort>10.0</effort>
        </limit>
        <dynamics>
          <friction>0.5</friction>
          <damping>0.6</damping>
          <spring_reference>0</spring_reference>
          <spring_stiffness>3.25</spring_stiffness>
        </dynamics>
        <use_parent_model_frame>1</use_parent_model_frame>
      </axis>
    </joint>
    <!--JOINT: neck_yaw-->
    <joint name="neck_yaw" type="revolute">
      <child>neck</child>
      <parent>torso</parent>
      <axis>
        <xyz>0 0 1</xyz>
        <limit>
          <lower>-3.14159265359</lower>
          <upper>3.14159265359</upper>
          <velocity>8.16814</velocity>
          <effort>7.3</effort>
        </limit>
        <dynamics>
          <friction>0.5</friction>
          <damping>0.6</damping>
          <spring_reference>0</spring_reference>
          <spring_stiffness>3.25</spring_stiffness>
        </dynamics>
        <use_parent_model_frame>1</use_parent_model_frame>
      </axis>
    </joint>
    <!--JOINT: head_pitch-->
    <joint name="head_pitch" type="revolute">
      <child>head</child>
      <parent>neck</parent>
      <axis>
        <xyz>0 1 0</xyz>
        <limit>
          <lower>-3.14159265359</lower>
          <upper>3.14159265359</upper>
          <velocity>8.16814</velocity>
          <effort>7.3</effort>
        </limit>
        <dynamics>
          <friction>0.5</friction>
          <damping>0.6</damping>
          <spring_reference>0</spring_reference>
          <spring_stiffness>3.25</spring_stiffness>
        </dynamics>
        <use_parent_model_frame>1</use_parent_model_frame>
      </axis>
    </joint>
  </model>
</sdf>
