<?xml version="1.0" ?>
<robot name="nubots_nugus_hull">
  <!--NUgus URDF Model-->
  <!--Last updated: 19 Aug 2019 23:10:13-->
  <!--LINK: torso-->
  <link name="torso">
    <inertial>
      <origin rpy="0.0 0.0 0.0" xyz="0.0050079703254699804 0.008880921777563762 0.1021503146237477"/>
      <mass value="2.5390000000000006"/>
      <inertia ixx="0.01665728720713129" ixy="0.0015451858906936002" ixz="0.004938657742879685" iyy="0.004225235417508923" iyz="0.0012027533896274989" izz="0.05550778391062456"/>
    </inertial>
    <visual name="torso_visual">
      <origin rpy="0.0 0.0 1.570796327" xyz="0.0 0.0 0.0"/>
      <geometry>
        <mesh filename="mesh/torso.stl" scale="1 1 1"/>
      </geometry>
    </visual>
  </link>
  <!--LINK: right_shoulder-->
  <link name="right_shoulder">
    <inertial>
      <origin rpy="0 0 0" xyz="0.003491 -0.001684 0.003753"/>
      <mass value="0.025434"/>
      <inertia ixx="0.000636" ixy="2e-06" ixz="-3.5e-05" iyy="0.000485" iyz="6e-06" izz="0.000628"/>
    </inertial>
    <visual name="right_shoulder_visual">
      <origin rpy="-1.570796327 0 1.570796327" xyz="0.005 -0.115 0.18"/>
      <geometry>
        <mesh filename="mesh/right_shoulder.stl" scale="1 1 1"/>
      </geometry>
    </visual>
  </link>
  <!--LINK: left_shoulder-->
  <link name="left_shoulder">
    <inertial>
      <origin rpy="0 0 0" xyz="0.003491 -0.001684 0.003753"/>
      <mass value="0.025434"/>
      <inertia ixx="0.000636" ixy="-2e-06" ixz="-3.5e-05" iyy="0.000485" iyz="-6e-06" izz="0.000628"/>
    </inertial>
    <visual name="left_shoulder_visual">
      <origin rpy="-1.570796327 0 1.570796327" xyz="0.005 0.115 0.18"/>
      <geometry>
        <mesh filename="mesh/left_shoulder.stl" scale="1 1 1"/>
      </geometry>
    </visual>
  </link>
  <!--LINK: right_upper_arm-->
  <link name="right_upper_arm">
    <inertial>
      <origin rpy="0 0 0" xyz="-0.0004754647829298364 -0.0004830631532648927 -0.047851449636613815"/>
      <mass value="0.29700000000000004"/>
      <inertia ixx="0.002440902596230906" ixy="-3.6713691248137597e-06" ixz="-0.00013891452285131982" iyy="0.002283834053695376" iyz="-1.9795333785260962e-05" izz="0.0005366937214088004"/>
    </inertial>
    <visual name="right_upper_arm_visual">
      <origin rpy="3.14159 3.14159 -1.570796327" xyz="0 -0.13 0.18"/>
      <geometry>
        <mesh filename="mesh/right_upper_arm.stl" scale="1 1 1"/>
      </geometry>
    </visual>
  </link>
  <!--LINK: left_upper_arm-->
  <link name="left_upper_arm">
    <inertial>
      <origin rpy="0 0 0" xyz="-0.0004754647829298364 0.0004830631532648927 -0.047851449636613815"/>
      <mass value="0.29700000000000004"/>
      <inertia ixx="0.002440902596230906" ixy="-3.6713691248137597e-06" ixz="-0.00013891452285131982" iyy="0.002283834053695376" iyz="-1.9795333785260962e-05" izz="0.0005366937214088004"/>
    </inertial>
    <visual name="left_upper_arm_visual">
      <origin rpy="3.14159 3.14159 -1.570796327" xyz="0 0.13 0.18"/>
      <geometry>
        <mesh filename="mesh/left_upper_arm.stl" scale="1 1 1"/>
      </geometry>
    </visual>
  </link>
  <!--LINK: right_lower_arm-->
  <link name="right_lower_arm">
    <inertial>
      <origin rpy="0 0 0" xyz="0.05336545685394963 -0.0008156196838209869 0.0006063260979097202"/>
      <mass value="0.26"/>
      <inertia ixx="0.0003407158555996035" ixy="0.00011823673412134757" ixz="-2.8830788618180246e-05" iyy="0.0017692134503461817" iyz="4.6856873014962955e-06" izz="0.0016180592541080458"/>
    </inertial>
    <visual name="right_lower_arm_visual">
      <origin rpy="0 0 1.570796327" xyz="0.19 -0.12 0.22"/>
      <geometry>
        <mesh filename="mesh/right_lower_arm.stl" scale="1 1 1"/>
      </geometry>
    </visual>
  </link>
  <!--LINK: left_lower_arm-->
  <link name="left_lower_arm">
    <inertial>
      <origin rpy="0 0 0" xyz="0.05336545685394963 -0.0008156196838209869 0.0006063260979097202"/>
      <mass value="0.26"/>
      <inertia ixx="0.0003407158555996035" ixy="0.00011823673412134757" ixz="-2.8830788618180246e-05" iyy="0.0017692134503461817" iyz="4.6856873014962955e-06" izz="0.0016180592541080458"/>
    </inertial>
    <visual name="left_lower_arm_visual">
      <origin rpy="0 0 1.570796327" xyz="0.19 0.12 0.22"/>
      <geometry>
        <mesh filename="mesh/left_lower_arm.stl" scale="1 1 1"/>
      </geometry>
    </visual>
  </link>
  <!--LINK: right_hip_yaw-->
  <link name="right_hip_yaw">
    <inertial>
      <origin rpy="0 0 0" xyz="-0.002182239425416095 -0.04605195346010214 -0.024755435159914185"/>
      <mass value="0.067"/>
      <inertia ixx="0.0008822908208723853" ixy="1.6774497281140121e-06" ixz="-7.823405160594508e-06" iyy="0.0017446691851970998" iyz="-2.533160764801179e-05" izz="0.0019969672270540887"/>
    </inertial>
    <visual name="right_hip_yaw_visual">
      <origin rpy="0 0 1.570796327" xyz="0 -0.055 0"/>
      <geometry>
        <mesh filename="mesh/right_hip_yaw.stl" scale="1 1 1"/>
      </geometry>
    </visual>
  </link>
  <!--LINK: left_hip_yaw-->
  <link name="left_hip_yaw">
    <inertial>
      <origin rpy="0 0 0" xyz="-0.002182239425416095 0.04605195346010214 -0.024755435159914185"/>
      <mass value="0.067"/>
      <inertia ixx="0.0008822260608090899" ixy="-1.7055231391090623e-06" ixz="-7.854427661648553e-06" iyy="0.0017446275715154703" iyz="2.5331794090224253e-05" izz="0.001996990306593893"/>
    </inertial>
    <visual name="left_hip_yaw_visual">
      <origin rpy="0 0 1.570796327" xyz="0 0.055 0"/>
      <geometry>
        <mesh filename="mesh/left_hip_yaw.stl" scale="1 1 1"/>
      </geometry>
    </visual>
  </link>
  <!--LINK: right_hip_roll-->
  <link name="right_hip_roll">
    <inertial>
      <origin rpy="0 0 0" xyz="0.015732946879847644 -3.319144005479369e-05 -0.02071085319304939"/>
      <mass value="0.306"/>
      <inertia ixx="0.0001179296979195992" ixy="3.750777661643139e-06" ixz="-3.7623939617341825e-06" iyy="0.00021675292165888234" iyz="-1.0471910235692515e-06" izz="0.000261935711080282"/>
    </inertial>
    <visual name="right_hip_roll_visual">
      <origin rpy="0 0 1.570796327" xyz="0 -0.055 -0.06"/>
      <geometry>
        <mesh filename="mesh/right_hip_roll.stl" scale="1 1 1"/>
      </geometry>
    </visual>
  </link>
  <!--LINK: left_hip_roll-->
  <link name="left_hip_roll">
    <inertial>
      <origin rpy="0 0 0" xyz="0.015732946879847644 3.319144005479369e-05 -0.02071085319304939"/>
      <mass value="0.306"/>
      <inertia ixx="0.0001179296979195992" ixy="3.750777661643139e-06" ixz="-3.7623939617341825e-06" iyy="0.00021675292165888234" iyz="-1.0471910235692515e-06" izz="0.000261935711080282"/>
    </inertial>
    <visual name="left_hip_roll_visual">
      <origin rpy="0 0 1.570796327" xyz="0 0.055 -0.06"/>
      <geometry>
        <mesh filename="mesh/left_hip_roll.stl" scale="1 1 1"/>
      </geometry>
    </visual>
  </link>
  <!--LINK: right_upper_leg-->
  <link name="right_upper_leg">
    <inertial>
      <origin rpy="0 0 0" xyz="-0.0868239473635843 -0.0009904680702090176 -0.0032236573318317092"/>
      <mass value="0.387"/>
      <inertia ixx="0.0006967005196318071" ixy="-9.534768064209597e-06" ixz="-0.00047062464986191157" iyy="0.0023927878790607625" iyz="1.168766364373783e-07" izz="0.0020569215256885614"/>
    </inertial>
    <visual name="right_upper_leg_visual">
      <origin rpy="-0.05 0 1.570796327" xyz="0.01 -0.055 -0.05"/>
      <geometry>
        <mesh filename="mesh/right_upper_leg.stl" scale="1 1 1"/>
      </geometry>
    </visual>
  </link>
  <!--LINK: left_upper_leg-->
  <link name="left_upper_leg">
    <inertial>
      <origin rpy="0 0 0" xyz="-0.0868239473635843 -0.0009904680702090176 -0.0032236573318317092"/>
      <mass value="0.387"/>
      <inertia ixx="0.0006967005196318071" ixy="9.534768064209597e-06" ixz="-0.00047062464986191157" iyy="0.0023927878790607625" iyz="-1.168766364373783e-07" izz="0.0020569215256885614"/>
    </inertial>
    <visual name="left_upper_leg_visual">
      <origin rpy="-0.05 0 1.570796327" xyz="0.01 0.055 -0.06"/>
      <geometry>
        <mesh filename="mesh/left_upper_leg.stl" scale="1 1 1"/>
      </geometry>
    </visual>
  </link>
  <!--LINK: right_lower_leg-->
  <link name="right_lower_leg">
    <inertial>
      <origin rpy="0 0 0" xyz="-0.10000847255111779 0.0012849442073489777 -0.0070729066189781946"/>
      <mass value="0.177"/>
      <inertia ixx="0.00026298531488117623" ixy="-8.38322526058631e-06" ixz="0.0002634339989834785" iyy="0.001587091949550628" iyz="-6.909200774158671e-07" izz="0.001417720950622744"/>
    </inertial>
    <visual name="right_lower_leg_visual">
      <origin rpy="0 0 1.570796327" xyz="0.01 -0.055 -0.25"/>
      <geometry>
        <mesh filename="mesh/right_lower_leg.stl" scale="1 1 1"/>
      </geometry>
    </visual>
  </link>
  <!--LINK: left_lower_leg-->
  <link name="left_lower_leg">
    <inertial>
      <origin rpy="0 0 0" xyz="-0.10000847255111779 0.0012849442073489777 -0.0070729066189781946"/>
      <mass value="0.177"/>
      <inertia ixx="0.00026298531488117623" ixy="8.38322526058631e-06" ixz="0.0002634339989834785" iyy="0.001587091949550628" iyz="6.909200774158671e-07" izz="0.001417720950622744"/>
    </inertial>
    <visual name="left_lower_leg_visual">
      <origin rpy="0 0 1.570796327" xyz="0.01 0.055 -0.25"/>
      <geometry>
        <mesh filename="mesh/left_lower_leg.stl" scale="1 1 1"/>
      </geometry>
    </visual>
  </link>
  <!--LINK: right_ankle-->
  <link name="right_ankle">
    <inertial>
      <origin rpy="0 0 0" xyz="-0.01573294687984541 0.0005126082201406932 -0.02197623716321553"/>
      <mass value="0.306"/>
      <inertia ixx="0.00011792969791959952" ixy="3.7507776616440774e-06" ixz="3.762393961734002e-06" iyy="0.00021675292165888193" iyz="1.0471910235692212e-06" izz="0.0002619357110802831"/>
    </inertial>
    <visual name="right_ankle_visual">
      <origin rpy="0 3.14159 1.570796327" xyz="0 -0.055 -0.45"/>
      <geometry>
        <mesh filename="mesh/right_ankle.stl" scale="1 1 1"/>
      </geometry>
    </visual>
  </link>
  <!--LINK: left_ankle-->
  <link name="left_ankle">
    <inertial>
      <origin rpy="0 0 0" xyz="-0.01573294687984541 0.0005126082201406932 -0.02197623716321553"/>
      <mass value="0.306"/>
      <inertia ixx="0.00011792969791959952" ixy="-3.7507776616440774e-06" ixz="3.762393961734002e-06" iyy="0.00021675292165888193" iyz="-1.0471910235692212e-06" izz="0.0002619357110802831"/>
    </inertial>
    <visual name="left_ankle_visual">
      <origin rpy="0 3.14159 1.570796327" xyz="0 0.055 -0.45"/>
      <geometry>
        <mesh filename="mesh/left_ankle.stl" scale="1 1 1"/>
      </geometry>
    </visual>
  </link>
  <!--LINK: right_foot-->
  <link name="right_foot">
    <inertial>
      <origin rpy="0 0 0" xyz="0.030807480494529724 0.008771710644510001 0.011298451871418577"/>
      <mass value="0.20500000000000002"/>
      <inertia ixx="0.00046922761556703155" ixy="1.237289853891243e-05" ixz="5.165617444725389e-06" iyy="0.0010836186025044235" iyz="-1.7594150186636352e-06" izz="0.0013901177557110861"/>
    </inertial>
    <visual name="right_foot_visual">
      <origin rpy="0 0.0 1.570796327" xyz="-0.04 -0.055 -0.45"/>
      <geometry>
        <mesh filename="mesh/right_foot.stl" scale="1 1 1"/>
      </geometry>
    </visual>
  </link>
  <!--LINK: left_foot-->
  <link name="left_foot">
    <inertial>
      <origin rpy="0 0 0" xyz="0.030807480494529724 0.008771710644510001 0.011298451871418577"/>
      <mass value="0.20500000000000002"/>
      <inertia ixx="0.00046922761556703155" ixy="-1.237289853891243e-05" ixz="5.165617444725389e-06" iyy="0.0010836186025044235" iyz="1.7594150186636352e-06" izz="0.0013901177557110861"/>
    </inertial>
    <visual name="left_foot_visual">
      <origin rpy="0 0 1.570796327" xyz="-0.04 0.055 -0.45"/>
      <geometry>
        <mesh filename="mesh/left_foot.stl" scale="1 1 1"/>
      </geometry>
    </visual>
  </link>
  <!--LINK: neck-->
  <link name="neck">
    <inertial>
      <origin rpy="0 0 0" xyz="-0.006037340172290435 -0.0015998434503701033 0.2411591619288128"/>
      <mass value="0.135"/>
      <inertia ixx="0.0004111124111540318" ixy="1.3444829354587089e-10" ixz="-3.6469345836421835e-10" iyy="0.00034317494217641443" iyz="-1.2460217686668395e-05" izz="0.00023338989035478087"/>
    </inertial>
    <visual name="neck_visual">
      <origin rpy="0 0 1.570796327" xyz="0 0 0.26"/>
      <geometry>
        <mesh filename="mesh/neck.stl" scale="1 1 1"/>
      </geometry>
    </visual>
  </link>
  <!--LINK: head-->
  <link name="head">
    <inertial>
      <origin rpy="0 0 0" xyz="-0.05482228998067195 -0.00010888238321339966 0.0011712900228573724"/>
      <mass value="0.41900000000000004"/>
      <inertia ixx="0.005229542632240126" ixy="8.068689130285243e-07" ixz="-7.854193775142716e-05" iyy="0.004273822060223504" iyz="2.2633217085057325e-07" izz="0.0033336320526664368"/>
    </inertial>
    <visual name="head_visual">
      <origin rpy="0 0 1.570796327" xyz="0 0 0.33"/>
      <geometry>
        <mesh filename="mesh/head.stl" scale="1 1 1"/>
      </geometry>
    </visual>
  </link>
  <!--JOINT: right_shoulder_pitch-->
  <joint name="right_shoulder_pitch" type="revolute">
    <origin rpy="0 0 0" xyz="0 0 0"/>
    <child link="right_shoulder"/>
    <parent link="torso"/>
    <axis xyz="0 1 0">
      <dynamics damping="0.6" friction="0.5"/>
      <limit effort="7.3" lower="-3.141592653589793" upper="3.141592653589793" velocity="8.16814"/>
    </axis>
  </joint>
  <!--JOINT: left_shoulder_pitch-->
  <joint name="left_shoulder_pitch" type="revolute">
    <origin rpy="0 0 0" xyz="0 0 0"/>
    <child link="left_shoulder"/>
    <parent link="torso"/>
    <axis xyz="0 1 0">
      <dynamics damping="0.6" friction="0.5"/>
      <limit effort="7.3" lower="-3.141592653589793" upper="3.141592653589793" velocity="8.16814"/>
    </axis>
  </joint>
  <!--JOINT: right_shoulder_roll-->
  <joint name="right_shoulder_roll" type="revolute">
    <origin rpy="0 0 0" xyz="0 0 0"/>
    <child link="right_upper_arm"/>
    <parent link="right_shoulder"/>
    <axis xyz="0 0 1">
      <dynamics damping="0.6" friction="0.5"/>
      <limit effort="7.3" lower="-3.141592653589793" upper="3.141592653589793" velocity="8.16814"/>
    </axis>
  </joint>
  <!--JOINT: left_shoulder_roll-->
  <joint name="left_shoulder_roll" type="revolute">
    <origin rpy="0 0 0" xyz="0 0 0"/>
    <child link="left_upper_arm"/>
    <parent link="left_shoulder"/>
    <axis xyz="0 0 1">
      <dynamics damping="0.6" friction="0.5"/>
      <limit effort="7.3" lower="-3.141592653589793" upper="3.141592653589793" velocity="8.16814"/>
    </axis>
  </joint>
  <!--JOINT: right_elbow_pitch-->
  <joint name="right_elbow_pitch" type="revolute">
    <origin rpy="0 0 0" xyz="0 0 0"/>
    <child link="right_lower_arm"/>
    <parent link="right_upper_arm"/>
    <axis xyz="0 1 0">
      <dynamics damping="0.6" friction="0.5"/>
      <limit effort="7.3" lower="-3.141592653589793" upper="3.141592653589793" velocity="8.16814"/>
    </axis>
  </joint>
  <!--JOINT: left_elbow_pitch-->
  <joint name="left_elbow_pitch" type="revolute">
    <origin rpy="0 0 0" xyz="0 0 0"/>
    <child link="left_lower_arm"/>
    <parent link="left_upper_arm"/>
    <axis xyz="0 1 0">
      <dynamics damping="0.6" friction="0.5"/>
      <limit effort="7.3" lower="-3.141592653589793" upper="3.141592653589793" velocity="8.16814"/>
    </axis>
  </joint>
  <!--JOINT: right_hip_yaw-->
  <joint name="right_hip_yaw" type="revolute">
    <origin rpy="0 0 0" xyz="0 0 0"/>
    <child link="right_hip_yaw"/>
    <parent link="torso"/>
    <axis xyz="0 0 1">
      <dynamics damping="0.6" friction="0.5"/>
      <limit effort="10.0" lower="-3.141592653589793" upper="3.141592653589793" velocity="5.75959"/>
    </axis>
  </joint>
  <!--JOINT: left_hip_yaw-->
  <joint name="left_hip_yaw" type="revolute">
    <origin rpy="0 0 0" xyz="0 0 0"/>
    <child link="left_hip_yaw"/>
    <parent link="torso"/>
    <axis xyz="0 0 1">
      <dynamics damping="0.6" friction="0.5"/>
      <limit effort="10.0" lower="-3.141592653589793" upper="3.141592653589793" velocity="5.75959"/>
    </axis>
  </joint>
  <!--JOINT: right_hip_roll-->
  <joint name="right_hip_roll" type="revolute">
    <origin rpy="0 0 0" xyz="0 0 0"/>
    <child link="right_hip_roll"/>
    <parent link="right_hip_yaw"/>
    <axis xyz="1 0 0">
      <dynamics damping="0.6" friction="0.5"/>
      <limit effort="10.0" lower="-3.141592653589793" upper="3.141592653589793" velocity="5.75959"/>
    </axis>
  </joint>
  <!--JOINT: left_hip_roll-->
  <joint name="left_hip_roll" type="revolute">
    <origin rpy="0 0 0" xyz="0 0 0"/>
    <child link="left_hip_roll"/>
    <parent link="left_hip_yaw"/>
    <axis xyz="1 0 0">
      <dynamics damping="0.6" friction="0.5"/>
      <limit effort="10.0" lower="-3.141592653589793" upper="3.141592653589793" velocity="5.75959"/>
    </axis>
  </joint>
  <!--JOINT: right_hip_pitch-->
  <joint name="right_hip_pitch" type="revolute">
    <origin rpy="0 0 0" xyz="0 0 0"/>
    <child link="right_upper_leg"/>
    <parent link="right_hip_roll"/>
    <axis xyz="0 1 0">
      <dynamics damping="0.6" friction="0.5"/>
      <limit effort="10.0" lower="-3.141592653589793" upper="3.141592653589793" velocity="5.75959"/>
    </axis>
  </joint>
  <!--JOINT: left_hip_pitch-->
  <joint name="left_hip_pitch" type="revolute">
    <origin rpy="0 0 0" xyz="0 0 0"/>
    <child link="left_upper_leg"/>
    <parent link="left_hip_roll"/>
    <axis xyz="0 1 0">
      <dynamics damping="0.6" friction="0.5"/>
      <limit effort="10.0" lower="-3.141592653589793" upper="3.141592653589793" velocity="5.75959"/>
    </axis>
  </joint>
  <!--JOINT: right_knee_pitch-->
  <joint name="right_knee_pitch" type="revolute">
    <origin rpy="0 0 0" xyz="0 0 0"/>
    <child link="right_lower_leg"/>
    <parent link="right_upper_leg"/>
    <axis xyz="0 1 0">
      <dynamics damping="0.6" friction="0.5"/>
      <limit effort="10.0" lower="-3.141592653589793" upper="3.141592653589793" velocity="5.75959"/>
    </axis>
  </joint>
  <!--JOINT: left_knee_pitch-->
  <joint name="left_knee_pitch" type="revolute">
    <origin rpy="0 0 0" xyz="0 0 0"/>
    <child link="left_lower_leg"/>
    <parent link="left_upper_leg"/>
    <axis xyz="0 1 0">
      <dynamics damping="0.6" friction="0.5"/>
      <limit effort="10.0" lower="-3.141592653589793" upper="3.141592653589793" velocity="5.75959"/>
    </axis>
  </joint>
  <!--JOINT: right_ankle_pitch-->
  <joint name="right_ankle_pitch" type="revolute">
    <origin rpy="0 0 0" xyz="0 0 0"/>
    <child link="right_ankle"/>
    <parent link="right_lower_leg"/>
    <axis xyz="0 1 0">
      <dynamics damping="0.6" friction="0.5"/>
      <limit effort="10.0" lower="-3.141592653589793" upper="3.141592653589793" velocity="5.75959"/>
    </axis>
  </joint>
  <!--JOINT: left_ankle_pitch-->
  <joint name="left_ankle_pitch" type="revolute">
    <origin rpy="0 0 0" xyz="0 0 0"/>
    <child link="left_ankle"/>
    <parent link="left_lower_leg"/>
    <axis xyz="0 1 0">
      <dynamics damping="0.6" friction="0.5"/>
      <limit effort="10.0" lower="-3.141592653589793" upper="3.141592653589793" velocity="5.75959"/>
    </axis>
  </joint>
  <!--JOINT: right_ankle_roll-->
  <joint name="right_ankle_roll" type="revolute">
    <origin rpy="0 0 0" xyz="0 0 0"/>
    <child link="right_foot"/>
    <parent link="right_ankle"/>
    <axis xyz="1 0 0">
      <dynamics damping="0.6" friction="0.5"/>
      <limit effort="10.0" lower="-3.141592653589793" upper="3.141592653589793" velocity="5.75959"/>
    </axis>
  </joint>
  <!--JOINT: left_ankle_roll-->
  <joint name="left_ankle_roll" type="revolute">
    <origin rpy="0 0 0" xyz="0 0 0"/>
    <child link="left_foot"/>
    <parent link="left_ankle"/>
    <axis xyz="1 0 0">
      <dynamics damping="0.6" friction="0.5"/>
      <limit effort="10.0" lower="-3.141592653589793" upper="3.141592653589793" velocity="5.75959"/>
    </axis>
  </joint>
  <!--JOINT: neck_yaw-->
  <joint name="neck_yaw" type="revolute">
    <origin rpy="0 0 0" xyz="0 0 0"/>
    <child link="neck"/>
    <parent link="torso"/>
    <axis xyz="0 0 1">
      <dynamics damping="0.6" friction="0.5"/>
      <limit effort="7.3" lower="-3.141592653589793" upper="3.141592653589793" velocity="8.16814"/>
    </axis>
  </joint>
  <!--JOINT: head_pitch-->
  <joint name="head_pitch" type="revolute">
    <origin rpy="0 0 0" xyz="0 0 0"/>
    <child link="head"/>
    <parent link="neck"/>
    <axis xyz="0 1 0">
      <dynamics damping="0.6" friction="0.5"/>
      <limit effort="7.3" lower="-3.141592653589793" upper="3.141592653589793" velocity="8.16814"/>
    </axis>
  </joint>
</robot>
