<?xml version="1.0" ?>
<sdf version="1.6">
  <!--NUgus SDF Model-->
  <!--Last updated: 18 Aug 2019 22:49:44-->
  <model name="nubots_nugus_hull">
    <pose frame="">0 0 0 0 0 0</pose>
    <!--LINK: torso-->
    <link name="torso">
      <pose frame="">0.0 0.0 0.0 0.0 0.0 1.570796327</pose>
      <inertial>
        <pose frame="">-0.016856 -0.000198 0.019225 0.0 0.0 0.0</pose>
        <mass>1.8051</mass>
        <inertia>
          <ixx>0.016444</ixx>
          <ixy>1.4574e-05</ixy>
          <ixz>0.00048254</ixz>
          <iyy>0.013972</iyy>
          <iyz>5.0355e-06</iyz>
          <izz>0.0064508</izz>
        </inertia>
      </inertial>
      <collision name="torso_collision">
        <pose frame="">0 0 0 0 0 0</pose>
        <geometry>
          <mesh>
            <scale>1 1 1</scale>
            <uri>model://nubots_nugus_hull/mesh/torso.stl</uri>
          </mesh>
        </geometry>
        <surface>
          <contact>
            <ode/>
          </contact>
          <friction>
            <ode>
              <mu>0.5</mu>
              <mu2>0.5</mu2>
            </ode>
            <torsional>
              <coefficient>0.5</coefficient>
              <patch_radius>1.0</patch_radius>
            </torsional>
          </friction>
        </surface>
      </collision>
      <visual name="torso_visual">
        <pose frame="">0 0 0 0 0 0</pose>
        <geometry>
          <mesh>
            <scale>1 1 1</scale>
            <uri>model://nubots_nugus_hull/mesh/torso.stl</uri>
          </mesh>
        </geometry>
        <material>
          <script>
            <name>Gazebo/Grey</name>
            <uri>file://media/materials/scripts/gazebo.material</uri>
          </script>
        </material>
      </visual>
      <gravity>1</gravity>
      <velocity_decay/>
      <self_collide>0</self_collide>
      <sensor name="imu_sensor" type="imu">
        <pose frame="">0.0 0.0 0.0 0.0 0.0 0.0</pose>
        <always_on>1</always_on>
        <visualize>1</visualize>
        <update_rate>1000</update_rate>
        <imu>
          <orientation_reference_frame>
            <localization>GRAV_UP</localization>
            <grav_dir_x>1 0 0</grav_dir_x>
          </orientation_reference_frame>
          <angular_velocity>
            <x>
              <noise type="gaussian">
                <mean>0.0</mean>
              </noise>
            </x>
            <y>
              <noise type="gaussian">
                <mean>0.0</mean>
              </noise>
            </y>
            <z>
              <noise type="gaussian">
                <mean>0.0</mean>
              </noise>
            </z>
          </angular_velocity>
          <linear_acceleration>
            <x>
              <noise type="gaussian">
                <mean>0.0</mean>
              </noise>
            </x>
            <y>
              <noise type="gaussian">
                <mean>0.0</mean>
              </noise>
            </y>
            <z>
              <noise type="gaussian">
                <mean>0.0</mean>
              </noise>
            </z>
          </linear_acceleration>
        </imu>
      </sensor>
    </link>
    <!--LINK: right_shoulder-->
    <link name="right_shoulder">
      <pose frame="">0.005 -0.115 0.18 -1.570796327 0 1.570796327</pose>
      <inertial>
        <pose frame="">0 0 0 0 0 0</pose>
        <mass>0.025434</mass>
        <inertia>
          <ixx>6.7511e-06</ixx>
          <ixy>1.5595e-20</ixy>
          <ixz>-5.4198e-21</ixz>
          <iyy>1.2425e-05</iyy>
          <iyz>-2.4006e-20</iyz>
          <izz>1.4317e-05</izz>
        </inertia>
      </inertial>
      <collision name="right_shoulder_collision">
        <pose frame="">0 0 0 0 0 0</pose>
        <geometry>
          <mesh>
            <scale>1 1 1</scale>
            <uri>model://nubots_nugus_hull/mesh/right_shoulder.stl</uri>
          </mesh>
        </geometry>
        <surface>
          <contact>
            <ode/>
          </contact>
          <friction>
            <ode>
              <mu>0.5</mu>
              <mu2>0.5</mu2>
            </ode>
            <torsional>
              <coefficient>0.5</coefficient>
              <patch_radius>1.0</patch_radius>
            </torsional>
          </friction>
        </surface>
      </collision>
      <visual name="right_shoulder_visual">
        <pose frame="">0 0 0 0 0 0</pose>
        <geometry>
          <mesh>
            <scale>1 1 1</scale>
            <uri>model://nubots_nugus_hull/mesh/right_shoulder.stl</uri>
          </mesh>
        </geometry>
        <material>
          <script>
            <name>Gazebo/Grey</name>
            <uri>file://media/materials/scripts/gazebo.material</uri>
          </script>
        </material>
      </visual>
      <gravity>1</gravity>
      <velocity_decay/>
      <self_collide>0</self_collide>
    </link>
    <!--LINK: left_shoulder-->
    <link name="left_shoulder">
      <pose frame="">0.005 0.115 0.18 -1.570796327 0 1.570796327</pose>
      <inertial>
        <pose frame="">0 0 0 0 0 0</pose>
        <mass>0.025434</mass>
        <inertia>
          <ixx>6.7511e-06</ixx>
          <ixy>6.4644e-21</ixy>
          <ixz>-3.365e-21</ixz>
          <iyy>1.2425e-05</iyy>
          <iyz>-4.6109e-22</iyz>
          <izz>1.4317e-05</izz>
        </inertia>
      </inertial>
      <collision name="left_shoulder_collision">
        <pose frame="">0 0 0 0 0 0</pose>
        <geometry>
          <mesh>
            <scale>1 1 1</scale>
            <uri>model://nubots_nugus_hull/mesh/left_shoulder.stl</uri>
          </mesh>
        </geometry>
        <surface>
          <contact>
            <ode/>
          </contact>
          <friction>
            <ode>
              <mu>0.5</mu>
              <mu2>0.5</mu2>
            </ode>
            <torsional>
              <coefficient>0.5</coefficient>
              <patch_radius>1.0</patch_radius>
            </torsional>
          </friction>
        </surface>
      </collision>
      <visual name="left_shoulder_visual">
        <pose frame="">0 0 0 0 0 0</pose>
        <geometry>
          <mesh>
            <scale>1 1 1</scale>
            <uri>model://nubots_nugus_hull/mesh/left_shoulder.stl</uri>
          </mesh>
        </geometry>
        <material>
          <script>
            <name>Gazebo/Grey</name>
            <uri>file://media/materials/scripts/gazebo.material</uri>
          </script>
        </material>
      </visual>
      <gravity>1</gravity>
      <velocity_decay/>
      <self_collide>0</self_collide>
    </link>
    <!--LINK: right_upper_arm-->
    <link name="right_upper_arm">
      <pose frame="">0 -0.13 0.18 3.14159 3.14159 -1.570796327</pose>
      <inertial>
        <pose frame="">0.001367 -0.000227 -0.049517 0 0 0</pose>
        <mass>0.2575</mass>
        <inertia>
          <ixx>0.00081539</ixx>
          <ixy>1.1134e-07</ixy>
          <ixz>-5.114e-05</ixz>
          <iyy>0.0007994</iyy>
          <iyz>-2.4756e-06</iyz>
          <izz>0.00012883</izz>
        </inertia>
      </inertial>
      <collision name="right_upper_arm_collision">
        <pose frame="">0 0 0 0 0 0</pose>
        <geometry>
          <mesh>
            <scale>1 1 1</scale>
            <uri>model://nubots_nugus_hull/mesh/right_upper_arm.stl</uri>
          </mesh>
        </geometry>
        <surface>
          <contact>
            <ode/>
          </contact>
          <friction>
            <ode>
              <mu>0.5</mu>
              <mu2>0.5</mu2>
            </ode>
            <torsional>
              <coefficient>0.5</coefficient>
              <patch_radius>1.0</patch_radius>
            </torsional>
          </friction>
        </surface>
      </collision>
      <visual name="right_upper_arm_visual">
        <pose frame="">0 0 0 0 0 0</pose>
        <geometry>
          <mesh>
            <scale>1 1 1</scale>
            <uri>model://nubots_nugus_hull/mesh/right_upper_arm.stl</uri>
          </mesh>
        </geometry>
        <material>
          <script>
            <name>Gazebo/Grey</name>
            <uri>file://media/materials/scripts/gazebo.material</uri>
          </script>
        </material>
      </visual>
      <gravity>1</gravity>
      <velocity_decay/>
      <self_collide>0</self_collide>
    </link>
    <!--LINK: left_upper_arm-->
    <link name="left_upper_arm">
      <pose frame="">0 0.13 0.18 3.14159 3.14159 -1.570796327</pose>
      <inertial>
        <pose frame="">0.001367 0.000227 -0.049517 0 0 0</pose>
        <mass>0.2575</mass>
        <inertia>
          <ixx>0.00081539</ixx>
          <ixy>1.1134e-07</ixy>
          <ixz>-5.114e-05</ixz>
          <iyy>0.0007994</iyy>
          <iyz>-2.4756e-06</iyz>
          <izz>0.00012883</izz>
        </inertia>
      </inertial>
      <collision name="left_upper_arm_collision">
        <pose frame="">0 0 0 0 0 0</pose>
        <geometry>
          <mesh>
            <scale>1 1 1</scale>
            <uri>model://nubots_nugus_hull/mesh/left_upper_arm.stl</uri>
          </mesh>
        </geometry>
        <surface>
          <contact>
            <ode/>
          </contact>
          <friction>
            <ode>
              <mu>0.5</mu>
              <mu2>0.5</mu2>
            </ode>
            <torsional>
              <coefficient>0.5</coefficient>
              <patch_radius>1.0</patch_radius>
            </torsional>
          </friction>
        </surface>
      </collision>
      <visual name="left_upper_arm_visual">
        <pose frame="">0 0 0 0 0 0</pose>
        <geometry>
          <mesh>
            <scale>1 1 1</scale>
            <uri>model://nubots_nugus_hull/mesh/left_upper_arm.stl</uri>
          </mesh>
        </geometry>
        <material>
          <script>
            <name>Gazebo/Grey</name>
            <uri>file://media/materials/scripts/gazebo.material</uri>
          </script>
        </material>
      </visual>
      <gravity>1</gravity>
      <velocity_decay/>
      <self_collide>0</self_collide>
    </link>
    <!--LINK: right_lower_arm-->
    <link name="right_lower_arm">
      <pose frame="">0.19 -0.12 0.22 0 0 1.570796327</pose>
      <inertial>
        <pose frame="">0.00185 -0.000227 -0.059095 0 0 0</pose>
        <mass>0.23502</mass>
        <inertia>
          <ixx>0.0011613</ixx>
          <ixy>-5.8221e-07</ixy>
          <ixz>-7.4224e-05</ixz>
          <iyy>0.0011747</iyy>
          <iyz>2.0082e-05</iyz>
          <izz>0.00010273</izz>
        </inertia>
      </inertial>
      <collision name="right_lower_arm_collision">
        <pose frame="">0 0 0 0 0 0</pose>
        <geometry>
          <mesh>
            <scale>1 1 1</scale>
            <uri>model://nubots_nugus_hull/mesh/right_lower_arm.stl</uri>
          </mesh>
        </geometry>
        <surface>
          <contact>
            <ode/>
          </contact>
          <friction>
            <ode>
              <mu>0.5</mu>
              <mu2>0.5</mu2>
            </ode>
            <torsional>
              <coefficient>0.5</coefficient>
              <patch_radius>1.0</patch_radius>
            </torsional>
          </friction>
        </surface>
      </collision>
      <visual name="right_lower_arm_visual">
        <pose frame="">0 0 0 0 0 0</pose>
        <geometry>
          <mesh>
            <scale>1 1 1</scale>
            <uri>model://nubots_nugus_hull/mesh/right_lower_arm.stl</uri>
          </mesh>
        </geometry>
        <material>
          <script>
            <name>Gazebo/Grey</name>
            <uri>file://media/materials/scripts/gazebo.material</uri>
          </script>
        </material>
      </visual>
      <gravity>1</gravity>
      <velocity_decay/>
      <self_collide>0</self_collide>
    </link>
    <!--LINK: left_lower_arm-->
    <link name="left_lower_arm">
      <pose frame="">0.19 0.12 0.22 0 0 1.570796327</pose>
      <inertial>
        <pose frame="">0.001367 0.000227 -0.049517 0 0 0</pose>
        <mass>0.2575</mass>
        <inertia>
          <ixx>0.00081539</ixx>
          <ixy>1.1134e-07</ixy>
          <ixz>-5.114e-05</ixz>
          <iyy>0.0007994</iyy>
          <iyz>-2.4756e-06</iyz>
          <izz>0.00012883</izz>
        </inertia>
      </inertial>
      <collision name="left_lower_arm_collision">
        <pose frame="">0 0 0 0 0 0</pose>
        <geometry>
          <mesh>
            <scale>1 1 1</scale>
            <uri>model://nubots_nugus_hull/mesh/left_lower_arm.stl</uri>
          </mesh>
        </geometry>
        <surface>
          <contact>
            <ode/>
          </contact>
          <friction>
            <ode>
              <mu>0.5</mu>
              <mu2>0.5</mu2>
            </ode>
            <torsional>
              <coefficient>0.5</coefficient>
              <patch_radius>1.0</patch_radius>
            </torsional>
          </friction>
        </surface>
      </collision>
      <visual name="left_lower_arm_visual">
        <pose frame="">0 0 0 0 0 0</pose>
        <geometry>
          <mesh>
            <scale>1 1 1</scale>
            <uri>model://nubots_nugus_hull/mesh/left_lower_arm.stl</uri>
          </mesh>
        </geometry>
        <material>
          <script>
            <name>Gazebo/Grey</name>
            <uri>file://media/materials/scripts/gazebo.material</uri>
          </script>
        </material>
      </visual>
      <gravity>1</gravity>
      <velocity_decay/>
      <self_collide>0</self_collide>
    </link>
    <!--LINK: right_hip_yaw-->
    <link name="right_hip_yaw">
      <pose frame="">0 -0.055 0 0 0 1.570796327</pose>
      <inertial>
        <pose frame="">0 0 -0.013803 0 0 0</pose>
        <mass>0.073374</mass>
        <inertia>
          <ixx>2.6774e-05</ixx>
          <ixy>1.5536e-19</ixy>
          <ixz>-9.0622e-19</ixz>
          <iyy>0.00011478</iyy>
          <iyz>-2.2736e-19</iyz>
          <izz>0.00010743</izz>
        </inertia>
      </inertial>
      <collision name="right_hip_yaw_collision">
        <pose frame="">0 0 0 0 0 0</pose>
        <geometry>
          <mesh>
            <scale>1 1 1</scale>
            <uri>model://nubots_nugus_hull/mesh/right_hip_yaw.stl</uri>
          </mesh>
        </geometry>
        <surface>
          <contact>
            <ode/>
          </contact>
          <friction>
            <ode>
              <mu>0.5</mu>
              <mu2>0.5</mu2>
            </ode>
            <torsional>
              <coefficient>0.5</coefficient>
              <patch_radius>1.0</patch_radius>
            </torsional>
          </friction>
        </surface>
      </collision>
      <visual name="right_hip_yaw_visual">
        <pose frame="">0 0 0 0 0 0</pose>
        <geometry>
          <mesh>
            <scale>1 1 1</scale>
            <uri>model://nubots_nugus_hull/mesh/right_hip_yaw.stl</uri>
          </mesh>
        </geometry>
        <material>
          <script>
            <name>Gazebo/Grey</name>
            <uri>file://media/materials/scripts/gazebo.material</uri>
          </script>
        </material>
      </visual>
      <gravity>1</gravity>
      <velocity_decay/>
      <self_collide>0</self_collide>
    </link>
    <!--LINK: left_hip_yaw-->
    <link name="left_hip_yaw">
      <pose frame="">0 0.055 0 0 0 1.570796327</pose>
      <inertial>
        <pose frame="">0 0 -0.013803 0 0 0</pose>
        <mass>0.073374</mass>
        <inertia>
          <ixx>2.6774e-05</ixx>
          <ixy>1.9727e-19</ixy>
          <ixz>-8.7961e-19</ixz>
          <iyy>0.00011478</iyy>
          <iyz>-2.3128e-19</iyz>
          <izz>0.00010743</izz>
        </inertia>
      </inertial>
      <collision name="left_hip_yaw_collision">
        <pose frame="">0 0 0 0 0 0</pose>
        <geometry>
          <mesh>
            <scale>1 1 1</scale>
            <uri>model://nubots_nugus_hull/mesh/left_hip_yaw.stl</uri>
          </mesh>
        </geometry>
        <surface>
          <contact>
            <ode/>
          </contact>
          <friction>
            <ode>
              <mu>0.5</mu>
              <mu2>0.5</mu2>
            </ode>
            <torsional>
              <coefficient>0.5</coefficient>
              <patch_radius>1.0</patch_radius>
            </torsional>
          </friction>
        </surface>
      </collision>
      <visual name="left_hip_yaw_visual">
        <pose frame="">0 0 0 0 0 0</pose>
        <geometry>
          <mesh>
            <scale>1 1 1</scale>
            <uri>model://nubots_nugus_hull/mesh/left_hip_yaw.stl</uri>
          </mesh>
        </geometry>
        <material>
          <script>
            <name>Gazebo/Grey</name>
            <uri>file://media/materials/scripts/gazebo.material</uri>
          </script>
        </material>
      </visual>
      <gravity>1</gravity>
      <velocity_decay/>
      <self_collide>0</self_collide>
    </link>
    <!--LINK: right_hip_roll-->
    <link name="right_hip_roll">
      <pose frame="">0 -0.055 -0.06 0 0 1.570796327</pose>
      <inertial>
        <pose frame="">0.010896 0.000238 -0.014538 0 0 0</pose>
        <mass>0.35903</mass>
        <inertia>
          <ixx>0.00015503</ixx>
          <ixy>1.738e-06</ixy>
          <ixz>8.5148e-06</ixz>
          <iyy>0.0003299</iyy>
          <iyz>2.4403e-07</iyz>
          <izz>0.0002782</izz>
        </inertia>
      </inertial>
      <collision name="right_hip_roll_collision">
        <pose frame="">0 0 0 0 0 0</pose>
        <geometry>
          <mesh>
            <scale>1 1 1</scale>
            <uri>model://nubots_nugus_hull/mesh/right_hip_roll.stl</uri>
          </mesh>
        </geometry>
        <surface>
          <contact>
            <ode/>
          </contact>
          <friction>
            <ode>
              <mu>0.5</mu>
              <mu2>0.5</mu2>
            </ode>
            <torsional>
              <coefficient>0.5</coefficient>
              <patch_radius>1.0</patch_radius>
            </torsional>
          </friction>
        </surface>
      </collision>
      <visual name="right_hip_roll_visual">
        <pose frame="">0 0 0 0 0 0</pose>
        <geometry>
          <mesh>
            <scale>1 1 1</scale>
            <uri>model://nubots_nugus_hull/mesh/right_hip_roll.stl</uri>
          </mesh>
        </geometry>
        <material>
          <script>
            <name>Gazebo/Grey</name>
            <uri>file://media/materials/scripts/gazebo.material</uri>
          </script>
        </material>
      </visual>
      <gravity>1</gravity>
      <velocity_decay/>
      <self_collide>0</self_collide>
    </link>
    <!--LINK: left_hip_roll-->
    <link name="left_hip_roll">
      <pose frame="">0 0.055 -0.06 0 0 1.570796327</pose>
      <inertial>
        <pose frame="">0 0 -0.013803 0 0 0</pose>
        <mass>0.35903</mass>
        <inertia>
          <ixx>0.00015501</ixx>
          <ixy>-1.7299e-06</ixy>
          <ixz>8.5156e-06</ixz>
          <iyy>0.00032958</iyy>
          <iyz>-2.4435e-07</iyz>
          <izz>0.00027786</izz>
        </inertia>
      </inertial>
      <collision name="left_hip_roll_collision">
        <pose frame="">0 0 0 0 0 0</pose>
        <geometry>
          <mesh>
            <scale>1 1 1</scale>
            <uri>model://nubots_nugus_hull/mesh/left_hip_roll.stl</uri>
          </mesh>
        </geometry>
        <surface>
          <contact>
            <ode/>
          </contact>
          <friction>
            <ode>
              <mu>0.5</mu>
              <mu2>0.5</mu2>
            </ode>
            <torsional>
              <coefficient>0.5</coefficient>
              <patch_radius>1.0</patch_radius>
            </torsional>
          </friction>
        </surface>
      </collision>
      <visual name="left_hip_roll_visual">
        <pose frame="">0 0 0 0 0 0</pose>
        <geometry>
          <mesh>
            <scale>1 1 1</scale>
            <uri>model://nubots_nugus_hull/mesh/left_hip_roll.stl</uri>
          </mesh>
        </geometry>
        <material>
          <script>
            <name>Gazebo/Grey</name>
            <uri>file://media/materials/scripts/gazebo.material</uri>
          </script>
        </material>
      </visual>
      <gravity>1</gravity>
      <velocity_decay/>
      <self_collide>0</self_collide>
    </link>
    <!--LINK: right_upper_leg-->
    <link name="right_upper_leg">
      <pose frame="">0 -0.055 -0.06 0 0 1.570796327</pose>
      <inertial>
        <pose frame="">0.003855 0.000238 -0.1495 0 0 0</pose>
        <mass>0.38276</mass>
        <inertia>
          <ixx>0.0020951</ixx>
          <ixy>1.8755e-07</ixy>
          <ixz>-0.00017816</ixz>
          <iyy>0.0020043</iyy>
          <iyz>-5.4867e-06</iyz>
          <izz>0.00027919</izz>
        </inertia>
      </inertial>
      <collision name="right_upper_leg_collision">
        <pose frame="">0 0 0 0 0</pose>
        <geometry>
          <mesh>
            <scale>1 1 1</scale>
            <uri>model://nubots_nugus_hull/mesh/right_upper_leg.stl</uri>
          </mesh>
        </geometry>
        <surface>
          <contact>
            <ode/>
          </contact>
          <friction>
            <ode>
              <mu>0.5</mu>
              <mu2>0.5</mu2>
            </ode>
            <torsional>
              <coefficient>0.5</coefficient>
              <patch_radius>1.0</patch_radius>
            </torsional>
          </friction>
        </surface>
      </collision>
      <visual name="right_upper_leg_visual">
        <pose frame="">0 0 0 0 0</pose>
        <geometry>
          <mesh>
            <scale>1 1 1</scale>
            <uri>model://nubots_nugus_hull/mesh/right_upper_leg.stl</uri>
          </mesh>
        </geometry>
        <material>
          <script>
            <name>Gazebo/Grey</name>
            <uri>file://media/materials/scripts/gazebo.material</uri>
          </script>
        </material>
      </visual>
      <gravity>1</gravity>
      <velocity_decay/>
      <self_collide>0</self_collide>
    </link>
    <!--LINK: left_upper_leg-->
    <link name="left_upper_leg">
      <pose frame="">0 0.055 -0.06 0 0 1.570796327</pose>
      <inertial>
        <pose frame="">0.003855 -0.000238 -0.1495 0 0 0</pose>
        <mass>0.38276</mass>
        <inertia>
          <ixx>0.0020952</ixx>
          <ixy>-1.9541e-07</ixy>
          <ixz>-0.00017822</ixz>
          <iyy>0.0020044</iyy>
          <iyz>5.4912e-06</iyz>
          <izz>0.00027919</izz>
        </inertia>
      </inertial>
      <collision name="left_upper_leg_collision">
        <pose frame="">0 0 0 0 0</pose>
        <geometry>
          <mesh>
            <scale>1 1 1</scale>
            <uri>model://nubots_nugus_hull/mesh/left_upper_leg.stl</uri>
          </mesh>
        </geometry>
        <surface>
          <contact>
            <ode/>
          </contact>
          <friction>
            <ode>
              <mu>0.5</mu>
              <mu2>0.5</mu2>
            </ode>
            <torsional>
              <coefficient>0.5</coefficient>
              <patch_radius>1.0</patch_radius>
            </torsional>
          </friction>
        </surface>
      </collision>
      <visual name="left_upper_leg_visual">
        <pose frame="">0 0 0 0 0</pose>
        <geometry>
          <mesh>
            <scale>1 1 1</scale>
            <uri>model://nubots_nugus_hull/mesh/left_upper_leg.stl</uri>
          </mesh>
        </geometry>
        <material>
          <script>
            <name>Gazebo/Grey</name>
            <uri>file://media/materials/scripts/gazebo.material</uri>
          </script>
        </material>
      </visual>
      <gravity>1</gravity>
      <velocity_decay/>
      <self_collide>0</self_collide>
    </link>
    <!--LINK: right_lower_leg-->
    <link name="right_lower_leg">
      <pose frame="">0 -0.055 -0.25 0 0 1.570796327</pose>
      <inertial>
        <pose frame="">-0.003378 0 -0.10469 0 0 0</pose>
        <mass>0.20549</mass>
        <inertia>
          <ixx>0.0011378</ixx>
          <ixy>-2.8771e-12</ixy>
          <ixz>9.7123e-05</ixz>
          <iyy>0.0010393</iyy>
          <iyz>-1.4479e-11</iyz>
          <izz>0.00019656</izz>
        </inertia>
      </inertial>
      <collision name="right_lower_leg_collision">
        <pose frame="">0 0 0 0 0</pose>
        <geometry>
          <mesh>
            <scale>1 1 1</scale>
            <uri>model://nubots_nugus_hull/mesh/right_lower_leg.stl</uri>
          </mesh>
        </geometry>
        <surface>
          <contact>
            <ode/>
          </contact>
          <friction>
            <ode>
              <mu>0.5</mu>
              <mu2>0.5</mu2>
            </ode>
            <torsional>
              <coefficient>0.5</coefficient>
              <patch_radius>1.0</patch_radius>
            </torsional>
          </friction>
        </surface>
      </collision>
      <visual name="right_lower_leg_visual">
        <pose frame="">0 0 0 0 0</pose>
        <geometry>
          <mesh>
            <scale>1 1 1</scale>
            <uri>model://nubots_nugus_hull/mesh/right_lower_leg.stl</uri>
          </mesh>
        </geometry>
        <material>
          <script>
            <name>Gazebo/Grey</name>
            <uri>file://media/materials/scripts/gazebo.material</uri>
          </script>
        </material>
      </visual>
      <gravity>1</gravity>
      <velocity_decay/>
      <self_collide>0</self_collide>
    </link>
    <!--LINK: left_lower_leg-->
    <link name="left_lower_leg">
      <pose frame="">0 0.055 -0.25 0 0 1.570796327</pose>
      <inertial>
        <pose frame="">-0.003378 -0.0012 -0.10469 0 0 0</pose>
        <mass>0.20549</mass>
        <inertia>
          <ixx>0.0011378</ixx>
          <ixy>-2.8771e-12</ixy>
          <ixz>9.7123e-05</ixz>
          <iyy>0.0010393</iyy>
          <iyz>-1.4479e-11</iyz>
          <izz>0.00019656</izz>
        </inertia>
      </inertial>
      <collision name="left_lower_leg_collision">
        <pose frame="">0 0 0 0 0</pose>
        <geometry>
          <mesh>
            <scale>1 1 1</scale>
            <uri>model://nubots_nugus_hull/mesh/left_lower_leg.stl</uri>
          </mesh>
        </geometry>
        <surface>
          <contact>
            <ode/>
          </contact>
          <friction>
            <ode>
              <mu>0.5</mu>
              <mu2>0.5</mu2>
            </ode>
            <torsional>
              <coefficient>0.5</coefficient>
              <patch_radius>1.0</patch_radius>
            </torsional>
          </friction>
        </surface>
      </collision>
      <visual name="left_lower_leg_visual">
        <pose frame="">0 0 0 0 0</pose>
        <geometry>
          <mesh>
            <scale>1 1 1</scale>
            <uri>model://nubots_nugus_hull/mesh/left_lower_leg.stl</uri>
          </mesh>
        </geometry>
        <material>
          <script>
            <name>Gazebo/Grey</name>
            <uri>file://media/materials/scripts/gazebo.material</uri>
          </script>
        </material>
      </visual>
      <gravity>1</gravity>
      <velocity_decay/>
      <self_collide>0</self_collide>
    </link>
    <!--LINK: right_ankle-->
    <link name="right_ankle">
      <pose frame="">0 -0.055 -0.45 0 3.14159 1.570796327</pose>
      <inertial>
        <pose frame="">-0.019434 0.00025 0.014536 0 0 0</pose>
        <mass>0.35844</mass>
        <inertia>
          <ixx>0.00015501</ixx>
          <ixy>1.7299e-06</ixy>
          <ixz>-8.5156e-06</ixz>
          <iyy>0.00032958</iyy>
          <iyz>-2.4435e-07</iyz>
          <izz>0.00027786</izz>
        </inertia>
      </inertial>
      <collision name="right_ankle_collision">
        <pose frame="">0.0 0.0 0.0 0.0 0.0 0.0</pose>
        <geometry>
          <mesh>
            <scale>1 1 1</scale>
            <uri>model://nubots_nugus_hull/mesh/right_ankle.stl</uri>
          </mesh>
        </geometry>
        <surface>
          <contact>
            <ode/>
          </contact>
          <friction>
            <ode>
              <mu>0.5</mu>
              <mu2>0.5</mu2>
            </ode>
            <torsional>
              <coefficient>0.5</coefficient>
              <patch_radius>1.0</patch_radius>
            </torsional>
          </friction>
        </surface>
      </collision>
      <visual name="right_ankle_visual">
        <pose frame="">0.0 0.0 0.0 0.0 0.0 0.0</pose>
        <geometry>
          <mesh>
            <scale>1 1 1</scale>
            <uri>model://nubots_nugus_hull/mesh/right_ankle.stl</uri>
          </mesh>
        </geometry>
        <material>
          <script>
            <name>Gazebo/Grey</name>
            <uri>file://media/materials/scripts/gazebo.material</uri>
          </script>
        </material>
      </visual>
      <gravity>1</gravity>
      <velocity_decay/>
      <self_collide>0</self_collide>
    </link>
    <!--LINK: left_ankle-->
    <link name="left_ankle">
      <pose frame="">0 0.055 -0.45 0 3.14159 1.570796327</pose>
      <inertial>
        <pose frame="">-0.019418 -0.001438 0.014538 0 0 0</pose>
        <mass>0.35844</mass>
        <inertia>
          <ixx>0.00015503</ixx>
          <ixy>-1.738e-06</ixy>
          <ixz>-8.5148e-06</ixz>
          <iyy>0.0003299</iyy>
          <iyz>2.4403e-07</iyz>
          <izz>0.0002782</izz>
        </inertia>
      </inertial>
      <collision name="left_ankle_collision">
        <pose frame="">0.0 0.0 0.0 0.0 0.0 0.0</pose>
        <geometry>
          <mesh>
            <scale>1 1 1</scale>
            <uri>model://nubots_nugus_hull/mesh/left_ankle.stl</uri>
          </mesh>
        </geometry>
        <surface>
          <contact>
            <ode/>
          </contact>
          <friction>
            <ode>
              <mu>0.5</mu>
              <mu2>0.5</mu2>
            </ode>
            <torsional>
              <coefficient>0.5</coefficient>
              <patch_radius>1.0</patch_radius>
            </torsional>
          </friction>
        </surface>
      </collision>
      <visual name="left_ankle_visual">
        <pose frame="">0.0 0.0 0.0 0.0 0.0 0.0</pose>
        <geometry>
          <mesh>
            <scale>1 1 1</scale>
            <uri>model://nubots_nugus_hull/mesh/left_ankle.stl</uri>
          </mesh>
        </geometry>
        <material>
          <script>
            <name>Gazebo/Grey</name>
            <uri>file://media/materials/scripts/gazebo.material</uri>
          </script>
        </material>
      </visual>
      <gravity>1</gravity>
      <velocity_decay/>
      <self_collide>0</self_collide>
    </link>
    <!--LINK: right_foot-->
    <link name="right_foot">
      <pose frame="">-0.04 -0.055 -0.45 0.0 0.0 1.570796327</pose>
      <inertial>
        <pose frame="">0.003669 -0.008117 -0.030903 0 0 0</pose>
        <mass>0.1488</mass>
        <inertia>
          <ixx>0.00018527</ixx>
          <ixy>-1.1504e-05</ixy>
          <ixz>-7.2667e-06</ixz>
          <iyy>0.00060485</iyy>
          <iyz>5.8883e-06</iyz>
          <izz>0.00075217</izz>
        </inertia>
      </inertial>
      <collision name="right_foot_collision">
        <pose frame="">0.0 0.0 0.0 0.0 0.0 0.0</pose>
        <geometry>
          <mesh>
            <scale>1 1 1</scale>
            <uri>model://nubots_nugus_hull/mesh/right_foot.stl</uri>
          </mesh>
        </geometry>
        <surface>
          <contact>
            <ode/>
          </contact>
          <friction>
            <ode>
              <mu>0.5</mu>
              <mu2>0.5</mu2>
            </ode>
            <torsional>
              <coefficient>0.5</coefficient>
              <patch_radius>1.0</patch_radius>
            </torsional>
          </friction>
        </surface>
      </collision>
      <visual name="right_foot_visual">
        <pose frame="">0.0 0.0 0.0 0.0 0.0 0.0</pose>
        <geometry>
          <mesh>
            <scale>1 1 1</scale>
            <uri>model://nubots_nugus_hull/mesh/right_foot.stl</uri>
          </mesh>
        </geometry>
        <material>
          <script>
            <name>Gazebo/Grey</name>
            <uri>file://media/materials/scripts/gazebo.material</uri>
          </script>
        </material>
      </visual>
      <gravity>1</gravity>
      <velocity_decay/>
      <self_collide>0</self_collide>
    </link>
    <!--LINK: left_foot-->
    <link name="left_foot">
      <pose frame="">-0.04 0.055 -0.45 0.0 0 1.570796327</pose>
      <inertial>
        <pose frame="">0.003608 0.008119 -0.03091 0 0 0</pose>
        <mass>0.1488</mass>
        <inertia>
          <ixx>0.0001853</ixx>
          <ixy>1.1466e-05</ixy>
          <ixz>-8.3793e-06</ixz>
          <iyy>0.00060485</iyy>
          <iyz>-5.9046e-06</iyz>
          <izz>0.00075213</izz>
        </inertia>
      </inertial>
      <collision name="left_foot_collision">
        <pose frame="">0.0 0.0 0.0 0.0 0.0 0.0</pose>
        <geometry>
          <mesh>
            <scale>1 1 1</scale>
            <uri>model://nubots_nugus_hull/mesh/left_foot.stl</uri>
          </mesh>
        </geometry>
        <surface>
          <contact>
            <ode/>
          </contact>
          <friction>
            <ode>
              <mu>0.5</mu>
              <mu2>0.5</mu2>
            </ode>
            <torsional>
              <coefficient>0.5</coefficient>
              <patch_radius>1.0</patch_radius>
            </torsional>
          </friction>
        </surface>
      </collision>
      <visual name="left_foot_visual">
        <pose frame="">0.0 0.0 0.0 0.0 0.0 0.0</pose>
        <geometry>
          <mesh>
            <scale>1 1 1</scale>
            <uri>model://nubots_nugus_hull/mesh/left_foot.stl</uri>
          </mesh>
        </geometry>
        <material>
          <script>
            <name>Gazebo/Grey</name>
            <uri>file://media/materials/scripts/gazebo.material</uri>
          </script>
        </material>
      </visual>
      <gravity>1</gravity>
      <velocity_decay/>
      <self_collide>0</self_collide>
    </link>
    <!--LINK: neck-->
    <link name="neck">
      <pose frame="">0 0 0.26 0 0 1.570796327</pose>
      <inertial>
        <pose frame="">2.2e-05 0.000648 0.033208 0 0 0</pose>
        <mass>0.15587</mass>
        <inertia>
          <ixx>7.5209e-05</ixx>
          <ixy>-1.8422e-06</ixy>
          <ixz>-4.9817e-07</ixz>
          <iyy>6.2999e-05</iyy>
          <iyz>-9.9088e-08</iyz>
          <izz>3.826e-05</izz>
        </inertia>
      </inertial>
      <collision name="neck_collision">
        <pose frame="">0 0 0 0 0 0</pose>
        <geometry>
          <mesh>
            <scale>1 1 1</scale>
            <uri>model://nubots_nugus_hull/mesh/neck.stl</uri>
          </mesh>
        </geometry>
        <surface>
          <contact>
            <ode/>
          </contact>
          <friction>
            <ode>
              <mu>0.5</mu>
              <mu2>0.5</mu2>
            </ode>
            <torsional>
              <coefficient>0.5</coefficient>
              <patch_radius>1.0</patch_radius>
            </torsional>
          </friction>
        </surface>
      </collision>
      <visual name="neck_visual">
        <pose frame="">0 0 0 0 0 0</pose>
        <geometry>
          <mesh>
            <scale>1 1 1</scale>
            <uri>model://nubots_nugus_hull/mesh/neck.stl</uri>
          </mesh>
        </geometry>
        <material>
          <script>
            <name>Gazebo/Grey</name>
            <uri>file://media/materials/scripts/gazebo.material</uri>
          </script>
        </material>
      </visual>
      <gravity>1</gravity>
      <velocity_decay/>
      <self_collide>0</self_collide>
    </link>
    <!--LINK: head-->
    <link name="head">
      <pose frame="">0 0 0.33 0 0 1.570796327</pose>
      <inertial>
        <pose frame="">0.014358 0.000552 0.069919 0 0 0</pose>
        <mass>0.40746</mass>
        <inertia>
          <ixx>0.0014813</ixx>
          <ixy>3.1631e-07</ixy>
          <ixz>-4.1003e-05</ixz>
          <iyy>0.0016361</iyy>
          <iyz>6.7483e-07</iyz>
          <izz>0.0017353</izz>
        </inertia>
      </inertial>
      <collision name="head_collision">
        <pose frame="">0 0 0 0 0 0</pose>
        <geometry>
          <mesh>
            <scale>1 1 1</scale>
            <uri>model://nubots_nugus_hull/mesh/head.stl</uri>
          </mesh>
        </geometry>
        <surface>
          <contact>
            <ode/>
          </contact>
          <friction>
            <ode>
              <mu>0.5</mu>
              <mu2>0.5</mu2>
            </ode>
            <torsional>
              <coefficient>0.5</coefficient>
              <patch_radius>1.0</patch_radius>
            </torsional>
          </friction>
        </surface>
      </collision>
      <visual name="head_visual">
        <pose frame="">0 0 0 0 0 0</pose>
        <geometry>
          <mesh>
            <scale>1 1 1</scale>
            <uri>model://nubots_nugus_hull/mesh/head.stl</uri>
          </mesh>
        </geometry>
        <material>
          <script>
            <name>Gazebo/Grey</name>
            <uri>file://media/materials/scripts/gazebo.material</uri>
          </script>
        </material>
      </visual>
      <gravity>1</gravity>
      <velocity_decay/>
      <self_collide>0</self_collide>
    </link>
    <!--JOINT: right_shoulder_pitch-->
    <joint name="right_shoulder_pitch" type="revolute">
      <child>right_shoulder</child>
      <parent>torso</parent>
      <axis>
        <xyz>0 1 0</xyz>
        <limit>
          <lower>-3.14159265359</lower>
          <upper>3.14159265359</upper>
          <velocity>8.16814</velocity>
          <effort>10</effort>
        </limit>
        <dynamics>
          <friction>0.6</friction>
          <damping>1.0</damping>
          <spring_reference>0</spring_reference>
          <spring_stiffness>3.25</spring_stiffness>
        </dynamics>
        <use_parent_model_frame>1</use_parent_model_frame>
      </axis>
      <physics>
        <ode>
          <max_force>10</max_force>
        </ode>
      </physics>
    </joint>
    <!--JOINT: left_shoulder_pitch-->
    <joint name="left_shoulder_pitch" type="revolute">
      <child>left_shoulder</child>
      <parent>torso</parent>
      <axis>
        <xyz>0 1 0</xyz>
        <limit>
          <lower>-3.14159265359</lower>
          <upper>3.14159265359</upper>
          <velocity>8.16814</velocity>
          <effort>10</effort>
        </limit>
        <dynamics>
          <friction>0.6</friction>
          <damping>1.0</damping>
          <spring_reference>0</spring_reference>
          <spring_stiffness>3.25</spring_stiffness>
        </dynamics>
        <use_parent_model_frame>1</use_parent_model_frame>
      </axis>
      <physics>
        <ode>
          <max_force>10</max_force>
        </ode>
      </physics>
    </joint>
    <!--JOINT: right_shoulder_roll-->
    <joint name="right_shoulder_roll" type="revolute">
      <child>right_upper_arm</child>
      <parent>right_shoulder</parent>
      <axis>
        <xyz>0 0 1</xyz>
        <limit>
          <lower>-3.14159265359</lower>
          <upper>3.14159265359</upper>
          <velocity>8.16814</velocity>
          <effort>10</effort>
        </limit>
        <dynamics>
          <friction>0.6</friction>
          <damping>1.0</damping>
          <spring_reference>0</spring_reference>
          <spring_stiffness>3.25</spring_stiffness>
        </dynamics>
        <use_parent_model_frame>1</use_parent_model_frame>
      </axis>
      <physics>
        <ode>
          <max_force>10</max_force>
        </ode>
      </physics>
    </joint>
    <!--JOINT: left_shoulder_roll-->
    <joint name="left_shoulder_roll" type="revolute">
      <child>left_upper_arm</child>
      <parent>left_shoulder</parent>
      <axis>
        <xyz>0 0 1</xyz>
        <limit>
          <lower>-3.14159265359</lower>
          <upper>3.14159265359</upper>
          <velocity>8.16814</velocity>
          <effort>10</effort>
        </limit>
        <dynamics>
          <friction>0.6</friction>
          <damping>1.0</damping>
          <spring_reference>0</spring_reference>
          <spring_stiffness>3.25</spring_stiffness>
        </dynamics>
        <use_parent_model_frame>1</use_parent_model_frame>
      </axis>
      <physics>
        <ode>
          <max_force>10</max_force>
        </ode>
      </physics>
    </joint>
    <!--JOINT: right_elbow_pitch-->
    <joint name="right_elbow_pitch" type="revolute">
      <child>right_lower_arm</child>
      <parent>right_upper_arm</parent>
      <axis>
        <xyz>0 1 0</xyz>
        <limit>
          <lower>-3.14159265359</lower>
          <upper>3.14159265359</upper>
          <velocity>8.16814</velocity>
          <effort>10</effort>
        </limit>
        <dynamics>
          <friction>0.6</friction>
          <damping>1.0</damping>
          <spring_reference>0</spring_reference>
          <spring_stiffness>3.25</spring_stiffness>
        </dynamics>
        <use_parent_model_frame>1</use_parent_model_frame>
      </axis>
      <physics>
        <ode>
          <max_force>10</max_force>
        </ode>
      </physics>
    </joint>
    <!--JOINT: left_elbow_pitch-->
    <joint name="left_elbow_pitch" type="revolute">
      <child>left_lower_arm</child>
      <parent>left_upper_arm</parent>
      <axis>
        <xyz>0 1 0</xyz>
        <limit>
          <lower>-3.14159265359</lower>
          <upper>3.14159265359</upper>
          <velocity>8.16814</velocity>
          <effort>10</effort>
        </limit>
        <dynamics>
          <friction>0.6</friction>
          <damping>1.0</damping>
          <spring_reference>0</spring_reference>
          <spring_stiffness>3.25</spring_stiffness>
        </dynamics>
        <use_parent_model_frame>1</use_parent_model_frame>
      </axis>
      <physics>
        <ode>
          <max_force>10</max_force>
        </ode>
      </physics>
    </joint>
    <!--JOINT: right_hip_yaw-->
    <joint name="right_hip_yaw" type="revolute">
      <child>right_hip_yaw</child>
      <parent>torso</parent>
      <axis>
        <xyz>0 0 1</xyz>
        <limit>
          <lower>-3.14159265359</lower>
          <upper>3.14159265359</upper>
          <velocity>5.75959</velocity>
          <effort>10.0</effort>
        </limit>
        <dynamics>
          <friction>0.6</friction>
          <damping>1.0</damping>
          <spring_reference>0</spring_reference>
          <spring_stiffness>3.25</spring_stiffness>
        </dynamics>
        <use_parent_model_frame>1</use_parent_model_frame>
      </axis>
      <physics>
        <ode>
          <max_force>10.0</max_force>
        </ode>
      </physics>
    </joint>
    <!--JOINT: left_hip_yaw-->
    <joint name="left_hip_yaw" type="revolute">
      <child>left_hip_yaw</child>
      <parent>torso</parent>
      <axis>
        <xyz>0 0 1</xyz>
        <limit>
          <lower>-3.14159265359</lower>
          <upper>3.14159265359</upper>
          <velocity>5.75959</velocity>
          <effort>10.0</effort>
        </limit>
        <dynamics>
          <friction>0.6</friction>
          <damping>1.0</damping>
          <spring_reference>0</spring_reference>
          <spring_stiffness>3.25</spring_stiffness>
        </dynamics>
        <use_parent_model_frame>1</use_parent_model_frame>
      </axis>
      <physics>
        <ode>
          <max_force>10.0</max_force>
        </ode>
      </physics>
    </joint>
    <!--JOINT: right_hip_roll-->
    <joint name="right_hip_roll" type="revolute">
      <child>right_hip_roll</child>
      <parent>right_hip_yaw</parent>
      <axis>
        <xyz>1 0 0</xyz>
        <limit>
          <lower>-3.14159265359</lower>
          <upper>3.14159265359</upper>
          <velocity>5.75959</velocity>
          <effort>10.0</effort>
        </limit>
        <dynamics>
          <friction>0.6</friction>
          <damping>1.0</damping>
          <spring_reference>0</spring_reference>
          <spring_stiffness>3.25</spring_stiffness>
        </dynamics>
        <use_parent_model_frame>1</use_parent_model_frame>
      </axis>
      <physics>
        <ode>
          <max_force>10.0</max_force>
        </ode>
      </physics>
    </joint>
    <!--JOINT: left_hip_roll-->
    <joint name="left_hip_roll" type="revolute">
      <child>left_hip_roll</child>
      <parent>left_hip_yaw</parent>
      <axis>
        <xyz>1 0 0</xyz>
        <limit>
          <lower>-3.14159265359</lower>
          <upper>3.14159265359</upper>
          <velocity>5.75959</velocity>
          <effort>10.0</effort>
        </limit>
        <dynamics>
          <friction>0.6</friction>
          <damping>1.0</damping>
          <spring_reference>0</spring_reference>
          <spring_stiffness>3.25</spring_stiffness>
        </dynamics>
        <use_parent_model_frame>1</use_parent_model_frame>
      </axis>
      <physics>
        <ode>
          <max_force>10.0</max_force>
        </ode>
      </physics>
    </joint>
    <!--JOINT: right_hip_pitch-->
    <joint name="right_hip_pitch" type="revolute">
      <child>right_upper_leg</child>
      <parent>right_hip_roll</parent>
      <axis>
        <xyz>0 1 0</xyz>
        <limit>
          <lower>-3.14159265359</lower>
          <upper>3.14159265359</upper>
          <velocity>5.75959</velocity>
          <effort>10.0</effort>
        </limit>
        <dynamics>
          <friction>0.6</friction>
          <damping>1.0</damping>
          <spring_reference>0</spring_reference>
          <spring_stiffness>3.25</spring_stiffness>
        </dynamics>
        <use_parent_model_frame>1</use_parent_model_frame>
      </axis>
      <physics>
        <ode>
          <max_force>10.0</max_force>
        </ode>
      </physics>
    </joint>
    <!--JOINT: left_hip_pitch-->
    <joint name="left_hip_pitch" type="revolute">
      <child>left_upper_leg</child>
      <parent>left_hip_roll</parent>
      <axis>
        <xyz>0 1 0</xyz>
        <limit>
          <lower>-3.14159265359</lower>
          <upper>3.14159265359</upper>
          <velocity>5.75959</velocity>
          <effort>10.0</effort>
        </limit>
        <dynamics>
          <friction>0.6</friction>
          <damping>1.0</damping>
          <spring_reference>0</spring_reference>
          <spring_stiffness>3.25</spring_stiffness>
        </dynamics>
        <use_parent_model_frame>1</use_parent_model_frame>
      </axis>
      <physics>
        <ode>
          <max_force>10.0</max_force>
        </ode>
      </physics>
    </joint>
    <!--JOINT: right_knee_pitch-->
    <joint name="right_knee_pitch" type="revolute">
      <child>right_lower_leg</child>
      <parent>right_upper_leg</parent>
      <axis>
        <xyz>0 1 0</xyz>
        <limit>
          <lower>-3.14159265359</lower>
          <upper>3.14159265359</upper>
          <velocity>5.75959</velocity>
          <effort>10.0</effort>
        </limit>
        <dynamics>
          <friction>0.6</friction>
          <damping>1.0</damping>
          <spring_reference>0</spring_reference>
          <spring_stiffness>3.25</spring_stiffness>
        </dynamics>
        <use_parent_model_frame>1</use_parent_model_frame>
      </axis>
      <physics>
        <ode>
          <max_force>10.0</max_force>
        </ode>
      </physics>
    </joint>
    <!--JOINT: left_knee_pitch-->
    <joint name="left_knee_pitch" type="revolute">
      <child>left_lower_leg</child>
      <parent>left_upper_leg</parent>
      <axis>
        <xyz>0 1 0</xyz>
        <limit>
          <lower>-3.14159265359</lower>
          <upper>3.14159265359</upper>
          <velocity>5.75959</velocity>
          <effort>10.0</effort>
        </limit>
        <dynamics>
          <friction>0.6</friction>
          <damping>1.0</damping>
          <spring_reference>0</spring_reference>
          <spring_stiffness>3.25</spring_stiffness>
        </dynamics>
        <use_parent_model_frame>1</use_parent_model_frame>
      </axis>
      <physics>
        <ode>
          <max_force>10.0</max_force>
        </ode>
      </physics>
    </joint>
    <!--JOINT: right_ankle_pitch-->
    <joint name="right_ankle_pitch" type="revolute">
      <child>right_ankle</child>
      <parent>right_lower_leg</parent>
      <axis>
        <xyz>0 1 0</xyz>
        <limit>
          <lower>-3.14159265359</lower>
          <upper>3.14159265359</upper>
          <velocity>5.75959</velocity>
          <effort>10.0</effort>
        </limit>
        <dynamics>
          <friction>0.6</friction>
          <damping>1.0</damping>
          <spring_reference>0</spring_reference>
          <spring_stiffness>3.25</spring_stiffness>
        </dynamics>
        <use_parent_model_frame>1</use_parent_model_frame>
      </axis>
      <physics>
        <ode>
          <max_force>10.0</max_force>
        </ode>
      </physics>
    </joint>
    <!--JOINT: left_ankle_pitch-->
    <joint name="left_ankle_pitch" type="revolute">
      <child>left_ankle</child>
      <parent>left_lower_leg</parent>
      <axis>
        <xyz>0 1 0</xyz>
        <limit>
          <lower>-3.14159265359</lower>
          <upper>3.14159265359</upper>
          <velocity>5.75959</velocity>
          <effort>10.0</effort>
        </limit>
        <dynamics>
          <friction>0.6</friction>
          <damping>1.0</damping>
          <spring_reference>0</spring_reference>
          <spring_stiffness>3.25</spring_stiffness>
        </dynamics>
        <use_parent_model_frame>1</use_parent_model_frame>
      </axis>
      <physics>
        <ode>
          <max_force>10.0</max_force>
        </ode>
      </physics>
    </joint>
    <!--JOINT: right_ankle_roll-->
    <joint name="right_ankle_roll" type="revolute">
      <child>right_foot</child>
      <parent>right_ankle</parent>
      <axis>
        <xyz>1 0 0</xyz>
        <limit>
          <lower>-3.14159265359</lower>
          <upper>3.14159265359</upper>
          <velocity>5.75959</velocity>
          <effort>10.0</effort>
        </limit>
        <dynamics>
          <friction>0.6</friction>
          <damping>1.0</damping>
          <spring_reference>0</spring_reference>
          <spring_stiffness>3.25</spring_stiffness>
        </dynamics>
        <use_parent_model_frame>1</use_parent_model_frame>
      </axis>
      <physics>
        <ode>
          <max_force>10.0</max_force>
        </ode>
      </physics>
    </joint>
    <!--JOINT: left_ankle_roll-->
    <joint name="left_ankle_roll" type="revolute">
      <child>left_foot</child>
      <parent>left_ankle</parent>
      <axis>
        <xyz>1 0 0</xyz>
        <limit>
          <lower>-3.14159265359</lower>
          <upper>3.14159265359</upper>
          <velocity>5.75959</velocity>
          <effort>10.0</effort>
        </limit>
        <dynamics>
          <friction>0.6</friction>
          <damping>1.0</damping>
          <spring_reference>0</spring_reference>
          <spring_stiffness>3.25</spring_stiffness>
        </dynamics>
        <use_parent_model_frame>1</use_parent_model_frame>
      </axis>
      <physics>
        <ode>
          <max_force>10.0</max_force>
        </ode>
      </physics>
    </joint>
    <!--JOINT: neck_yaw-->
    <joint name="neck_yaw" type="revolute">
      <child>neck</child>
      <parent>torso</parent>
      <axis>
        <xyz>0 0 1</xyz>
        <limit>
          <lower>-3.14159265359</lower>
          <upper>3.14159265359</upper>
          <velocity>8.16814</velocity>
          <effort>10</effort>
        </limit>
        <dynamics>
          <friction>0.6</friction>
          <damping>1.0</damping>
          <spring_reference>0</spring_reference>
          <spring_stiffness>3.25</spring_stiffness>
        </dynamics>
        <use_parent_model_frame>1</use_parent_model_frame>
      </axis>
      <physics>
        <ode>
          <max_force>10</max_force>
        </ode>
      </physics>
    </joint>
    <!--JOINT: head_pitch-->
    <joint name="head_pitch" type="revolute">
      <child>head</child>
      <parent>neck</parent>
      <axis>
        <xyz>0 1 0</xyz>
        <limit>
          <lower>-3.14159265359</lower>
          <upper>3.14159265359</upper>
          <velocity>8.16814</velocity>
          <effort>10</effort>
        </limit>
        <dynamics>
          <friction>0.6</friction>
          <damping>1.0</damping>
          <spring_reference>0</spring_reference>
          <spring_stiffness>3.25</spring_stiffness>
        </dynamics>
        <use_parent_model_frame>1</use_parent_model_frame>
      </axis>
      <physics>
        <ode>
          <max_force>10</max_force>
        </ode>
      </physics>
    </joint>
  </model>
</sdf>
