<?xml version="1.0" ?>
<sdf version="1.6">
  <!--NUgus SDF Model-->
  <!--Last updated: 19 Aug 2019 23:11:51-->
  <model name="nubots_nugus_hull">
    <pose frame="">0 0 0 0 0 0</pose>
    <!--LINK: torso-->
    <link name="torso">
      <pose frame="">0.0 0.0 0.0 0.0 0.0 1.570796327</pose>
      <inertial>
        <pose frame="">0.0050079703254699804 0.008880921777563762 0.1021503146237477 0.0 0.0 0.0</pose>
        <mass>2.5390000000000006</mass>
        <inertia>
          <ixx>0.01665728720713129</ixx>
          <ixy>0.0015451858906936002</ixy>
          <ixz>0.004938657742879685</ixz>
          <iyy>0.004225235417508923</iyy>
          <iyz>0.0012027533896274989</iyz>
          <izz>0.05550778391062456</izz>
        </inertia>
      </inertial>
      <collision name="torso_collision">
        <pose frame="">0 0 0 0 0 0</pose>
        <geometry>
          <mesh>
            <scale>1 1 1</scale>
            <uri>model://nubots_nugus_hull/mesh/torso.stl</uri>
          </mesh>
        </geometry>
        <surface>
          <contact>
            <ode/>
          </contact>
          <friction>
            <ode>
              <mu>0.98</mu>
              <mu2>0.98</mu2>
              <slip1>1e-05</slip1>
              <slip2>1e-05</slip2>
            </ode>
            <torsional>
              <coefficient>0.8</coefficient>
              <patch_radius>1.0</patch_radius>
            </torsional>
          </friction>
        </surface>
      </collision>
      <visual name="torso_visual">
        <pose frame="">0 0 0 0 0 0</pose>
        <geometry>
          <mesh>
            <scale>1 1 1</scale>
            <uri>model://nubots_nugus_hull/mesh/torso.stl</uri>
          </mesh>
        </geometry>
        <material>
          <script>
            <name>Gazebo/Grey</name>
            <uri>file://media/materials/scripts/gazebo.material</uri>
          </script>
        </material>
      </visual>
      <gravity>1</gravity>
      <self_collide/>
      <sensor name="imu_sensor" type="imu">
        <pose frame="">0.0 0.0 0.0 0.0 0.0 0.0</pose>
        <always_on>1</always_on>
        <visualize>1</visualize>
        <update_rate>100</update_rate>
        <imu>
          <orientation_reference_frame>
            <localization>GRAV_UP</localization>
            <grav_dir_x>1 0 0</grav_dir_x>
          </orientation_reference_frame>
          <angular_velocity>
            <x>
              <noise type="gaussian">
                <mean>0.0</mean>
              </noise>
            </x>
            <y>
              <noise type="gaussian">
                <mean>0.0</mean>
              </noise>
            </y>
            <z>
              <noise type="gaussian">
                <mean>0.0</mean>
              </noise>
            </z>
          </angular_velocity>
          <linear_acceleration>
            <x>
              <noise type="gaussian">
                <mean>0.0</mean>
              </noise>
            </x>
            <y>
              <noise type="gaussian">
                <mean>0.0</mean>
              </noise>
            </y>
            <z>
              <noise type="gaussian">
                <mean>0.0</mean>
              </noise>
            </z>
          </linear_acceleration>
        </imu>
      </sensor>
    </link>
    <!--LINK: right_shoulder-->
    <link name="right_shoulder">
      <pose frame="">0.005 -0.115 0.18 -1.570796327 0 1.570796327</pose>
      <inertial>
        <pose frame="">0.003491 -0.001684 0.003753 0 0 0</pose>
        <mass>0.025434</mass>
        <inertia>
          <ixx>0.000636</ixx>
          <ixy>2e-06</ixy>
          <ixz>-3.5e-05</ixz>
          <iyy>0.000485</iyy>
          <iyz>6e-06</iyz>
          <izz>0.000628</izz>
        </inertia>
      </inertial>
      <collision name="right_shoulder_collision">
        <pose frame="">0 0 0 0 0 0</pose>
        <geometry>
          <mesh>
            <scale>1 1 1</scale>
            <uri>model://nubots_nugus_hull/mesh/right_shoulder.stl</uri>
          </mesh>
        </geometry>
        <surface>
          <contact>
            <ode/>
          </contact>
          <friction>
            <ode>
              <mu>0.98</mu>
              <mu2>0.98</mu2>
              <slip1>1e-05</slip1>
              <slip2>1e-05</slip2>
            </ode>
            <torsional>
              <coefficient>0.8</coefficient>
              <patch_radius>1.0</patch_radius>
            </torsional>
          </friction>
        </surface>
      </collision>
      <visual name="right_shoulder_visual">
        <pose frame="">0 0 0 0 0 0</pose>
        <geometry>
          <mesh>
            <scale>1 1 1</scale>
            <uri>model://nubots_nugus_hull/mesh/right_shoulder.stl</uri>
          </mesh>
        </geometry>
        <material>
          <script>
            <name>Gazebo/Grey</name>
            <uri>file://media/materials/scripts/gazebo.material</uri>
          </script>
        </material>
      </visual>
      <gravity>1</gravity>
      <self_collide/>
    </link>
    <!--LINK: left_shoulder-->
    <link name="left_shoulder">
      <pose frame="">0.005 0.115 0.18 -1.570796327 0 1.570796327</pose>
      <inertial>
        <pose frame="">0.003491 -0.001684 0.003753 0 0 0</pose>
        <mass>0.025434</mass>
        <inertia>
          <ixx>0.000636</ixx>
          <ixy>-2e-06</ixy>
          <ixz>-3.5e-05</ixz>
          <iyy>0.000485</iyy>
          <iyz>-6e-06</iyz>
          <izz>0.000628</izz>
        </inertia>
      </inertial>
      <collision name="left_shoulder_collision">
        <pose frame="">0 0 0 0 0 0</pose>
        <geometry>
          <mesh>
            <scale>1 1 1</scale>
            <uri>model://nubots_nugus_hull/mesh/left_shoulder.stl</uri>
          </mesh>
        </geometry>
        <surface>
          <contact>
            <ode/>
          </contact>
          <friction>
            <ode>
              <mu>0.98</mu>
              <mu2>0.98</mu2>
              <slip1>1e-05</slip1>
              <slip2>1e-05</slip2>
            </ode>
            <torsional>
              <coefficient>0.8</coefficient>
              <patch_radius>1.0</patch_radius>
            </torsional>
          </friction>
        </surface>
      </collision>
      <visual name="left_shoulder_visual">
        <pose frame="">0 0 0 0 0 0</pose>
        <geometry>
          <mesh>
            <scale>1 1 1</scale>
            <uri>model://nubots_nugus_hull/mesh/left_shoulder.stl</uri>
          </mesh>
        </geometry>
        <material>
          <script>
            <name>Gazebo/Grey</name>
            <uri>file://media/materials/scripts/gazebo.material</uri>
          </script>
        </material>
      </visual>
      <gravity>1</gravity>
      <self_collide/>
    </link>
    <!--LINK: right_upper_arm-->
    <link name="right_upper_arm">
      <pose frame="">0 -0.13 0.18 3.14159 3.14159 -1.570796327</pose>
      <inertial>
        <pose frame="">-0.0004754647829298364 -0.0004830631532648927 -0.047851449636613815 0 0 0</pose>
        <mass>0.29700000000000004</mass>
        <inertia>
          <ixx>0.002440902596230906</ixx>
          <ixy>-3.6713691248137597e-06</ixy>
          <ixz>-0.00013891452285131982</ixz>
          <iyy>0.002283834053695376</iyy>
          <iyz>-1.9795333785260962e-05</iyz>
          <izz>0.0005366937214088004</izz>
        </inertia>
      </inertial>
      <collision name="right_upper_arm_collision">
        <pose frame="">0 0 0 0 0 0</pose>
        <geometry>
          <mesh>
            <scale>1 1 1</scale>
            <uri>model://nubots_nugus_hull/mesh/right_upper_arm.stl</uri>
          </mesh>
        </geometry>
        <surface>
          <contact>
            <ode/>
          </contact>
          <friction>
            <ode>
              <mu>0.98</mu>
              <mu2>0.98</mu2>
              <slip1>1e-05</slip1>
              <slip2>1e-05</slip2>
            </ode>
            <torsional>
              <coefficient>0.8</coefficient>
              <patch_radius>1.0</patch_radius>
            </torsional>
          </friction>
        </surface>
      </collision>
      <visual name="right_upper_arm_visual">
        <pose frame="">0 0 0 0 0 0</pose>
        <geometry>
          <mesh>
            <scale>1 1 1</scale>
            <uri>model://nubots_nugus_hull/mesh/right_upper_arm.stl</uri>
          </mesh>
        </geometry>
        <material>
          <script>
            <name>Gazebo/Grey</name>
            <uri>file://media/materials/scripts/gazebo.material</uri>
          </script>
        </material>
      </visual>
      <gravity>1</gravity>
      <self_collide/>
    </link>
    <!--LINK: left_upper_arm-->
    <link name="left_upper_arm">
      <pose frame="">0 0.13 0.18 3.14159 3.14159 -1.570796327</pose>
      <inertial>
        <pose frame="">-0.0004754647829298364 0.0004830631532648927 -0.047851449636613815 0 0 0</pose>
        <mass>0.29700000000000004</mass>
        <inertia>
          <ixx>0.002440902596230906</ixx>
          <ixy>-3.6713691248137597e-06</ixy>
          <ixz>-0.00013891452285131982</ixz>
          <iyy>0.002283834053695376</iyy>
          <iyz>-1.9795333785260962e-05</iyz>
          <izz>0.0005366937214088004</izz>
        </inertia>
      </inertial>
      <collision name="left_upper_arm_collision">
        <pose frame="">0 0 0 0 0 0</pose>
        <geometry>
          <mesh>
            <scale>1 1 1</scale>
            <uri>model://nubots_nugus_hull/mesh/left_upper_arm.stl</uri>
          </mesh>
        </geometry>
        <surface>
          <contact>
            <ode/>
          </contact>
          <friction>
            <ode>
              <mu>0.98</mu>
              <mu2>0.98</mu2>
              <slip1>1e-05</slip1>
              <slip2>1e-05</slip2>
            </ode>
            <torsional>
              <coefficient>0.8</coefficient>
              <patch_radius>1.0</patch_radius>
            </torsional>
          </friction>
        </surface>
      </collision>
      <visual name="left_upper_arm_visual">
        <pose frame="">0 0 0 0 0 0</pose>
        <geometry>
          <mesh>
            <scale>1 1 1</scale>
            <uri>model://nubots_nugus_hull/mesh/left_upper_arm.stl</uri>
          </mesh>
        </geometry>
        <material>
          <script>
            <name>Gazebo/Grey</name>
            <uri>file://media/materials/scripts/gazebo.material</uri>
          </script>
        </material>
      </visual>
      <gravity>1</gravity>
      <self_collide/>
    </link>
    <!--LINK: right_lower_arm-->
    <link name="right_lower_arm">
      <pose frame="">0.19 -0.12 0.22 0 0 1.570796327</pose>
      <inertial>
        <pose frame="">0.05336545685394963 -0.0008156196838209869 0.0006063260979097202 0 0 0</pose>
        <mass>0.26</mass>
        <inertia>
          <ixx>0.0003407158555996035</ixx>
          <ixy>0.00011823673412134757</ixy>
          <ixz>-2.8830788618180246e-05</ixz>
          <iyy>0.0017692134503461817</iyy>
          <iyz>4.6856873014962955e-06</iyz>
          <izz>0.0016180592541080458</izz>
        </inertia>
      </inertial>
      <collision name="right_lower_arm_collision">
        <pose frame="">0 0 0 0 0 0</pose>
        <geometry>
          <mesh>
            <scale>1 1 1</scale>
            <uri>model://nubots_nugus_hull/mesh/right_lower_arm.stl</uri>
          </mesh>
        </geometry>
        <surface>
          <contact>
            <ode/>
          </contact>
          <friction>
            <ode>
              <mu>0.98</mu>
              <mu2>0.98</mu2>
              <slip1>1e-05</slip1>
              <slip2>1e-05</slip2>
            </ode>
            <torsional>
              <coefficient>0.8</coefficient>
              <patch_radius>1.0</patch_radius>
            </torsional>
          </friction>
        </surface>
      </collision>
      <visual name="right_lower_arm_visual">
        <pose frame="">0 0 0 0 0 0</pose>
        <geometry>
          <mesh>
            <scale>1 1 1</scale>
            <uri>model://nubots_nugus_hull/mesh/right_lower_arm.stl</uri>
          </mesh>
        </geometry>
        <material>
          <script>
            <name>Gazebo/Grey</name>
            <uri>file://media/materials/scripts/gazebo.material</uri>
          </script>
        </material>
      </visual>
      <gravity>1</gravity>
      <self_collide/>
    </link>
    <!--LINK: left_lower_arm-->
    <link name="left_lower_arm">
      <pose frame="">0.19 0.12 0.22 0 0 1.570796327</pose>
      <inertial>
        <pose frame="">0.05336545685394963 -0.0008156196838209869 0.0006063260979097202 0 0 0</pose>
        <mass>0.26</mass>
        <inertia>
          <ixx>0.0003407158555996035</ixx>
          <ixy>0.00011823673412134757</ixy>
          <ixz>-2.8830788618180246e-05</ixz>
          <iyy>0.0017692134503461817</iyy>
          <iyz>4.6856873014962955e-06</iyz>
          <izz>0.0016180592541080458</izz>
        </inertia>
      </inertial>
      <collision name="left_lower_arm_collision">
        <pose frame="">0 0 0 0 0 0</pose>
        <geometry>
          <mesh>
            <scale>1 1 1</scale>
            <uri>model://nubots_nugus_hull/mesh/left_lower_arm.stl</uri>
          </mesh>
        </geometry>
        <surface>
          <contact>
            <ode/>
          </contact>
          <friction>
            <ode>
              <mu>0.98</mu>
              <mu2>0.98</mu2>
              <slip1>1e-05</slip1>
              <slip2>1e-05</slip2>
            </ode>
            <torsional>
              <coefficient>0.8</coefficient>
              <patch_radius>1.0</patch_radius>
            </torsional>
          </friction>
        </surface>
      </collision>
      <visual name="left_lower_arm_visual">
        <pose frame="">0 0 0 0 0 0</pose>
        <geometry>
          <mesh>
            <scale>1 1 1</scale>
            <uri>model://nubots_nugus_hull/mesh/left_lower_arm.stl</uri>
          </mesh>
        </geometry>
        <material>
          <script>
            <name>Gazebo/Grey</name>
            <uri>file://media/materials/scripts/gazebo.material</uri>
          </script>
        </material>
      </visual>
      <gravity>1</gravity>
      <self_collide/>
    </link>
    <!--LINK: right_hip_yaw-->
    <link name="right_hip_yaw">
      <pose frame="">0 -0.055 0 0 0 1.570796327</pose>
      <inertial>
        <pose frame="">-0.002182239425416095 -0.04605195346010214 -0.024755435159914185</pose>
        <mass>0.067</mass>
        <inertia>
          <ixx>0.0008822908208723853</ixx>
          <ixy>1.6774497281140121e-06</ixy>
          <ixz>-7.823405160594508e-06</ixz>
          <iyy>0.0017446691851970998</iyy>
          <iyz>-2.533160764801179e-05</iyz>
          <izz>0.0019969672270540887</izz>
        </inertia>
      </inertial>
      <collision name="right_hip_yaw_collision">
        <pose frame="">0 0 0 0 0 0</pose>
        <geometry>
          <mesh>
            <scale>1 1 1</scale>
            <uri>model://nubots_nugus_hull/mesh/right_hip_yaw.stl</uri>
          </mesh>
        </geometry>
        <surface>
          <contact>
            <ode/>
          </contact>
          <friction>
            <ode>
              <mu>0.98</mu>
              <mu2>0.98</mu2>
              <slip1>1e-05</slip1>
              <slip2>1e-05</slip2>
            </ode>
            <torsional>
              <coefficient>0.8</coefficient>
              <patch_radius>1.0</patch_radius>
            </torsional>
          </friction>
        </surface>
      </collision>
      <visual name="right_hip_yaw_visual">
        <pose frame="">0 0 0 0 0 0</pose>
        <geometry>
          <mesh>
            <scale>1 1 1</scale>
            <uri>model://nubots_nugus_hull/mesh/right_hip_yaw.stl</uri>
          </mesh>
        </geometry>
        <material>
          <script>
            <name>Gazebo/Grey</name>
            <uri>file://media/materials/scripts/gazebo.material</uri>
          </script>
        </material>
      </visual>
      <gravity>1</gravity>
      <self_collide/>
    </link>
    <!--LINK: left_hip_yaw-->
    <link name="left_hip_yaw">
      <pose frame="">0 0.055 0 0 0 1.570796327</pose>
      <inertial>
        <pose frame="">-0.002182239425416095 0.04605195346010214 -0.024755435159914185</pose>
        <mass>0.067</mass>
        <inertia>
          <ixx>0.0008822260608090899</ixx>
          <ixy>-1.7055231391090623e-06</ixy>
          <ixz>-7.854427661648553e-06</ixz>
          <iyy>0.0017446275715154703</iyy>
          <iyz>2.5331794090224253e-05</iyz>
          <izz>0.001996990306593893</izz>
        </inertia>
      </inertial>
      <collision name="left_hip_yaw_collision">
        <pose frame="">0 0 0 0 0 0</pose>
        <geometry>
          <mesh>
            <scale>1 1 1</scale>
            <uri>model://nubots_nugus_hull/mesh/left_hip_yaw.stl</uri>
          </mesh>
        </geometry>
        <surface>
          <contact>
            <ode/>
          </contact>
          <friction>
            <ode>
              <mu>0.98</mu>
              <mu2>0.98</mu2>
              <slip1>1e-05</slip1>
              <slip2>1e-05</slip2>
            </ode>
            <torsional>
              <coefficient>0.8</coefficient>
              <patch_radius>1.0</patch_radius>
            </torsional>
          </friction>
        </surface>
      </collision>
      <visual name="left_hip_yaw_visual">
        <pose frame="">0 0 0 0 0 0</pose>
        <geometry>
          <mesh>
            <scale>1 1 1</scale>
            <uri>model://nubots_nugus_hull/mesh/left_hip_yaw.stl</uri>
          </mesh>
        </geometry>
        <material>
          <script>
            <name>Gazebo/Grey</name>
            <uri>file://media/materials/scripts/gazebo.material</uri>
          </script>
        </material>
      </visual>
      <gravity>1</gravity>
      <self_collide/>
    </link>
    <!--LINK: right_hip_roll-->
    <link name="right_hip_roll">
      <pose frame="">0 -0.055 -0.06 0 0 1.570796327</pose>
      <inertial>
        <pose frame="">0.015732946879847644 -3.319144005479369e-05 -0.02071085319304939</pose>
        <mass>0.306</mass>
        <inertia>
          <ixx>0.0001179296979195992</ixx>
          <ixy>3.750777661643139e-06</ixy>
          <ixz>-3.7623939617341825e-06</ixz>
          <iyy>0.00021675292165888234</iyy>
          <iyz>-1.0471910235692515e-06</iyz>
          <izz>0.000261935711080282</izz>
        </inertia>
      </inertial>
      <collision name="right_hip_roll_collision">
        <pose frame="">0 0 0 0 0 0</pose>
        <geometry>
          <mesh>
            <scale>1 1 1</scale>
            <uri>model://nubots_nugus_hull/mesh/right_hip_roll.stl</uri>
          </mesh>
        </geometry>
        <surface>
          <contact>
            <ode/>
          </contact>
          <friction>
            <ode>
              <mu>0.98</mu>
              <mu2>0.98</mu2>
              <slip1>1e-05</slip1>
              <slip2>1e-05</slip2>
            </ode>
            <torsional>
              <coefficient>0.8</coefficient>
              <patch_radius>1.0</patch_radius>
            </torsional>
          </friction>
        </surface>
      </collision>
      <visual name="right_hip_roll_visual">
        <pose frame="">0 0 0 0 0 0</pose>
        <geometry>
          <mesh>
            <scale>1 1 1</scale>
            <uri>model://nubots_nugus_hull/mesh/right_hip_roll.stl</uri>
          </mesh>
        </geometry>
        <material>
          <script>
            <name>Gazebo/Grey</name>
            <uri>file://media/materials/scripts/gazebo.material</uri>
          </script>
        </material>
      </visual>
      <gravity>1</gravity>
      <self_collide/>
    </link>
    <!--LINK: left_hip_roll-->
    <link name="left_hip_roll">
      <pose frame="">0 0.055 -0.06 0 0 1.570796327</pose>
      <inertial>
        <pose frame="">0.015732946879847644 3.319144005479369e-05 -0.02071085319304939</pose>
        <mass>0.306</mass>
        <inertia>
          <ixx>0.0001179296979195992</ixx>
          <ixy>3.750777661643139e-06</ixy>
          <ixz>-3.7623939617341825e-06</ixz>
          <iyy>0.00021675292165888234</iyy>
          <iyz>-1.0471910235692515e-06</iyz>
          <izz>0.000261935711080282</izz>
        </inertia>
      </inertial>
      <collision name="left_hip_roll_collision">
        <pose frame="">0 0 0 0 0 0</pose>
        <geometry>
          <mesh>
            <scale>1 1 1</scale>
            <uri>model://nubots_nugus_hull/mesh/left_hip_roll.stl</uri>
          </mesh>
        </geometry>
        <surface>
          <contact>
            <ode/>
          </contact>
          <friction>
            <ode>
              <mu>0.98</mu>
              <mu2>0.98</mu2>
              <slip1>1e-05</slip1>
              <slip2>1e-05</slip2>
            </ode>
            <torsional>
              <coefficient>0.8</coefficient>
              <patch_radius>1.0</patch_radius>
            </torsional>
          </friction>
        </surface>
      </collision>
      <visual name="left_hip_roll_visual">
        <pose frame="">0 0 0 0 0 0</pose>
        <geometry>
          <mesh>
            <scale>1 1 1</scale>
            <uri>model://nubots_nugus_hull/mesh/left_hip_roll.stl</uri>
          </mesh>
        </geometry>
        <material>
          <script>
            <name>Gazebo/Grey</name>
            <uri>file://media/materials/scripts/gazebo.material</uri>
          </script>
        </material>
      </visual>
      <gravity>1</gravity>
      <self_collide/>
    </link>
    <!--LINK: right_upper_leg-->
    <link name="right_upper_leg">
      <pose frame="">0.01 -0.055 -0.05 -0.05 0 1.570796327</pose>
      <inertial>
        <pose frame="">-0.0868239473635843 -0.0009904680702090176 -0.0032236573318317092 0 0 0</pose>
        <mass>0.387</mass>
        <inertia>
          <ixx>0.0006967005196318071</ixx>
          <ixy>-9.534768064209597e-06</ixy>
          <ixz>-0.00047062464986191157</ixz>
          <iyy>0.0023927878790607625</iyy>
          <iyz>1.168766364373783e-07</iyz>
          <izz>0.0020569215256885614</izz>
        </inertia>
      </inertial>
      <collision name="right_upper_leg_collision">
        <pose frame="">0 0 0 0 0 0</pose>
        <geometry>
          <mesh>
            <scale>1 1 1</scale>
            <uri>model://nubots_nugus_hull/mesh/right_upper_leg.stl</uri>
          </mesh>
        </geometry>
        <surface>
          <contact>
            <ode/>
          </contact>
          <friction>
            <ode>
              <mu>0.98</mu>
              <mu2>0.98</mu2>
              <slip1>1e-05</slip1>
              <slip2>1e-05</slip2>
            </ode>
            <torsional>
              <coefficient>0.8</coefficient>
              <patch_radius>1.0</patch_radius>
            </torsional>
          </friction>
        </surface>
      </collision>
      <visual name="right_upper_leg_visual">
        <pose frame="">0 0 0 0 0 0</pose>
        <geometry>
          <mesh>
            <scale>1 1 1</scale>
            <uri>model://nubots_nugus_hull/mesh/right_upper_leg.stl</uri>
          </mesh>
        </geometry>
        <material>
          <script>
            <name>Gazebo/Grey</name>
            <uri>file://media/materials/scripts/gazebo.material</uri>
          </script>
        </material>
      </visual>
      <gravity>1</gravity>
      <self_collide/>
    </link>
    <!--LINK: left_upper_leg-->
    <link name="left_upper_leg">
      <pose frame="">0.01 0.055 -0.06 -0.05 0 1.570796327</pose>
      <inertial>
        <pose frame="">-0.0868239473635843 -0.0009904680702090176 -0.0032236573318317092 0 0 0</pose>
        <mass>0.387</mass>
        <inertia>
          <ixx>0.0006967005196318071</ixx>
          <ixy>9.534768064209597e-06</ixy>
          <ixz>-0.00047062464986191157</ixz>
          <iyy>0.0023927878790607625</iyy>
          <iyz>-1.168766364373783e-07</iyz>
          <izz>0.0020569215256885614</izz>
        </inertia>
      </inertial>
      <collision name="left_upper_leg_collision">
        <pose frame="">0 0 0 0 0 0</pose>
        <geometry>
          <mesh>
            <scale>1 1 1</scale>
            <uri>model://nubots_nugus_hull/mesh/left_upper_leg.stl</uri>
          </mesh>
        </geometry>
        <surface>
          <contact>
            <ode/>
          </contact>
          <friction>
            <ode>
              <mu>0.98</mu>
              <mu2>0.98</mu2>
              <slip1>1e-05</slip1>
              <slip2>1e-05</slip2>
            </ode>
            <torsional>
              <coefficient>0.8</coefficient>
              <patch_radius>1.0</patch_radius>
            </torsional>
          </friction>
        </surface>
      </collision>
      <visual name="left_upper_leg_visual">
        <pose frame="">0 0 0 0 0 0</pose>
        <geometry>
          <mesh>
            <scale>1 1 1</scale>
            <uri>model://nubots_nugus_hull/mesh/left_upper_leg.stl</uri>
          </mesh>
        </geometry>
        <material>
          <script>
            <name>Gazebo/Grey</name>
            <uri>file://media/materials/scripts/gazebo.material</uri>
          </script>
        </material>
      </visual>
      <gravity>1</gravity>
      <self_collide/>
    </link>
    <!--LINK: right_lower_leg-->
    <link name="right_lower_leg">
      <pose frame="">0.01 -0.055 -0.25 0 0 1.570796327</pose>
      <inertial>
        <pose frame="">-0.10000847255111779 0.0012849442073489777 -0.0070729066189781946 0 0 0</pose>
        <mass>0.177</mass>
        <inertia>
          <ixx>0.00026298531488117623</ixx>
          <ixy>-8.38322526058631e-06</ixy>
          <ixz>0.0002634339989834785</ixz>
          <iyy>0.001587091949550628</iyy>
          <iyz>-6.909200774158671e-07</iyz>
          <izz>0.001417720950622744</izz>
        </inertia>
      </inertial>
      <collision name="right_lower_leg_collision">
        <pose frame="">0 0 0 0 0 0</pose>
        <geometry>
          <mesh>
            <scale>1 1 1</scale>
            <uri>model://nubots_nugus_hull/mesh/right_lower_leg.stl</uri>
          </mesh>
        </geometry>
        <surface>
          <contact>
            <ode/>
          </contact>
          <friction>
            <ode>
              <mu>0.98</mu>
              <mu2>0.98</mu2>
              <slip1>1e-05</slip1>
              <slip2>1e-05</slip2>
            </ode>
            <torsional>
              <coefficient>0.8</coefficient>
              <patch_radius>1.0</patch_radius>
            </torsional>
          </friction>
        </surface>
      </collision>
      <visual name="right_lower_leg_visual">
        <pose frame="">0 0 0 0 0 0</pose>
        <geometry>
          <mesh>
            <scale>1 1 1</scale>
            <uri>model://nubots_nugus_hull/mesh/right_lower_leg.stl</uri>
          </mesh>
        </geometry>
        <material>
          <script>
            <name>Gazebo/Grey</name>
            <uri>file://media/materials/scripts/gazebo.material</uri>
          </script>
        </material>
      </visual>
      <gravity>1</gravity>
      <self_collide/>
    </link>
    <!--LINK: left_lower_leg-->
    <link name="left_lower_leg">
      <pose frame="">0.01 0.055 -0.25 0 0 1.570796327</pose>
      <inertial>
        <pose frame="">-0.10000847255111779 0.0012849442073489777 -0.0070729066189781946 0 0 0</pose>
        <mass>0.177</mass>
        <inertia>
          <ixx>0.00026298531488117623</ixx>
          <ixy>8.38322526058631e-06</ixy>
          <ixz>0.0002634339989834785</ixz>
          <iyy>0.001587091949550628</iyy>
          <iyz>6.909200774158671e-07</iyz>
          <izz>0.001417720950622744</izz>
        </inertia>
      </inertial>
      <collision name="left_lower_leg_collision">
        <pose frame="">0 0 0 0 0 0</pose>
        <geometry>
          <mesh>
            <scale>1 1 1</scale>
            <uri>model://nubots_nugus_hull/mesh/left_lower_leg.stl</uri>
          </mesh>
        </geometry>
        <surface>
          <contact>
            <ode/>
          </contact>
          <friction>
            <ode>
              <mu>0.98</mu>
              <mu2>0.98</mu2>
              <slip1>1e-05</slip1>
              <slip2>1e-05</slip2>
            </ode>
            <torsional>
              <coefficient>0.8</coefficient>
              <patch_radius>1.0</patch_radius>
            </torsional>
          </friction>
        </surface>
      </collision>
      <visual name="left_lower_leg_visual">
        <pose frame="">0 0 0 0 0 0</pose>
        <geometry>
          <mesh>
            <scale>1 1 1</scale>
            <uri>model://nubots_nugus_hull/mesh/left_lower_leg.stl</uri>
          </mesh>
        </geometry>
        <material>
          <script>
            <name>Gazebo/Grey</name>
            <uri>file://media/materials/scripts/gazebo.material</uri>
          </script>
        </material>
      </visual>
      <gravity>1</gravity>
      <self_collide/>
    </link>
    <!--LINK: right_ankle-->
    <link name="right_ankle">
      <pose frame="">0 -0.055 -0.45 0 3.14159 1.570796327</pose>
      <inertial>
        <pose frame="">-0.01573294687984541 0.0005126082201406932 -0.02197623716321553 0 0 0</pose>
        <mass>0.306</mass>
        <inertia>
          <ixx>0.00011792969791959952</ixx>
          <ixy>3.7507776616440774e-06</ixy>
          <ixz>3.762393961734002e-06</ixz>
          <iyy>0.00021675292165888193</iyy>
          <iyz>1.0471910235692212e-06</iyz>
          <izz>0.0002619357110802831</izz>
        </inertia>
      </inertial>
      <collision name="right_ankle_collision">
        <pose frame="">0 0 0 0 0 0</pose>
        <geometry>
          <mesh>
            <scale>1 1 1</scale>
            <uri>model://nubots_nugus_hull/mesh/right_ankle.stl</uri>
          </mesh>
        </geometry>
        <surface>
          <contact>
            <ode/>
          </contact>
          <friction>
            <ode>
              <mu>0.98</mu>
              <mu2>0.98</mu2>
              <slip1>1e-05</slip1>
              <slip2>1e-05</slip2>
            </ode>
            <torsional>
              <coefficient>0.8</coefficient>
              <patch_radius>1.0</patch_radius>
            </torsional>
          </friction>
        </surface>
      </collision>
      <visual name="right_ankle_visual">
        <pose frame="">0 0 0 0 0 0</pose>
        <geometry>
          <mesh>
            <scale>1 1 1</scale>
            <uri>model://nubots_nugus_hull/mesh/right_ankle.stl</uri>
          </mesh>
        </geometry>
        <material>
          <script>
            <name>Gazebo/Grey</name>
            <uri>file://media/materials/scripts/gazebo.material</uri>
          </script>
        </material>
      </visual>
      <gravity>1</gravity>
      <self_collide/>
    </link>
    <!--LINK: left_ankle-->
    <link name="left_ankle">
      <pose frame="">0 0.055 -0.45 0 3.14159 1.570796327</pose>
      <inertial>
        <pose frame="">-0.01573294687984541 0.0005126082201406932 -0.02197623716321553 0 0 0</pose>
        <mass>0.306</mass>
        <inertia>
          <ixx>0.00011792969791959952</ixx>
          <ixy>-3.7507776616440774e-06</ixy>
          <ixz>3.762393961734002e-06</ixz>
          <iyy>0.00021675292165888193</iyy>
          <iyz>-1.0471910235692212e-06</iyz>
          <izz>0.0002619357110802831</izz>
        </inertia>
      </inertial>
      <collision name="left_ankle_collision">
        <pose frame="">0 0 0 0 0 0</pose>
        <geometry>
          <mesh>
            <scale>1 1 1</scale>
            <uri>model://nubots_nugus_hull/mesh/left_ankle.stl</uri>
          </mesh>
        </geometry>
        <surface>
          <contact>
            <ode/>
          </contact>
          <friction>
            <ode>
              <mu>0.98</mu>
              <mu2>0.98</mu2>
              <slip1>1e-05</slip1>
              <slip2>1e-05</slip2>
            </ode>
            <torsional>
              <coefficient>0.8</coefficient>
              <patch_radius>1.0</patch_radius>
            </torsional>
          </friction>
        </surface>
      </collision>
      <visual name="left_ankle_visual">
        <pose frame="">0 0 0 0 0 0</pose>
        <geometry>
          <mesh>
            <scale>1 1 1</scale>
            <uri>model://nubots_nugus_hull/mesh/left_ankle.stl</uri>
          </mesh>
        </geometry>
        <material>
          <script>
            <name>Gazebo/Grey</name>
            <uri>file://media/materials/scripts/gazebo.material</uri>
          </script>
        </material>
      </visual>
      <gravity>1</gravity>
      <self_collide/>
    </link>
    <!--LINK: right_foot-->
    <link name="right_foot">
      <pose frame="">-0.04 -0.055 -0.45 0 0.0 1.570796327</pose>
      <inertial>
        <pose frame="">0.030807480494529724 0.008771710644510001 0.011298451871418577 0 0 0</pose>
        <mass>0.20500000000000002</mass>
        <inertia>
          <ixx>0.00046922761556703155</ixx>
          <ixy>1.237289853891243e-05</ixy>
          <ixz>5.165617444725389e-06</ixz>
          <iyy>0.0010836186025044235</iyy>
          <iyz>-1.7594150186636352e-06</iyz>
          <izz>0.0013901177557110861</izz>
        </inertia>
      </inertial>
      <collision name="right_foot_collision">
        <pose frame="">0 0 0 0 0 0</pose>
        <geometry>
          <mesh>
            <scale>1 1 1</scale>
            <uri>model://nubots_nugus_hull/mesh/right_foot.stl</uri>
          </mesh>
        </geometry>
        <surface>
          <contact>
            <ode/>
          </contact>
          <friction>
            <ode>
              <mu>0.98</mu>
              <mu2>0.98</mu2>
              <slip1>1e-05</slip1>
              <slip2>1e-05</slip2>
            </ode>
            <torsional>
              <coefficient>0.8</coefficient>
              <patch_radius>1.0</patch_radius>
            </torsional>
          </friction>
        </surface>
      </collision>
      <visual name="right_foot_visual">
        <pose frame="">0 0 0 0 0 0</pose>
        <geometry>
          <mesh>
            <scale>1 1 1</scale>
            <uri>model://nubots_nugus_hull/mesh/right_foot.stl</uri>
          </mesh>
        </geometry>
        <material>
          <script>
            <name>Gazebo/Grey</name>
            <uri>file://media/materials/scripts/gazebo.material</uri>
          </script>
        </material>
      </visual>
      <gravity>1</gravity>
      <self_collide/>
    </link>
    <!--LINK: left_foot-->
    <link name="left_foot">
      <pose frame="">-0.04 0.055 -0.45 0 0 1.570796327</pose>
      <inertial>
        <pose frame="">0.030807480494529724 0.008771710644510001 0.011298451871418577 0 0 0</pose>
        <mass>0.20500000000000002</mass>
        <inertia>
          <ixx>0.00046922761556703155</ixx>
          <ixy>-1.237289853891243e-05</ixy>
          <ixz>5.165617444725389e-06</ixz>
          <iyy>0.0010836186025044235</iyy>
          <iyz>1.7594150186636352e-06</iyz>
          <izz>0.0013901177557110861</izz>
        </inertia>
      </inertial>
      <collision name="left_foot_collision">
        <pose frame="">0 0 0 0 0 0</pose>
        <geometry>
          <mesh>
            <scale>1 1 1</scale>
            <uri>model://nubots_nugus_hull/mesh/left_foot.stl</uri>
          </mesh>
        </geometry>
        <surface>
          <contact>
            <ode/>
          </contact>
          <friction>
            <ode>
              <mu>0.98</mu>
              <mu2>0.98</mu2>
              <slip1>1e-05</slip1>
              <slip2>1e-05</slip2>
            </ode>
            <torsional>
              <coefficient>0.8</coefficient>
              <patch_radius>1.0</patch_radius>
            </torsional>
          </friction>
        </surface>
      </collision>
      <visual name="left_foot_visual">
        <pose frame="">0 0 0 0 0 0</pose>
        <geometry>
          <mesh>
            <scale>1 1 1</scale>
            <uri>model://nubots_nugus_hull/mesh/left_foot.stl</uri>
          </mesh>
        </geometry>
        <material>
          <script>
            <name>Gazebo/Grey</name>
            <uri>file://media/materials/scripts/gazebo.material</uri>
          </script>
        </material>
      </visual>
      <gravity>1</gravity>
      <self_collide/>
    </link>
    <!--LINK: neck-->
    <link name="neck">
      <pose frame="">0 0 0.26 0 0 1.570796327</pose>
      <inertial>
        <pose frame="">-0.006037340172290435 -0.0015998434503701033 0.2411591619288128 0 0 0</pose>
        <mass>0.135</mass>
        <inertia>
          <ixx>0.0004111124111540318</ixx>
          <ixy>1.3444829354587089e-10</ixy>
          <ixz>-3.6469345836421835e-10</ixz>
          <iyy>0.00034317494217641443</iyy>
          <iyz>-1.2460217686668395e-05</iyz>
          <izz>0.00023338989035478087</izz>
        </inertia>
      </inertial>
      <collision name="neck_collision">
        <pose frame="">0 0 0 0 0 0</pose>
        <geometry>
          <mesh>
            <scale>1 1 1</scale>
            <uri>model://nubots_nugus_hull/mesh/neck.stl</uri>
          </mesh>
        </geometry>
        <surface>
          <contact>
            <ode/>
          </contact>
          <friction>
            <ode>
              <mu>0.98</mu>
              <mu2>0.98</mu2>
              <slip1>1e-05</slip1>
              <slip2>1e-05</slip2>
            </ode>
            <torsional>
              <coefficient>0.8</coefficient>
              <patch_radius>1.0</patch_radius>
            </torsional>
          </friction>
        </surface>
      </collision>
      <visual name="neck_visual">
        <pose frame="">0 0 0 0 0 0</pose>
        <geometry>
          <mesh>
            <scale>1 1 1</scale>
            <uri>model://nubots_nugus_hull/mesh/neck.stl</uri>
          </mesh>
        </geometry>
        <material>
          <script>
            <name>Gazebo/Grey</name>
            <uri>file://media/materials/scripts/gazebo.material</uri>
          </script>
        </material>
      </visual>
      <gravity>1</gravity>
      <self_collide/>
    </link>
    <!--LINK: head-->
    <link name="head">
      <pose frame="">0 0 0.33 0 0 1.570796327</pose>
      <inertial>
        <pose frame="">-0.05482228998067195 -0.00010888238321339966 0.0011712900228573724 0 0 0</pose>
        <mass>0.41900000000000004</mass>
        <inertia>
          <ixx>0.005229542632240126</ixx>
          <ixy>8.068689130285243e-07</ixy>
          <ixz>-7.854193775142716e-05</ixz>
          <iyy>0.004273822060223504</iyy>
          <iyz>2.2633217085057325e-07</iyz>
          <izz>0.0033336320526664368</izz>
        </inertia>
      </inertial>
      <collision name="head_collision">
        <pose frame="">0 0 0 0 0 0</pose>
        <geometry>
          <mesh>
            <scale>1 1 1</scale>
            <uri>model://nubots_nugus_hull/mesh/head.stl</uri>
          </mesh>
        </geometry>
        <surface>
          <contact>
            <ode/>
          </contact>
          <friction>
            <ode>
              <mu>0.98</mu>
              <mu2>0.98</mu2>
              <slip1>1e-05</slip1>
              <slip2>1e-05</slip2>
            </ode>
            <torsional>
              <coefficient>0.8</coefficient>
              <patch_radius>1.0</patch_radius>
            </torsional>
          </friction>
        </surface>
      </collision>
      <visual name="head_visual">
        <pose frame="">0 0 0 0 0 0</pose>
        <geometry>
          <mesh>
            <scale>1 1 1</scale>
            <uri>model://nubots_nugus_hull/mesh/head.stl</uri>
          </mesh>
        </geometry>
        <material>
          <script>
            <name>Gazebo/Grey</name>
            <uri>file://media/materials/scripts/gazebo.material</uri>
          </script>
        </material>
      </visual>
      <gravity>1</gravity>
      <self_collide/>
    </link>
    <!--JOINT: right_shoulder_pitch-->
    <joint name="right_shoulder_pitch" type="revolute">
      <child>right_shoulder</child>
      <parent>torso</parent>
      <axis>
        <xyz>0 1 0</xyz>
        <limit>
          <lower>-3.141592653589793</lower>
          <upper>3.141592653589793</upper>
          <velocity>8.16814</velocity>
          <effort>7.3</effort>
        </limit>
        <dynamics>
          <friction>0.5</friction>
          <damping>0.6</damping>
          <spring_reference>0</spring_reference>
          <spring_stiffness>3.25</spring_stiffness>
        </dynamics>
        <use_parent_model_frame>1</use_parent_model_frame>
      </axis>
    </joint>
    <!--JOINT: left_shoulder_pitch-->
    <joint name="left_shoulder_pitch" type="revolute">
      <child>left_shoulder</child>
      <parent>torso</parent>
      <axis>
        <xyz>0 1 0</xyz>
        <limit>
          <lower>-3.141592653589793</lower>
          <upper>3.141592653589793</upper>
          <velocity>8.16814</velocity>
          <effort>7.3</effort>
        </limit>
        <dynamics>
          <friction>0.5</friction>
          <damping>0.6</damping>
          <spring_reference>0</spring_reference>
          <spring_stiffness>3.25</spring_stiffness>
        </dynamics>
        <use_parent_model_frame>1</use_parent_model_frame>
      </axis>
    </joint>
    <!--JOINT: right_shoulder_roll-->
    <joint name="right_shoulder_roll" type="revolute">
      <child>right_upper_arm</child>
      <parent>right_shoulder</parent>
      <axis>
        <xyz>0 0 1</xyz>
        <limit>
          <lower>-3.141592653589793</lower>
          <upper>3.141592653589793</upper>
          <velocity>8.16814</velocity>
          <effort>7.3</effort>
        </limit>
        <dynamics>
          <friction>0.5</friction>
          <damping>0.6</damping>
          <spring_reference>0</spring_reference>
          <spring_stiffness>3.25</spring_stiffness>
        </dynamics>
        <use_parent_model_frame>1</use_parent_model_frame>
      </axis>
    </joint>
    <!--JOINT: left_shoulder_roll-->
    <joint name="left_shoulder_roll" type="revolute">
      <child>left_upper_arm</child>
      <parent>left_shoulder</parent>
      <axis>
        <xyz>0 0 1</xyz>
        <limit>
          <lower>-3.141592653589793</lower>
          <upper>3.141592653589793</upper>
          <velocity>8.16814</velocity>
          <effort>7.3</effort>
        </limit>
        <dynamics>
          <friction>0.5</friction>
          <damping>0.6</damping>
          <spring_reference>0</spring_reference>
          <spring_stiffness>3.25</spring_stiffness>
        </dynamics>
        <use_parent_model_frame>1</use_parent_model_frame>
      </axis>
    </joint>
    <!--JOINT: right_elbow_pitch-->
    <joint name="right_elbow_pitch" type="revolute">
      <child>right_lower_arm</child>
      <parent>right_upper_arm</parent>
      <axis>
        <xyz>0 1 0</xyz>
        <limit>
          <lower>-3.141592653589793</lower>
          <upper>3.141592653589793</upper>
          <velocity>8.16814</velocity>
          <effort>7.3</effort>
        </limit>
        <dynamics>
          <friction>0.5</friction>
          <damping>0.6</damping>
          <spring_reference>0</spring_reference>
          <spring_stiffness>3.25</spring_stiffness>
        </dynamics>
        <use_parent_model_frame>1</use_parent_model_frame>
      </axis>
    </joint>
    <!--JOINT: left_elbow_pitch-->
    <joint name="left_elbow_pitch" type="revolute">
      <child>left_lower_arm</child>
      <parent>left_upper_arm</parent>
      <axis>
        <xyz>0 1 0</xyz>
        <limit>
          <lower>-3.141592653589793</lower>
          <upper>3.141592653589793</upper>
          <velocity>8.16814</velocity>
          <effort>7.3</effort>
        </limit>
        <dynamics>
          <friction>0.5</friction>
          <damping>0.6</damping>
          <spring_reference>0</spring_reference>
          <spring_stiffness>3.25</spring_stiffness>
        </dynamics>
        <use_parent_model_frame>1</use_parent_model_frame>
      </axis>
    </joint>
    <!--JOINT: right_hip_yaw-->
    <joint name="right_hip_yaw" type="revolute">
      <child>right_hip_yaw</child>
      <parent>torso</parent>
      <axis>
        <xyz>0 0 1</xyz>
        <limit>
          <lower>-3.141592653589793</lower>
          <upper>3.141592653589793</upper>
          <velocity>5.75959</velocity>
          <effort>10.0</effort>
        </limit>
        <dynamics>
          <friction>0.5</friction>
          <damping>0.6</damping>
          <spring_reference>0</spring_reference>
          <spring_stiffness>3.25</spring_stiffness>
        </dynamics>
        <use_parent_model_frame>1</use_parent_model_frame>
      </axis>
    </joint>
    <!--JOINT: left_hip_yaw-->
    <joint name="left_hip_yaw" type="revolute">
      <child>left_hip_yaw</child>
      <parent>torso</parent>
      <axis>
        <xyz>0 0 1</xyz>
        <limit>
          <lower>-3.141592653589793</lower>
          <upper>3.141592653589793</upper>
          <velocity>5.75959</velocity>
          <effort>10.0</effort>
        </limit>
        <dynamics>
          <friction>0.5</friction>
          <damping>0.6</damping>
          <spring_reference>0</spring_reference>
          <spring_stiffness>3.25</spring_stiffness>
        </dynamics>
        <use_parent_model_frame>1</use_parent_model_frame>
      </axis>
    </joint>
    <!--JOINT: right_hip_roll-->
    <joint name="right_hip_roll" type="revolute">
      <child>right_hip_roll</child>
      <parent>right_hip_yaw</parent>
      <axis>
        <xyz>1 0 0</xyz>
        <limit>
          <lower>-3.141592653589793</lower>
          <upper>3.141592653589793</upper>
          <velocity>5.75959</velocity>
          <effort>10.0</effort>
        </limit>
        <dynamics>
          <friction>0.5</friction>
          <damping>0.6</damping>
          <spring_reference>0</spring_reference>
          <spring_stiffness>3.25</spring_stiffness>
        </dynamics>
        <use_parent_model_frame>1</use_parent_model_frame>
      </axis>
    </joint>
    <!--JOINT: left_hip_roll-->
    <joint name="left_hip_roll" type="revolute">
      <child>left_hip_roll</child>
      <parent>left_hip_yaw</parent>
      <axis>
        <xyz>1 0 0</xyz>
        <limit>
          <lower>-3.141592653589793</lower>
          <upper>3.141592653589793</upper>
          <velocity>5.75959</velocity>
          <effort>10.0</effort>
        </limit>
        <dynamics>
          <friction>0.5</friction>
          <damping>0.6</damping>
          <spring_reference>0</spring_reference>
          <spring_stiffness>3.25</spring_stiffness>
        </dynamics>
        <use_parent_model_frame>1</use_parent_model_frame>
      </axis>
    </joint>
    <!--JOINT: right_hip_pitch-->
    <joint name="right_hip_pitch" type="revolute">
      <child>right_upper_leg</child>
      <parent>right_hip_roll</parent>
      <axis>
        <xyz>0 1 0</xyz>
        <limit>
          <lower>-3.141592653589793</lower>
          <upper>3.141592653589793</upper>
          <velocity>5.75959</velocity>
          <effort>10.0</effort>
        </limit>
        <dynamics>
          <friction>0.5</friction>
          <damping>0.6</damping>
          <spring_reference>0</spring_reference>
          <spring_stiffness>3.25</spring_stiffness>
        </dynamics>
        <use_parent_model_frame>1</use_parent_model_frame>
      </axis>
    </joint>
    <!--JOINT: left_hip_pitch-->
    <joint name="left_hip_pitch" type="revolute">
      <child>left_upper_leg</child>
      <parent>left_hip_roll</parent>
      <axis>
        <xyz>0 1 0</xyz>
        <limit>
          <lower>-3.141592653589793</lower>
          <upper>3.141592653589793</upper>
          <velocity>5.75959</velocity>
          <effort>10.0</effort>
        </limit>
        <dynamics>
          <friction>0.5</friction>
          <damping>0.6</damping>
          <spring_reference>0</spring_reference>
          <spring_stiffness>3.25</spring_stiffness>
        </dynamics>
        <use_parent_model_frame>1</use_parent_model_frame>
      </axis>
    </joint>
    <!--JOINT: right_knee_pitch-->
    <joint name="right_knee_pitch" type="revolute">
      <child>right_lower_leg</child>
      <parent>right_upper_leg</parent>
      <axis>
        <xyz>0 1 0</xyz>
        <limit>
          <lower>-3.141592653589793</lower>
          <upper>3.141592653589793</upper>
          <velocity>5.75959</velocity>
          <effort>10.0</effort>
        </limit>
        <dynamics>
          <friction>0.5</friction>
          <damping>0.6</damping>
          <spring_reference>0</spring_reference>
          <spring_stiffness>3.25</spring_stiffness>
        </dynamics>
        <use_parent_model_frame>1</use_parent_model_frame>
      </axis>
    </joint>
    <!--JOINT: left_knee_pitch-->
    <joint name="left_knee_pitch" type="revolute">
      <child>left_lower_leg</child>
      <parent>left_upper_leg</parent>
      <axis>
        <xyz>0 1 0</xyz>
        <limit>
          <lower>-3.141592653589793</lower>
          <upper>3.141592653589793</upper>
          <velocity>5.75959</velocity>
          <effort>10.0</effort>
        </limit>
        <dynamics>
          <friction>0.5</friction>
          <damping>0.6</damping>
          <spring_reference>0</spring_reference>
          <spring_stiffness>3.25</spring_stiffness>
        </dynamics>
        <use_parent_model_frame>1</use_parent_model_frame>
      </axis>
    </joint>
    <!--JOINT: right_ankle_pitch-->
    <joint name="right_ankle_pitch" type="revolute">
      <child>right_ankle</child>
      <parent>right_lower_leg</parent>
      <axis>
        <xyz>0 1 0</xyz>
        <limit>
          <lower>-3.141592653589793</lower>
          <upper>3.141592653589793</upper>
          <velocity>5.75959</velocity>
          <effort>10.0</effort>
        </limit>
        <dynamics>
          <friction>0.5</friction>
          <damping>0.6</damping>
          <spring_reference>0</spring_reference>
          <spring_stiffness>3.25</spring_stiffness>
        </dynamics>
        <use_parent_model_frame>1</use_parent_model_frame>
      </axis>
    </joint>
    <!--JOINT: left_ankle_pitch-->
    <joint name="left_ankle_pitch" type="revolute">
      <child>left_ankle</child>
      <parent>left_lower_leg</parent>
      <axis>
        <xyz>0 1 0</xyz>
        <limit>
          <lower>-3.141592653589793</lower>
          <upper>3.141592653589793</upper>
          <velocity>5.75959</velocity>
          <effort>10.0</effort>
        </limit>
        <dynamics>
          <friction>0.5</friction>
          <damping>0.6</damping>
          <spring_reference>0</spring_reference>
          <spring_stiffness>3.25</spring_stiffness>
        </dynamics>
        <use_parent_model_frame>1</use_parent_model_frame>
      </axis>
    </joint>
    <!--JOINT: right_ankle_roll-->
    <joint name="right_ankle_roll" type="revolute">
      <child>right_foot</child>
      <parent>right_ankle</parent>
      <axis>
        <xyz>1 0 0</xyz>
        <limit>
          <lower>-3.141592653589793</lower>
          <upper>3.141592653589793</upper>
          <velocity>5.75959</velocity>
          <effort>10.0</effort>
        </limit>
        <dynamics>
          <friction>0.5</friction>
          <damping>0.6</damping>
          <spring_reference>0</spring_reference>
          <spring_stiffness>3.25</spring_stiffness>
        </dynamics>
        <use_parent_model_frame>1</use_parent_model_frame>
      </axis>
    </joint>
    <!--JOINT: left_ankle_roll-->
    <joint name="left_ankle_roll" type="revolute">
      <child>left_foot</child>
      <parent>left_ankle</parent>
      <axis>
        <xyz>1 0 0</xyz>
        <limit>
          <lower>-3.141592653589793</lower>
          <upper>3.141592653589793</upper>
          <velocity>5.75959</velocity>
          <effort>10.0</effort>
        </limit>
        <dynamics>
          <friction>0.5</friction>
          <damping>0.6</damping>
          <spring_reference>0</spring_reference>
          <spring_stiffness>3.25</spring_stiffness>
        </dynamics>
        <use_parent_model_frame>1</use_parent_model_frame>
      </axis>
    </joint>
    <!--JOINT: neck_yaw-->
    <joint name="neck_yaw" type="revolute">
      <child>neck</child>
      <parent>torso</parent>
      <axis>
        <xyz>0 0 1</xyz>
        <limit>
          <lower>-3.141592653589793</lower>
          <upper>3.141592653589793</upper>
          <velocity>8.16814</velocity>
          <effort>7.3</effort>
        </limit>
        <dynamics>
          <friction>0.5</friction>
          <damping>0.6</damping>
          <spring_reference>0</spring_reference>
          <spring_stiffness>3.25</spring_stiffness>
        </dynamics>
        <use_parent_model_frame>1</use_parent_model_frame>
      </axis>
    </joint>
    <!--JOINT: head_pitch-->
    <joint name="head_pitch" type="revolute">
      <child>head</child>
      <parent>neck</parent>
      <axis>
        <xyz>0 1 0</xyz>
        <limit>
          <lower>-3.141592653589793</lower>
          <upper>3.141592653589793</upper>
          <velocity>8.16814</velocity>
          <effort>7.3</effort>
        </limit>
        <dynamics>
          <friction>0.5</friction>
          <damping>0.6</damping>
          <spring_reference>0</spring_reference>
          <spring_stiffness>3.25</spring_stiffness>
        </dynamics>
        <use_parent_model_frame>1</use_parent_model_frame>
      </axis>
    </joint>
  </model>
</sdf>
